Workbook

Sheet 25.04
B2: this month is | E2: July | F2: 2025 | K2: 29625000
H3: =sum(H7:H10) -> 29625000 | K3: =K2-H7-H8-H9 -> 11325000
B4: How much money do you have coming in? and spend out? | K4: 625000
D5: ( + ) | F5: (-) | J5: ( + )
B6: Month | C6: Date | D6: SOURCE | E6: Name | F6: Account | G6: Fund | H6: AMOUNT | J6: Fund | K6: Account
C7: 45840 | D7: House rental money | E7: Xuân trả tiền thuê nhà | H7: 13300000 | J7: Togohub management | K7: Cash
C8: 45840 | D8: Family | E8: bà đưa tiền của Nghĩa | H8: 4000000 | K8: Cash
C9: 45840 | D9: Family | E9: bà̀ cho sinh nhật | H9: 1000000 | K9: Cash
C10: 45840 | D10: Banking interest | E10: lãi ngân hàng | H10: 11325000
C11: 45839 | E11: đi chợ | F11: Vietcombank | G11: Go Market | H11: 1825316
C12: 45847 | E12: đi chợ | F12: Vietcombank | G12: Go Market | H12: 1578328
C13: 45839 | E13: đồ ăn | F13: Vietcombank | G13: Extra meal | H13: 176500
C14: 45844 | E14: cafe | F14: Cash | G14: Café | H14: 195000
C15: 45844 | E15: cafe | F15: Cash | G15: Café | H15: 125000
C323: 45322
C324: 45322
C325: 45322
C326: 45322
C327: 45322
C328: 45322
C329: 45322
E412: TOTAL (A) | H412: =sum(H7:H411) -> 33525144
B414: How much money do you have going out? | E414: =#REF! -> #REF!
B417: How much money do you have available to you?
B418: TOTAL (A) | D418: - | E418: TOTAL (B) | F418: = | H418: TOTAL (C)
B419: =H412 -> 33525144 | E419: =#REF! -> #REF! | H419: =B419-E419 -> #REF!
B421: How much money do you want to save
B422: TOTAL (D) | E422: ='Spending 25.04'!H89+#REF! -> #REF!
B424: What for?
B430: How much should you spend?
B431: TOTAL (C) | D431: - | E431: TOTAL (D) | F431: = | H431: TOTAL (E) (PER MONTH)
B432: =H419 -> #REF! | E432: =E422 -> #REF! | H432: =H419-E422 -> #REF!
B434: TOTAL (E) | D434: / | E434: No OF WEEKS | F434: = | H434: TOTAL (PER WEEK)
B435: =H432 -> #REF! | E435: 5 | H435: =B435/E435 -> #REF!
B437: NOTES

Sheet Spending 25.04
C1: Chi tiêu thực tế
E2: (-) | U2: ( + )
E3: Cash | F3: BIDV | G3: Vietcombank | H3: Vp bank Lady | I3: Moca | J3: Momo | K3: Zalo | L3: Saving | M3: Loan | N3: Total out | P3: % | Q3: % | T3: Cash | U3: BIDV | V3: Vietcombank | W3: Vp bank Lady | X3: Moca | Y3: Momo | Z3: Zalo | AA3: Saving | AB3: Loan | AC3: Total in
C4: 1 | D4: Education | E4: =sumifs('25.04'!$H$7:$H$411,'25.04'!$G$7:$G$411,$D4,'25.04'!$F$7:$F$411,E$3) -> 0 | F4: =sumifs('25.04'!$H$7:$H$411,'25.04'!$G$7:$G$411,$D4,'25.04'!$F$7:$F$411,F$3) -> 0 | G4: =sumifs('25.04'!$H$7:$H$411,'25.04'!$G$7:$G$411,$D4,'25.04'!$F$7:$F$411,G$3) -> 0 | H4: =sumifs('25.04'!$H$7:$H$411,'25.04'!$G$7:$G$411,$D4,'25.04'!$F$7:$F$411,H$3) -> 0 | I4: =sumifs('25.04'!$H$7:$H$411,'25.04'!$G$7:$G$411,$D4,'25.04'!$F$7:$F$411,I$3) -> 0 | J4: =sumifs('25.04'!$H$7:$H$411,'25.04'!$G$7:$G$411,$D4,'25.04'!$F$7:$F$411,J$3) -> 0 | K4: =sumifs('25.04'!$H$7:$H$411,'25.04'!$G$7:$G$411,$D4,'25.04'!$F$7:$F$411,K$3) -> 0 | L4: =sumifs('25.04'!$H$7:$H$411,'25.04'!$G$7:$G$411,$D4,'25.04'!$F$7:$F$411,L$3) -> 0 | M4: =sumifs('25.04'!$H$7:$H$411,'25.04'!$G$7:$G$411,$D4,'25.04'!$F$7:$F$411,M$3) -> 0 | N4: =sum(E4:M4) -> 0 | P4: =N4/sum(N$4:N$9) -> #DIV/0! | R4: =sum(N4:N9) -> 0 | S4: =R4/sum($R$4:$R$49) -> 0 | T4: =sumifs('25.04'!$H$7:$H$411,'25.04'!$J$7:$J$411,$D4,'25.04'!$K$7:$K$411,T$3) -> 0 | U4: =sumifs('25.04'!$H$7:$H$411,'25.04'!$J$7:$J$411,$D4,'25.04'!$K$7:$K$411,U$3) -> 0 | V4: =sumifs('25.04'!$H$7:$H$411,'25.04'!$J$7:$J$411,$D4,'25.04'!$K$7:$K$411,V$3) -> 0 | W4: =sumifs('25.04'!$H$7:$H$411,'25.04'!$J$7:$J$411,$D4,'25.04'!$K$7:$K$411,W$3) -> 0 | X4: =sumifs('25.04'!$H$7:$H$411,'25.04'!$J$7:$J$411,$D4,'25.04'!$K$7:$K$411,X$3) -> 0 | Y4: =sumifs('25.04'!$H$7:$H$411,'25.04'!$J$7:$J$411,$D4,'25.04'!$K$7:$K$411,Y$3) -> 0 | Z4: =sumifs('25.04'!$H$7:$H$411,'25.04'!$J$7:$J$411,$D4,'25.04'!$K$7:$K$411,Z$3) -> 0 | AA4: =sumifs('25.04'!$H$7:$H$411,'25.04'!$J$7:$J$411,$D4,'25.04'!$K$7:$K$411,AA$3) -> 0 | AB4: =sumifs('25.04'!$H$7:$H$411,'25.04'!$J$7:$J$411,$D4,'25.04'!$K$7:$K$411,AB$3) -> 0 | AC4: =sum(T4:AB4) -> 0
A5: 1 | B5: Education | C5: 44927 | D5: Education fee | E5: =sumifs('25.04'!$H$7:$H$411,'25.04'!$G$7:$G$411,$D5,'25.04'!$F$7:$F$411,E$3) -> 0 | F5: =sumifs('25.04'!$H$7:$H$411,'25.04'!$G$7:$G$411,$D5,'25.04'!$F$7:$F$411,F$3) -> 0 | G5: =sumifs('25.04'!$H$7:$H$411,'25.04'!$G$7:$G$411,$D5,'25.04'!$F$7:$F$411,G$3) -> 0 | H5: =sumifs('25.04'!$H$7:$H$411,'25.04'!$G$7:$G$411,$D5,'25.04'!$F$7:$F$411,H$3) -> 0 | I5: =sumifs('25.04'!$H$7:$H$411,'25.04'!$G$7:$G$411,$D5,'25.04'!$F$7:$F$411,I$3) -> 0 | J5: =sumifs('25.04'!$H$7:$H$411,'25.04'!$G$7:$G$411,$D5,'25.04'!$F$7:$F$411,J$3) -> 0 | K5: =sumifs('25.04'!$H$7:$H$411,'25.04'!$G$7:$G$411,$D5,'25.04'!$F$7:$F$411,K$3) -> 0 | L5: =sumifs('25.04'!$H$7:$H$411,'25.04'!$G$7:$G$411,$D5,'25.04'!$F$7:$F$411,L$3) -> 0 | M5: =sumifs('25.04'!$H$7:$H$411,'25.04'!$G$7:$G$411,$D5,'25.04'!$F$7:$F$411,M$3) -> 0 | N5: =sum(E5:M5) -> 0 | P5: =N5/sum(N$4:N$9) -> #DIV/0! | T5: =sumifs('25.04'!$H$7:$H$411,'25.04'!$J$7:$J$411,$D5,'25.04'!$K$7:$K$411,T$3) -> 0 | U5: =sumifs('25.04'!$H$7:$H$411,'25.04'!$J$7:$J$411,$D5,'25.04'!$K$7:$K$411,U$3) -> 0 | V5: =sumifs('25.04'!$H$7:$H$411,'25.04'!$J$7:$J$411,$D5,'25.04'!$K$7:$K$411,V$3) -> 0 | W5: =sumifs('25.04'!$H$7:$H$411,'25.04'!$J$7:$J$411,$D5,'25.04'!$K$7:$K$411,W$3) -> 0 | X5: =sumifs('25.04'!$H$7:$H$411,'25.04'!$J$7:$J$411,$D5,'25.04'!$K$7:$K$411,X$3) -> 0 | Y5: =sumifs('25.04'!$H$7:$H$411,'25.04'!$J$7:$J$411,$D5,'25.04'!$K$7:$K$411,Y$3) -> 0 | Z5: =sumifs('25.04'!$H$7:$H$411,'25.04'!$J$7:$J$411,$D5,'25.04'!$K$7:$K$411,Z$3) -> 0 | AA5: =sumifs('25.04'!$H$7:$H$411,'25.04'!$J$7:$J$411,$D5,'25.04'!$K$7:$K$411,AA$3) -> 0 | AB5: =sumifs('25.04'!$H$7:$H$411,'25.04'!$J$7:$J$411,$D5,'25.04'!$K$7:$K$411,AB$3) -> 0 | AC5: =sum(T5:AB5) -> 0
C6: 44958 | D6: Extra Education fee | E6: =sumifs('25.04'!$H$7:$H$411,'25.04'!$G$7:$G$411,$D6,'25.04'!$F$7:$F$411,E$3) -> 0 | F6: =sumifs('25.04'!$H$7:$H$411,'25.04'!$G$7:$G$411,$D6,'25.04'!$F$7:$F$411,F$3) -> 0 | G6: =sumifs('25.04'!$H$7:$H$411,'25.04'!$G$7:$G$411,$D6,'25.04'!$F$7:$F$411,G$3) -> 0 | H6: =sumifs('25.04'!$H$7:$H$411,'25.04'!$G$7:$G$411,$D6,'25.04'!$F$7:$F$411,H$3) -> 0 | I6: =sumifs('25.04'!$H$7:$H$411,'25.04'!$G$7:$G$411,$D6,'25.04'!$F$7:$F$411,I$3) -> 0 | J6: =sumifs('25.04'!$H$7:$H$411,'25.04'!$G$7:$G$411,$D6,'25.04'!$F$7:$F$411,J$3) -> 0 | K6: =sumifs('25.04'!$H$7:$H$411,'25.04'!$G$7:$G$411,$D6,'25.04'!$F$7:$F$411,K$3) -> 0 | L6: =sumifs('25.04'!$H$7:$H$411,'25.04'!$G$7:$G$411,$D6,'25.04'!$F$7:$F$411,L$3) -> 0 | M6: =sumifs('25.04'!$H$7:$H$411,'25.04'!$G$7:$G$411,$D6,'25.04'!$F$7:$F$411,M$3) -> 0 | N6: =sum(E6:M6) -> 0 | P6: =N6/sum(N$4:N$9) -> #DIV/0! | T6: =sumifs('25.04'!$H$7:$H$411,'25.04'!$J$7:$J$411,$D6,'25.04'!$K$7:$K$411,T$3) -> 0 | U6: =sumifs('25.04'!$H$7:$H$411,'25.04'!$J$7:$J$411,$D6,'25.04'!$K$7:$K$411,U$3) -> 0 | V6: =sumifs('25.04'!$H$7:$H$411,'25.04'!$J$7:$J$411,$D6,'25.04'!$K$7:$K$411,V$3) -> 0 | W6: =sumifs('25.04'!$H$7:$H$411,'25.04'!$J$7:$J$411,$D6,'25.04'!$K$7:$K$411,W$3) -> 0 | X6: =sumifs('25.04'!$H$7:$H$411,'25.04'!$J$7:$J$411,$D6,'25.04'!$K$7:$K$411,X$3) -> 0 | Y6: =sumifs('25.04'!$H$7:$H$411,'25.04'!$J$7:$J$411,$D6,'25.04'!$K$7:$K$411,Y$3) -> 0 | Z6: =sumifs('25.04'!$H$7:$H$411,'25.04'!$J$7:$J$411,$D6,'25.04'!$K$7:$K$411,Z$3) -> 0 | AA6: =sumifs('25.04'!$H$7:$H$411,'25.04'!$J$7:$J$411,$D6,'25.04'!$K$7:$K$411,AA$3) -> 0 | AB6: =sumifs('25.04'!$H$7:$H$411,'25.04'!$J$7:$J$411,$D6,'25.04'!$K$7:$K$411,AB$3) -> 0 | AC6: =sum(T6:AB6) -> 0
C7: 44986 | D7: Talent Education fee | E7: =sumifs('25.04'!$H$7:$H$411,'25.04'!$G$7:$G$411,$D7,'25.04'!$F$7:$F$411,E$3) -> 0 | F7: =sumifs('25.04'!$H$7:$H$411,'25.04'!$G$7:$G$411,$D7,'25.04'!$F$7:$F$411,F$3) -> 0 | G7: =sumifs('25.04'!$H$7:$H$411,'25.04'!$G$7:$G$411,$D7,'25.04'!$F$7:$F$411,G$3) -> 0 | H7: =sumifs('25.04'!$H$7:$H$411,'25.04'!$G$7:$G$411,$D7,'25.04'!$F$7:$F$411,H$3) -> 0 | I7: =sumifs('25.04'!$H$7:$H$411,'25.04'!$G$7:$G$411,$D7,'25.04'!$F$7:$F$411,I$3) -> 0 | J7: =sumifs('25.04'!$H$7:$H$411,'25.04'!$G$7:$G$411,$D7,'25.04'!$F$7:$F$411,J$3) -> 0 | K7: =sumifs('25.04'!$H$7:$H$411,'25.04'!$G$7:$G$411,$D7,'25.04'!$F$7:$F$411,K$3) -> 0 | L7: =sumifs('25.04'!$H$7:$H$411,'25.04'!$G$7:$G$411,$D7,'25.04'!$F$7:$F$411,L$3) -> 0 | M7: =sumifs('25.04'!$H$7:$H$411,'25.04'!$G$7:$G$411,$D7,'25.04'!$F$7:$F$411,M$3) -> 0 | N7: =sum(E7:M7) -> 0 | P7: =N7/sum(N$4:N$9) -> #DIV/0! | T7: =sumifs('25.04'!$H$7:$H$411,'25.04'!$J$7:$J$411,$D7,'25.04'!$K$7:$K$411,T$3) -> 0 | U7: =sumifs('25.04'!$H$7:$H$411,'25.04'!$J$7:$J$411,$D7,'25.04'!$K$7:$K$411,U$3) -> 0 | V7: =sumifs('25.04'!$H$7:$H$411,'25.04'!$J$7:$J$411,$D7,'25.04'!$K$7:$K$411,V$3) -> 0 | W7: =sumifs('25.04'!$H$7:$H$411,'25.04'!$J$7:$J$411,$D7,'25.04'!$K$7:$K$411,W$3) -> 0 | X7: =sumifs('25.04'!$H$7:$H$411,'25.04'!$J$7:$J$411,$D7,'25.04'!$K$7:$K$411,X$3) -> 0 | Y7: =sumifs('25.04'!$H$7:$H$411,'25.04'!$J$7:$J$411,$D7,'25.04'!$K$7:$K$411,Y$3) -> 0 | Z7: =sumifs('25.04'!$H$7:$H$411,'25.04'!$J$7:$J$411,$D7,'25.04'!$K$7:$K$411,Z$3) -> 0 | AA7: =sumifs('25.04'!$H$7:$H$411,'25.04'!$J$7:$J$411,$D7,'25.04'!$K$7:$K$411,AA$3) -> 0 | AB7: =sumifs('25.04'!$H$7:$H$411,'25.04'!$J$7:$J$411,$D7,'25.04'!$K$7:$K$411,AB$3) -> 0 | AC7: =sum(T7:AB7) -> 0
C8: 45017 | D8: Books | E8: =sumifs('25.04'!$H$7:$H$411,'25.04'!$G$7:$G$411,$D8,'25.04'!$F$7:$F$411,E$3) -> 0 | F8: =sumifs('25.04'!$H$7:$H$411,'25.04'!$G$7:$G$411,$D8,'25.04'!$F$7:$F$411,F$3) -> 0 | G8: =sumifs('25.04'!$H$7:$H$411,'25.04'!$G$7:$G$411,$D8,'25.04'!$F$7:$F$411,G$3) -> 0 | H8: =sumifs('25.04'!$H$7:$H$411,'25.04'!$G$7:$G$411,$D8,'25.04'!$F$7:$F$411,H$3) -> 0 | I8: =sumifs('25.04'!$H$7:$H$411,'25.04'!$G$7:$G$411,$D8,'25.04'!$F$7:$F$411,I$3) -> 0 | J8: =sumifs('25.04'!$H$7:$H$411,'25.04'!$G$7:$G$411,$D8,'25.04'!$F$7:$F$411,J$3) -> 0 | K8: =sumifs('25.04'!$H$7:$H$411,'25.04'!$G$7:$G$411,$D8,'25.04'!$F$7:$F$411,K$3) -> 0 | L8: =sumifs('25.04'!$H$7:$H$411,'25.04'!$G$7:$G$411,$D8,'25.04'!$F$7:$F$411,L$3) -> 0 | M8: =sumifs('25.04'!$H$7:$H$411,'25.04'!$G$7:$G$411,$D8,'25.04'!$F$7:$F$411,M$3) -> 0 | N8: =sum(E8:M8) -> 0 | P8: =N8/sum(N$4:N$9) -> #DIV/0! | T8: =sumifs('25.04'!$H$7:$H$411,'25.04'!$J$7:$J$411,$D8,'25.04'!$K$7:$K$411,T$3) -> 0 | U8: =sumifs('25.04'!$H$7:$H$411,'25.04'!$J$7:$J$411,$D8,'25.04'!$K$7:$K$411,U$3) -> 0 | V8: =sumifs('25.04'!$H$7:$H$411,'25.04'!$J$7:$J$411,$D8,'25.04'!$K$7:$K$411,V$3) -> 0 | W8: =sumifs('25.04'!$H$7:$H$411,'25.04'!$J$7:$J$411,$D8,'25.04'!$K$7:$K$411,W$3) -> 0 | X8: =sumifs('25.04'!$H$7:$H$411,'25.04'!$J$7:$J$411,$D8,'25.04'!$K$7:$K$411,X$3) -> 0 | Y8: =sumifs('25.04'!$H$7:$H$411,'25.04'!$J$7:$J$411,$D8,'25.04'!$K$7:$K$411,Y$3) -> 0 | Z8: =sumifs('25.04'!$H$7:$H$411,'25.04'!$J$7:$J$411,$D8,'25.04'!$K$7:$K$411,Z$3) -> 0 | AA8: =sumifs('25.04'!$H$7:$H$411,'25.04'!$J$7:$J$411,$D8,'25.04'!$K$7:$K$411,AA$3) -> 0 | AB8: =sumifs('25.04'!$H$7:$H$411,'25.04'!$J$7:$J$411,$D8,'25.04'!$K$7:$K$411,AB$3) -> 0 | AC8: =sum(T8:AB8) -> 0
C9: 45047 | D9: Stationery | E9: =sumifs('25.04'!$H$7:$H$411,'25.04'!$G$7:$G$411,$D9,'25.04'!$F$7:$F$411,E$3) -> 0 | F9: =sumifs('25.04'!$H$7:$H$411,'25.04'!$G$7:$G$411,$D9,'25.04'!$F$7:$F$411,F$3) -> 0 | G9: =sumifs('25.04'!$H$7:$H$411,'25.04'!$G$7:$G$411,$D9,'25.04'!$F$7:$F$411,G$3) -> 0 | H9: =sumifs('25.04'!$H$7:$H$411,'25.04'!$G$7:$G$411,$D9,'25.04'!$F$7:$F$411,H$3) -> 0 | I9: =sumifs('25.04'!$H$7:$H$411,'25.04'!$G$7:$G$411,$D9,'25.04'!$F$7:$F$411,I$3) -> 0 | J9: =sumifs('25.04'!$H$7:$H$411,'25.04'!$G$7:$G$411,$D9,'25.04'!$F$7:$F$411,J$3) -> 0 | K9: =sumifs('25.04'!$H$7:$H$411,'25.04'!$G$7:$G$411,$D9,'25.04'!$F$7:$F$411,K$3) -> 0 | L9: =sumifs('25.04'!$H$7:$H$411,'25.04'!$G$7:$G$411,$D9,'25.04'!$F$7:$F$411,L$3) -> 0 | M9: =sumifs('25.04'!$H$7:$H$411,'25.04'!$G$7:$G$411,$D9,'25.04'!$F$7:$F$411,M$3) -> 0 | N9: =sum(E9:M9) -> 0 | P9: =N9/sum(N$4:N$9) -> #DIV/0! | T9: =sumifs('25.04'!$H$7:$H$411,'25.04'!$J$7:$J$411,$D9,'25.04'!$K$7:$K$411,T$3) -> 0 | U9: =sumifs('25.04'!$H$7:$H$411,'25.04'!$J$7:$J$411,$D9,'25.04'!$K$7:$K$411,U$3) -> 0 | V9: =sumifs('25.04'!$H$7:$H$411,'25.04'!$J$7:$J$411,$D9,'25.04'!$K$7:$K$411,V$3) -> 0 | W9: =sumifs('25.04'!$H$7:$H$411,'25.04'!$J$7:$J$411,$D9,'25.04'!$K$7:$K$411,W$3) -> 0 | X9: =sumifs('25.04'!$H$7:$H$411,'25.04'!$J$7:$J$411,$D9,'25.04'!$K$7:$K$411,X$3) -> 0 | Y9: =sumifs('25.04'!$H$7:$H$411,'25.04'!$J$7:$J$411,$D9,'25.04'!$K$7:$K$411,Y$3) -> 0 | Z9: =sumifs('25.04'!$H$7:$H$411,'25.04'!$J$7:$J$411,$D9,'25.04'!$K$7:$K$411,Z$3) -> 0 | AA9: =sumifs('25.04'!$H$7:$H$411,'25.04'!$J$7:$J$411,$D9,'25.04'!$K$7:$K$411,AA$3) -> 0 | AB9: =sumifs('25.04'!$H$7:$H$411,'25.04'!$J$7:$J$411,$D9,'25.04'!$K$7:$K$411,AB$3) -> 0 | AC9: =sum(T9:AB9) -> 0
C10: 2 | D10: Enjoy | E10: =sumifs('25.04'!$H$7:$H$411,'25.04'!$G$7:$G$411,$D10,'25.04'!$F$7:$F$411,E$3) -> 0 | F10: =sumifs('25.04'!$H$7:$H$411,'25.04'!$G$7:$G$411,$D10,'25.04'!$F$7:$F$411,F$3) -> 0 | G10: =sumifs('25.04'!$H$7:$H$411,'25.04'!$G$7:$G$411,$D10,'25.04'!$F$7:$F$411,G$3) -> 0 | H10: =sumifs('25.04'!$H$7:$H$411,'25.04'!$G$7:$G$411,$D10,'25.04'!$F$7:$F$411,H$3) -> 0 | I10: =sumifs('25.04'!$H$7:$H$411,'25.04'!$G$7:$G$411,$D10,'25.04'!$F$7:$F$411,I$3) -> 0 | J10: =sumifs('25.04'!$H$7:$H$411,'25.04'!$G$7:$G$411,$D10,'25.04'!$F$7:$F$411,J$3) -> 0 | K10: =sumifs('25.04'!$H$7:$H$411,'25.04'!$G$7:$G$411,$D10,'25.04'!$F$7:$F$411,K$3) -> 0 | L10: =sumifs('25.04'!$H$7:$H$411,'25.04'!$G$7:$G$411,$D10,'25.04'!$F$7:$F$411,L$3) -> 0 | M10: =sumifs('25.04'!$H$7:$H$411,'25.04'!$G$7:$G$411,$D10,'25.04'!$F$7:$F$411,M$3) -> 0 | N10: =sum(E10:M10) -> 0 | P10: =N10/sum(N$10:N$16) -> 0 | R10: =sum(N10:N16) -> 320000 | S10: =R10/sum($R$4:$R$49) -> 1 | T10: =sumifs('25.04'!$H$7:$H$411,'25.04'!$J$7:$J$411,$D10,'25.04'!$K$7:$K$411,T$3) -> 0 | U10: =sumifs('25.04'!$H$7:$H$411,'25.04'!$J$7:$J$411,$D10,'25.04'!$K$7:$K$411,U$3) -> 0 | V10: =sumifs('25.04'!$H$7:$H$411,'25.04'!$J$7:$J$411,$D10,'25.04'!$K$7:$K$411,V$3) -> 0 | W10: =sumifs('25.04'!$H$7:$H$411,'25.04'!$J$7:$J$411,$D10,'25.04'!$K$7:$K$411,W$3) -> 0 | X10: =sumifs('25.04'!$H$7:$H$411,'25.04'!$J$7:$J$411,$D10,'25.04'!$K$7:$K$411,X$3) -> 0 | Y10: =sumifs('25.04'!$H$7:$H$411,'25.04'!$J$7:$J$411,$D10,'25.04'!$K$7:$K$411,Y$3) -> 0 | Z10: =sumifs('25.04'!$H$7:$H$411,'25.04'!$J$7:$J$411,$D10,'25.04'!$K$7:$K$411,Z$3) -> 0 | AA10: =sumifs('25.04'!$H$7:$H$411,'25.04'!$J$7:$J$411,$D10,'25.04'!$K$7:$K$411,AA$3) -> 0 | AB10: =sumifs('25.04'!$H$7:$H$411,'25.04'!$J$7:$J$411,$D10,'25.04'!$K$7:$K$411,AB$3) -> 0 | AC10: =sum(T10:AB10) -> 0
A11: 2 | B11: Enjoy | C11: 44928 | D11: Travel | E11: =sumifs('25.04'!$H$7:$H$411,'25.04'!$G$7:$G$411,$D11,'25.04'!$F$7:$F$411,E$3) -> 0 | F11: =sumifs('25.04'!$H$7:$H$411,'25.04'!$G$7:$G$411,$D11,'25.04'!$F$7:$F$411,F$3) -> 0 | G11: =sumifs('25.04'!$H$7:$H$411,'25.04'!$G$7:$G$411,$D11,'25.04'!$F$7:$F$411,G$3) -> 0 | H11: =sumifs('25.04'!$H$7:$H$411,'25.04'!$G$7:$G$411,$D11,'25.04'!$F$7:$F$411,H$3) -> 0 | I11: =sumifs('25.04'!$H$7:$H$411,'25.04'!$G$7:$G$411,$D11,'25.04'!$F$7:$F$411,I$3) -> 0 | J11: =sumifs('25.04'!$H$7:$H$411,'25.04'!$G$7:$G$411,$D11,'25.04'!$F$7:$F$411,J$3) -> 0 | K11: =sumifs('25.04'!$H$7:$H$411,'25.04'!$G$7:$G$411,$D11,'25.04'!$F$7:$F$411,K$3) -> 0 | L11: =sumifs('25.04'!$H$7:$H$411,'25.04'!$G$7:$G$411,$D11,'25.04'!$F$7:$F$411,L$3) -> 0 | M11: =sumifs('25.04'!$H$7:$H$411,'25.04'!$G$7:$G$411,$D11,'25.04'!$F$7:$F$411,M$3) -> 0 | N11: =sum(E11:M11) -> 0 | P11: =N11/sum(N$10:N$16) -> 0 | T11: =sumifs('25.04'!$H$7:$H$411,'25.04'!$J$7:$J$411,$D11,'25.04'!$K$7:$K$411,T$3) -> 0 | U11: =sumifs('25.04'!$H$7:$H$411,'25.04'!$J$7:$J$411,$D11,'25.04'!$K$7:$K$411,U$3) -> 0 | V11: =sumifs('25.04'!$H$7:$H$411,'25.04'!$J$7:$J$411,$D11,'25.04'!$K$7:$K$411,V$3) -> 0 | W11: =sumifs('25.04'!$H$7:$H$411,'25.04'!$J$7:$J$411,$D11,'25.04'!$K$7:$K$411,W$3) -> 0 | X11: =sumifs('25.04'!$H$7:$H$411,'25.04'!$J$7:$J$411,$D11,'25.04'!$K$7:$K$411,X$3) -> 0 | Y11: =sumifs('25.04'!$H$7:$H$411,'25.04'!$J$7:$J$411,$D11,'25.04'!$K$7:$K$411,Y$3) -> 0 | Z11: =sumifs('25.04'!$H$7:$H$411,'25.04'!$J$7:$J$411,$D11,'25.04'!$K$7:$K$411,Z$3) -> 0 | AA11: =sumifs('25.04'!$H$7:$H$411,'25.04'!$J$7:$J$411,$D11,'25.04'!$K$7:$K$411,AA$3) -> 0 | AB11: =sumifs('25.04'!$H$7:$H$411,'25.04'!$J$7:$J$411,$D11,'25.04'!$K$7:$K$411,AB$3) -> 0 | AC11: =sum(T11:AB11) -> 0
C12: 44959 | D12: Café | E12: =sumifs('25.04'!$H$7:$H$411,'25.04'!$G$7:$G$411,$D12,'25.04'!$F$7:$F$411,E$3) -> 320000 | F12: =sumifs('25.04'!$H$7:$H$411,'25.04'!$G$7:$G$411,$D12,'25.04'!$F$7:$F$411,F$3) -> 0 | G12: =sumifs('25.04'!$H$7:$H$411,'25.04'!$G$7:$G$411,$D12,'25.04'!$F$7:$F$411,G$3) -> 0 | H12: =sumifs('25.04'!$H$7:$H$411,'25.04'!$G$7:$G$411,$D12,'25.04'!$F$7:$F$411,H$3) -> 0 | I12: =sumifs('25.04'!$H$7:$H$411,'25.04'!$G$7:$G$411,$D12,'25.04'!$F$7:$F$411,I$3) -> 0 | J12: =sumifs('25.04'!$H$7:$H$411,'25.04'!$G$7:$G$411,$D12,'25.04'!$F$7:$F$411,J$3) -> 0 | K12: =sumifs('25.04'!$H$7:$H$411,'25.04'!$G$7:$G$411,$D12,'25.04'!$F$7:$F$411,K$3) -> 0 | L12: =sumifs('25.04'!$H$7:$H$411,'25.04'!$G$7:$G$411,$D12,'25.04'!$F$7:$F$411,L$3) -> 0 | M12: =sumifs('25.04'!$H$7:$H$411,'25.04'!$G$7:$G$411,$D12,'25.04'!$F$7:$F$411,M$3) -> 0 | N12: =sum(E12:M12) -> 320000 | P12: =N12/sum(N$10:N$16) -> 1 | T12: =sumifs('25.04'!$H$7:$H$411,'25.04'!$J$7:$J$411,$D12,'25.04'!$K$7:$K$411,T$3) -> 0 | U12: =sumifs('25.04'!$H$7:$H$411,'25.04'!$J$7:$J$411,$D12,'25.04'!$K$7:$K$411,U$3) -> 0 | V12: =sumifs('25.04'!$H$7:$H$411,'25.04'!$J$7:$J$411,$D12,'25.04'!$K$7:$K$411,V$3) -> 0 | W12: =sumifs('25.04'!$H$7:$H$411,'25.04'!$J$7:$J$411,$D12,'25.04'!$K$7:$K$411,W$3) -> 0 | X12: =sumifs('25.04'!$H$7:$H$411,'25.04'!$J$7:$J$411,$D12,'25.04'!$K$7:$K$411,X$3) -> 0 | Y12: =sumifs('25.04'!$H$7:$H$411,'25.04'!$J$7:$J$411,$D12,'25.04'!$K$7:$K$411,Y$3) -> 0 | Z12: =sumifs('25.04'!$H$7:$H$411,'25.04'!$J$7:$J$411,$D12,'25.04'!$K$7:$K$411,Z$3) -> 0 | AA12: =sumifs('25.04'!$H$7:$H$411,'25.04'!$J$7:$J$411,$D12,'25.04'!$K$7:$K$411,AA$3) -> 0 | AB12: =sumifs('25.04'!$H$7:$H$411,'25.04'!$J$7:$J$411,$D12,'25.04'!$K$7:$K$411,AB$3) -> 0 | AC12: =sum(T12:AB12) -> 0
C13: 44987 | D13: Restaurant | E13: =sumifs('25.04'!$H$7:$H$411,'25.04'!$G$7:$G$411,$D13,'25.04'!$F$7:$F$411,E$3) -> 0 | F13: =sumifs('25.04'!$H$7:$H$411,'25.04'!$G$7:$G$411,$D13,'25.04'!$F$7:$F$411,F$3) -> 0 | G13: =sumifs('25.04'!$H$7:$H$411,'25.04'!$G$7:$G$411,$D13,'25.04'!$F$7:$F$411,G$3) -> 0 | H13: =sumifs('25.04'!$H$7:$H$411,'25.04'!$G$7:$G$411,$D13,'25.04'!$F$7:$F$411,H$3) -> 0 | I13: =sumifs('25.04'!$H$7:$H$411,'25.04'!$G$7:$G$411,$D13,'25.04'!$F$7:$F$411,I$3) -> 0 | J13: =sumifs('25.04'!$H$7:$H$411,'25.04'!$G$7:$G$411,$D13,'25.04'!$F$7:$F$411,J$3) -> 0 | K13: =sumifs('25.04'!$H$7:$H$411,'25.04'!$G$7:$G$411,$D13,'25.04'!$F$7:$F$411,K$3) -> 0 | L13: =sumifs('25.04'!$H$7:$H$411,'25.04'!$G$7:$G$411,$D13,'25.04'!$F$7:$F$411,L$3) -> 0 | M13: =sumifs('25.04'!$H$7:$H$411,'25.04'!$G$7:$G$411,$D13,'25.04'!$F$7:$F$411,M$3) -> 0 | N13: =sum(E13:M13) -> 0 | P13: =N13/sum(N$10:N$16) -> 0 | T13: =sumifs('25.04'!$H$7:$H$411,'25.04'!$J$7:$J$411,$D13,'25.04'!$K$7:$K$411,T$3) -> 0 | U13: =sumifs('25.04'!$H$7:$H$411,'25.04'!$J$7:$J$411,$D13,'25.04'!$K$7:$K$411,U$3) -> 0 | V13: =sumifs('25.04'!$H$7:$H$411,'25.04'!$J$7:$J$411,$D13,'25.04'!$K$7:$K$411,V$3) -> 0 | W13: =sumifs('25.04'!$H$7:$H$411,'25.04'!$J$7:$J$411,$D13,'25.04'!$K$7:$K$411,W$3) -> 0 | X13: =sumifs('25.04'!$H$7:$H$411,'25.04'!$J$7:$J$411,$D13,'25.04'!$K$7:$K$411,X$3) -> 0 | Y13: =sumifs('25.04'!$H$7:$H$411,'25.04'!$J$7:$J$411,$D13,'25.04'!$K$7:$K$411,Y$3) -> 0 | Z13: =sumifs('25.04'!$H$7:$H$411,'25.04'!$J$7:$J$411,$D13,'25.04'!$K$7:$K$411,Z$3) -> 0 | AA13: =sumifs('25.04'!$H$7:$H$411,'25.04'!$J$7:$J$411,$D13,'25.04'!$K$7:$K$411,AA$3) -> 0 | AB13: =sumifs('25.04'!$H$7:$H$411,'25.04'!$J$7:$J$411,$D13,'25.04'!$K$7:$K$411,AB$3) -> 0 | AC13: =sum(T13:AB13) -> 0
C14: 45018 | D14: Sightseeing | E14: =sumifs('25.04'!$H$7:$H$411,'25.04'!$G$7:$G$411,$D14,'25.04'!$F$7:$F$411,E$3) -> 0 | F14: =sumifs('25.04'!$H$7:$H$411,'25.04'!$G$7:$G$411,$D14,'25.04'!$F$7:$F$411,F$3) -> 0 | G14: =sumifs('25.04'!$H$7:$H$411,'25.04'!$G$7:$G$411,$D14,'25.04'!$F$7:$F$411,G$3) -> 0 | H14: =sumifs('25.04'!$H$7:$H$411,'25.04'!$G$7:$G$411,$D14,'25.04'!$F$7:$F$411,H$3) -> 0 | I14: =sumifs('25.04'!$H$7:$H$411,'25.04'!$G$7:$G$411,$D14,'25.04'!$F$7:$F$411,I$3) -> 0 | J14: =sumifs('25.04'!$H$7:$H$411,'25.04'!$G$7:$G$411,$D14,'25.04'!$F$7:$F$411,J$3) -> 0 | K14: =sumifs('25.04'!$H$7:$H$411,'25.04'!$G$7:$G$411,$D14,'25.04'!$F$7:$F$411,K$3) -> 0 | L14: =sumifs('25.04'!$H$7:$H$411,'25.04'!$G$7:$G$411,$D14,'25.04'!$F$7:$F$411,L$3) -> 0 | M14: =sumifs('25.04'!$H$7:$H$411,'25.04'!$G$7:$G$411,$D14,'25.04'!$F$7:$F$411,M$3) -> 0 | N14: =sum(E14:M14) -> 0 | P14: =N14/sum(N$10:N$16) -> 0 | T14: =sumifs('25.04'!$H$7:$H$411,'25.04'!$J$7:$J$411,$D14,'25.04'!$K$7:$K$411,T$3) -> 0 | U14: =sumifs('25.04'!$H$7:$H$411,'25.04'!$J$7:$J$411,$D14,'25.04'!$K$7:$K$411,U$3) -> 0 | V14: =sumifs('25.04'!$H$7:$H$411,'25.04'!$J$7:$J$411,$D14,'25.04'!$K$7:$K$411,V$3) -> 0 | W14: =sumifs('25.04'!$H$7:$H$411,'25.04'!$J$7:$J$411,$D14,'25.04'!$K$7:$K$411,W$3) -> 0 | X14: =sumifs('25.04'!$H$7:$H$411,'25.04'!$J$7:$J$411,$D14,'25.04'!$K$7:$K$411,X$3) -> 0 | Y14: =sumifs('25.04'!$H$7:$H$411,'25.04'!$J$7:$J$411,$D14,'25.04'!$K$7:$K$411,Y$3) -> 0 | Z14: =sumifs('25.04'!$H$7:$H$411,'25.04'!$J$7:$J$411,$D14,'25.04'!$K$7:$K$411,Z$3) -> 0 | AA14: =sumifs('25.04'!$H$7:$H$411,'25.04'!$J$7:$J$411,$D14,'25.04'!$K$7:$K$411,AA$3) -> 0 | AB14: =sumifs('25.04'!$H$7:$H$411,'25.04'!$J$7:$J$411,$D14,'25.04'!$K$7:$K$411,AB$3) -> 0 | AC14: =sum(T14:AB14) -> 0
C15: 45048 | D15: Exhibition | E15: =sumifs('25.04'!$H$7:$H$411,'25.04'!$G$7:$G$411,$D15,'25.04'!$F$7:$F$411,E$3) -> 0 | F15: =sumifs('25.04'!$H$7:$H$411,'25.04'!$G$7:$G$411,$D15,'25.04'!$F$7:$F$411,F$3) -> 0 | G15: =sumifs('25.04'!$H$7:$H$411,'25.04'!$G$7:$G$411,$D15,'25.04'!$F$7:$F$411,G$3) -> 0 | H15: =sumifs('25.04'!$H$7:$H$411,'25.04'!$G$7:$G$411,$D15,'25.04'!$F$7:$F$411,H$3) -> 0 | I15: =sumifs('25.04'!$H$7:$H$411,'25.04'!$G$7:$G$411,$D15,'25.04'!$F$7:$F$411,I$3) -> 0 | J15: =sumifs('25.04'!$H$7:$H$411,'25.04'!$G$7:$G$411,$D15,'25.04'!$F$7:$F$411,J$3) -> 0 | K15: =sumifs('25.04'!$H$7:$H$411,'25.04'!$G$7:$G$411,$D15,'25.04'!$F$7:$F$411,K$3) -> 0 | L15: =sumifs('25.04'!$H$7:$H$411,'25.04'!$G$7:$G$411,$D15,'25.04'!$F$7:$F$411,L$3) -> 0 | M15: =sumifs('25.04'!$H$7:$H$411,'25.04'!$G$7:$G$411,$D15,'25.04'!$F$7:$F$411,M$3) -> 0 | N15: =sum(E15:M15) -> 0 | P15: =N15/sum(N$10:N$16) -> 0 | T15: =sumifs('25.04'!$H$7:$H$411,'25.04'!$J$7:$J$411,$D15,'25.04'!$K$7:$K$411,T$3) -> 0 | U15: =sumifs('25.04'!$H$7:$H$411,'25.04'!$J$7:$J$411,$D15,'25.04'!$K$7:$K$411,U$3) -> 0 | V15: =sumifs('25.04'!$H$7:$H$411,'25.04'!$J$7:$J$411,$D15,'25.04'!$K$7:$K$411,V$3) -> 0 | W15: =sumifs('25.04'!$H$7:$H$411,'25.04'!$J$7:$J$411,$D15,'25.04'!$K$7:$K$411,W$3) -> 0 | X15: =sumifs('25.04'!$H$7:$H$411,'25.04'!$J$7:$J$411,$D15,'25.04'!$K$7:$K$411,X$3) -> 0 | Y15: =sumifs('25.04'!$H$7:$H$411,'25.04'!$J$7:$J$411,$D15,'25.04'!$K$7:$K$411,Y$3) -> 0 | Z15: =sumifs('25.04'!$H$7:$H$411,'25.04'!$J$7:$J$411,$D15,'25.04'!$K$7:$K$411,Z$3) -> 0 | AA15: =sumifs('25.04'!$H$7:$H$411,'25.04'!$J$7:$J$411,$D15,'25.04'!$K$7:$K$411,AA$3) -> 0 | AB15: =sumifs('25.04'!$H$7:$H$411,'25.04'!$J$7:$J$411,$D15,'25.04'!$K$7:$K$411,AB$3) -> 0 | AC15: =sum(T15:AB15) -> 0
C16: 45079 | D16: Museum | E16: =sumifs('25.04'!$H$7:$H$411,'25.04'!$G$7:$G$411,$D16,'25.04'!$F$7:$F$411,E$3) -> 0 | F16: =sumifs('25.04'!$H$7:$H$411,'25.04'!$G$7:$G$411,$D16,'25.04'!$F$7:$F$411,F$3) -> 0 | G16: =sumifs('25.04'!$H$7:$H$411,'25.04'!$G$7:$G$411,$D16,'25.04'!$F$7:$F$411,G$3) -> 0 | H16: =sumifs('25.04'!$H$7:$H$411,'25.04'!$G$7:$G$411,$D16,'25.04'!$F$7:$F$411,H$3) -> 0 | I16: =sumifs('25.04'!$H$7:$H$411,'25.04'!$G$7:$G$411,$D16,'25.04'!$F$7:$F$411,I$3) -> 0 | J16: =sumifs('25.04'!$H$7:$H$411,'25.04'!$G$7:$G$411,$D16,'25.04'!$F$7:$F$411,J$3) -> 0 | K16: =sumifs('25.04'!$H$7:$H$411,'25.04'!$G$7:$G$411,$D16,'25.04'!$F$7:$F$411,K$3) -> 0 | L16: =sumifs('25.04'!$H$7:$H$411,'25.04'!$G$7:$G$411,$D16,'25.04'!$F$7:$F$411,L$3) -> 0 | M16: =sumifs('25.04'!$H$7:$H$411,'25.04'!$G$7:$G$411,$D16,'25.04'!$F$7:$F$411,M$3) -> 0 | N16: =sum(E16:M16) -> 0 | P16: =N16/sum(N$10:N$16) -> 0 | T16: =sumifs('25.04'!$H$7:$H$411,'25.04'!$J$7:$J$411,$D16,'25.04'!$K$7:$K$411,T$3) -> 0 | U16: =sumifs('25.04'!$H$7:$H$411,'25.04'!$J$7:$J$411,$D16,'25.04'!$K$7:$K$411,U$3) -> 0 | V16: =sumifs('25.04'!$H$7:$H$411,'25.04'!$J$7:$J$411,$D16,'25.04'!$K$7:$K$411,V$3) -> 0 | W16: =sumifs('25.04'!$H$7:$H$411,'25.04'!$J$7:$J$411,$D16,'25.04'!$K$7:$K$411,W$3) -> 0 | X16: =sumifs('25.04'!$H$7:$H$411,'25.04'!$J$7:$J$411,$D16,'25.04'!$K$7:$K$411,X$3) -> 0 | Y16: =sumifs('25.04'!$H$7:$H$411,'25.04'!$J$7:$J$411,$D16,'25.04'!$K$7:$K$411,Y$3) -> 0 | Z16: =sumifs('25.04'!$H$7:$H$411,'25.04'!$J$7:$J$411,$D16,'25.04'!$K$7:$K$411,Z$3) -> 0 | AA16: =sumifs('25.04'!$H$7:$H$411,'25.04'!$J$7:$J$411,$D16,'25.04'!$K$7:$K$411,AA$3) -> 0 | AB16: =sumifs('25.04'!$H$7:$H$411,'25.04'!$J$7:$J$411,$D16,'25.04'!$K$7:$K$411,AB$3) -> 0 | AC16: =sum(T16:AB16) -> 0
C17: 3 | D17: For give | E17: =sumifs('25.04'!$H$7:$H$411,'25.04'!$G$7:$G$411,$D17,'25.04'!$F$7:$F$411,E$3) -> 0 | F17: =sumifs('25.04'!$H$7:$H$411,'25.04'!$G$7:$G$411,$D17,'25.04'!$F$7:$F$411,F$3) -> 0 | G17: =sumifs('25.04'!$H$7:$H$411,'25.04'!$G$7:$G$411,$D17,'25.04'!$F$7:$F$411,G$3) -> 0 | H17: =sumifs('25.04'!$H$7:$H$411,'25.04'!$G$7:$G$411,$D17,'25.04'!$F$7:$F$411,H$3) -> 0 | I17: =sumifs('25.04'!$H$7:$H$411,'25.04'!$G$7:$G$411,$D17,'25.04'!$F$7:$F$411,I$3) -> 0 | J17: =sumifs('25.04'!$H$7:$H$411,'25.04'!$G$7:$G$411,$D17,'25.04'!$F$7:$F$411,J$3) -> 0 | K17: =sumifs('25.04'!$H$7:$H$411,'25.04'!$G$7:$G$411,$D17,'25.04'!$F$7:$F$411,K$3) -> 0 | L17: =sumifs('25.04'!$H$7:$H$411,'25.04'!$G$7:$G$411,$D17,'25.04'!$F$7:$F$411,L$3) -> 0 | M17: =sumifs('25.04'!$H$7:$H$411,'25.04'!$G$7:$G$411,$D17,'25.04'!$F$7:$F$411,M$3) -> 0 | N17: =sum(E17:M17) -> 0 | P17: =N17/sum(N$17:N$22) -> #DIV/0! | R17: =sum(N17:N22) -> 0 | S17: =R17/sum($R$4:$R$49) -> 0 | T17: =sumifs('25.04'!$H$7:$H$411,'25.04'!$J$7:$J$411,$D17,'25.04'!$K$7:$K$411,T$3) -> 0 | U17: =sumifs('25.04'!$H$7:$H$411,'25.04'!$J$7:$J$411,$D17,'25.04'!$K$7:$K$411,U$3) -> 0 | V17: =sumifs('25.04'!$H$7:$H$411,'25.04'!$J$7:$J$411,$D17,'25.04'!$K$7:$K$411,V$3) -> 0 | W17: =sumifs('25.04'!$H$7:$H$411,'25.04'!$J$7:$J$411,$D17,'25.04'!$K$7:$K$411,W$3) -> 0 | X17: =sumifs('25.04'!$H$7:$H$411,'25.04'!$J$7:$J$411,$D17,'25.04'!$K$7:$K$411,X$3) -> 0 | Y17: =sumifs('25.04'!$H$7:$H$411,'25.04'!$J$7:$J$411,$D17,'25.04'!$K$7:$K$411,Y$3) -> 0 | Z17: =sumifs('25.04'!$H$7:$H$411,'25.04'!$J$7:$J$411,$D17,'25.04'!$K$7:$K$411,Z$3) -> 0 | AA17: =sumifs('25.04'!$H$7:$H$411,'25.04'!$J$7:$J$411,$D17,'25.04'!$K$7:$K$411,AA$3) -> 0 | AB17: =sumifs('25.04'!$H$7:$H$411,'25.04'!$J$7:$J$411,$D17,'25.04'!$K$7:$K$411,AB$3) -> 0 | AC17: =sum(T17:AB17) -> 0
A18: 3 | B18: For give | C18: 44929 | D18: Funeral | E18: =sumifs('25.04'!$H$7:$H$411,'25.04'!$G$7:$G$411,$D18,'25.04'!$F$7:$F$411,E$3) -> 0 | F18: =sumifs('25.04'!$H$7:$H$411,'25.04'!$G$7:$G$411,$D18,'25.04'!$F$7:$F$411,F$3) -> 0 | G18: =sumifs('25.04'!$H$7:$H$411,'25.04'!$G$7:$G$411,$D18,'25.04'!$F$7:$F$411,G$3) -> 0 | H18: =sumifs('25.04'!$H$7:$H$411,'25.04'!$G$7:$G$411,$D18,'25.04'!$F$7:$F$411,H$3) -> 0 | I18: =sumifs('25.04'!$H$7:$H$411,'25.04'!$G$7:$G$411,$D18,'25.04'!$F$7:$F$411,I$3) -> 0 | J18: =sumifs('25.04'!$H$7:$H$411,'25.04'!$G$7:$G$411,$D18,'25.04'!$F$7:$F$411,J$3) -> 0 | K18: =sumifs('25.04'!$H$7:$H$411,'25.04'!$G$7:$G$411,$D18,'25.04'!$F$7:$F$411,K$3) -> 0 | L18: =sumifs('25.04'!$H$7:$H$411,'25.04'!$G$7:$G$411,$D18,'25.04'!$F$7:$F$411,L$3) -> 0 | M18: =sumifs('25.04'!$H$7:$H$411,'25.04'!$G$7:$G$411,$D18,'25.04'!$F$7:$F$411,M$3) -> 0 | N18: =sum(E18:M18) -> 0 | P18: =N18/sum(N$17:N$22) -> #DIV/0! | T18: =sumifs('25.04'!$H$7:$H$411,'25.04'!$J$7:$J$411,$D18,'25.04'!$K$7:$K$411,T$3) -> 0 | U18: =sumifs('25.04'!$H$7:$H$411,'25.04'!$J$7:$J$411,$D18,'25.04'!$K$7:$K$411,U$3) -> 0 | V18: =sumifs('25.04'!$H$7:$H$411,'25.04'!$J$7:$J$411,$D18,'25.04'!$K$7:$K$411,V$3) -> 0 | W18: =sumifs('25.04'!$H$7:$H$411,'25.04'!$J$7:$J$411,$D18,'25.04'!$K$7:$K$411,W$3) -> 0 | X18: =sumifs('25.04'!$H$7:$H$411,'25.04'!$J$7:$J$411,$D18,'25.04'!$K$7:$K$411,X$3) -> 0 | Y18: =sumifs('25.04'!$H$7:$H$411,'25.04'!$J$7:$J$411,$D18,'25.04'!$K$7:$K$411,Y$3) -> 0 | Z18: =sumifs('25.04'!$H$7:$H$411,'25.04'!$J$7:$J$411,$D18,'25.04'!$K$7:$K$411,Z$3) -> 0 | AA18: =sumifs('25.04'!$H$7:$H$411,'25.04'!$J$7:$J$411,$D18,'25.04'!$K$7:$K$411,AA$3) -> 0 | AB18: =sumifs('25.04'!$H$7:$H$411,'25.04'!$J$7:$J$411,$D18,'25.04'!$K$7:$K$411,AB$3) -> 0 | AC18: =sum(T18:AB18) -> 0
C19: 44960 | D19: Wedding | E19: =sumifs('25.04'!$H$7:$H$411,'25.04'!$G$7:$G$411,$D19,'25.04'!$F$7:$F$411,E$3) -> 0 | F19: =sumifs('25.04'!$H$7:$H$411,'25.04'!$G$7:$G$411,$D19,'25.04'!$F$7:$F$411,F$3) -> 0 | G19: =sumifs('25.04'!$H$7:$H$411,'25.04'!$G$7:$G$411,$D19,'25.04'!$F$7:$F$411,G$3) -> 0 | H19: =sumifs('25.04'!$H$7:$H$411,'25.04'!$G$7:$G$411,$D19,'25.04'!$F$7:$F$411,H$3) -> 0 | I19: =sumifs('25.04'!$H$7:$H$411,'25.04'!$G$7:$G$411,$D19,'25.04'!$F$7:$F$411,I$3) -> 0 | J19: =sumifs('25.04'!$H$7:$H$411,'25.04'!$G$7:$G$411,$D19,'25.04'!$F$7:$F$411,J$3) -> 0 | K19: =sumifs('25.04'!$H$7:$H$411,'25.04'!$G$7:$G$411,$D19,'25.04'!$F$7:$F$411,K$3) -> 0 | L19: =sumifs('25.04'!$H$7:$H$411,'25.04'!$G$7:$G$411,$D19,'25.04'!$F$7:$F$411,L$3) -> 0 | M19: =sumifs('25.04'!$H$7:$H$411,'25.04'!$G$7:$G$411,$D19,'25.04'!$F$7:$F$411,M$3) -> 0 | N19: =sum(E19:M19) -> 0 | P19: =N19/sum(N$17:N$22) -> #DIV/0! | T19: =sumifs('25.04'!$H$7:$H$411,'25.04'!$J$7:$J$411,$D19,'25.04'!$K$7:$K$411,T$3) -> 0 | U19: =sumifs('25.04'!$H$7:$H$411,'25.04'!$J$7:$J$411,$D19,'25.04'!$K$7:$K$411,U$3) -> 0 | V19: =sumifs('25.04'!$H$7:$H$411,'25.04'!$J$7:$J$411,$D19,'25.04'!$K$7:$K$411,V$3) -> 0 | W19: =sumifs('25.04'!$H$7:$H$411,'25.04'!$J$7:$J$411,$D19,'25.04'!$K$7:$K$411,W$3) -> 0 | X19: =sumifs('25.04'!$H$7:$H$411,'25.04'!$J$7:$J$411,$D19,'25.04'!$K$7:$K$411,X$3) -> 0 | Y19: =sumifs('25.04'!$H$7:$H$411,'25.04'!$J$7:$J$411,$D19,'25.04'!$K$7:$K$411,Y$3) -> 0 | Z19: =sumifs('25.04'!$H$7:$H$411,'25.04'!$J$7:$J$411,$D19,'25.04'!$K$7:$K$411,Z$3) -> 0 | AA19: =sumifs('25.04'!$H$7:$H$411,'25.04'!$J$7:$J$411,$D19,'25.04'!$K$7:$K$411,AA$3) -> 0 | AB19: =sumifs('25.04'!$H$7:$H$411,'25.04'!$J$7:$J$411,$D19,'25.04'!$K$7:$K$411,AB$3) -> 0 | AC19: =sum(T19:AB19) -> 0
C20: 44988 | D20: Gift | E20: =sumifs('25.04'!$H$7:$H$411,'25.04'!$G$7:$G$411,$D20,'25.04'!$F$7:$F$411,E$3) -> 0 | F20: =sumifs('25.04'!$H$7:$H$411,'25.04'!$G$7:$G$411,$D20,'25.04'!$F$7:$F$411,F$3) -> 0 | G20: =sumifs('25.04'!$H$7:$H$411,'25.04'!$G$7:$G$411,$D20,'25.04'!$F$7:$F$411,G$3) -> 0 | H20: =sumifs('25.04'!$H$7:$H$411,'25.04'!$G$7:$G$411,$D20,'25.04'!$F$7:$F$411,H$3) -> 0 | I20: =sumifs('25.04'!$H$7:$H$411,'25.04'!$G$7:$G$411,$D20,'25.04'!$F$7:$F$411,I$3) -> 0 | J20: =sumifs('25.04'!$H$7:$H$411,'25.04'!$G$7:$G$411,$D20,'25.04'!$F$7:$F$411,J$3) -> 0 | K20: =sumifs('25.04'!$H$7:$H$411,'25.04'!$G$7:$G$411,$D20,'25.04'!$F$7:$F$411,K$3) -> 0 | L20: =sumifs('25.04'!$H$7:$H$411,'25.04'!$G$7:$G$411,$D20,'25.04'!$F$7:$F$411,L$3) -> 0 | M20: =sumifs('25.04'!$H$7:$H$411,'25.04'!$G$7:$G$411,$D20,'25.04'!$F$7:$F$411,M$3) -> 0 | N20: =sum(E20:M20) -> 0 | P20: =N20/sum(N$17:N$22) -> #DIV/0! | T20: =sumifs('25.04'!$H$7:$H$411,'25.04'!$J$7:$J$411,$D20,'25.04'!$K$7:$K$411,T$3) -> 0 | U20: =sumifs('25.04'!$H$7:$H$411,'25.04'!$J$7:$J$411,$D20,'25.04'!$K$7:$K$411,U$3) -> 0 | V20: =sumifs('25.04'!$H$7:$H$411,'25.04'!$J$7:$J$411,$D20,'25.04'!$K$7:$K$411,V$3) -> 0 | W20: =sumifs('25.04'!$H$7:$H$411,'25.04'!$J$7:$J$411,$D20,'25.04'!$K$7:$K$411,W$3) -> 0 | X20: =sumifs('25.04'!$H$7:$H$411,'25.04'!$J$7:$J$411,$D20,'25.04'!$K$7:$K$411,X$3) -> 0 | Y20: =sumifs('25.04'!$H$7:$H$411,'25.04'!$J$7:$J$411,$D20,'25.04'!$K$7:$K$411,Y$3) -> 0 | Z20: =sumifs('25.04'!$H$7:$H$411,'25.04'!$J$7:$J$411,$D20,'25.04'!$K$7:$K$411,Z$3) -> 0 | AA20: =sumifs('25.04'!$H$7:$H$411,'25.04'!$J$7:$J$411,$D20,'25.04'!$K$7:$K$411,AA$3) -> 0 | AB20: =sumifs('25.04'!$H$7:$H$411,'25.04'!$J$7:$J$411,$D20,'25.04'!$K$7:$K$411,AB$3) -> 0 | AC20: =sum(T20:AB20) -> 0
C21: 45019 | D21: Charity | E21: =sumifs('25.04'!$H$7:$H$411,'25.04'!$G$7:$G$411,$D21,'25.04'!$F$7:$F$411,E$3) -> 0 | F21: =sumifs('25.04'!$H$7:$H$411,'25.04'!$G$7:$G$411,$D21,'25.04'!$F$7:$F$411,F$3) -> 0 | G21: =sumifs('25.04'!$H$7:$H$411,'25.04'!$G$7:$G$411,$D21,'25.04'!$F$7:$F$411,G$3) -> 0 | H21: =sumifs('25.04'!$H$7:$H$411,'25.04'!$G$7:$G$411,$D21,'25.04'!$F$7:$F$411,H$3) -> 0 | I21: =sumifs('25.04'!$H$7:$H$411,'25.04'!$G$7:$G$411,$D21,'25.04'!$F$7:$F$411,I$3) -> 0 | J21: =sumifs('25.04'!$H$7:$H$411,'25.04'!$G$7:$G$411,$D21,'25.04'!$F$7:$F$411,J$3) -> 0 | K21: =sumifs('25.04'!$H$7:$H$411,'25.04'!$G$7:$G$411,$D21,'25.04'!$F$7:$F$411,K$3) -> 0 | L21: =sumifs('25.04'!$H$7:$H$411,'25.04'!$G$7:$G$411,$D21,'25.04'!$F$7:$F$411,L$3) -> 0 | M21: =sumifs('25.04'!$H$7:$H$411,'25.04'!$G$7:$G$411,$D21,'25.04'!$F$7:$F$411,M$3) -> 0 | N21: =sum(E21:M21) -> 0 | P21: =N21/sum(N$17:N$22) -> #DIV/0! | T21: =sumifs('25.04'!$H$7:$H$411,'25.04'!$J$7:$J$411,$D21,'25.04'!$K$7:$K$411,T$3) -> 0 | U21: =sumifs('25.04'!$H$7:$H$411,'25.04'!$J$7:$J$411,$D21,'25.04'!$K$7:$K$411,U$3) -> 0 | V21: =sumifs('25.04'!$H$7:$H$411,'25.04'!$J$7:$J$411,$D21,'25.04'!$K$7:$K$411,V$3) -> 0 | W21: =sumifs('25.04'!$H$7:$H$411,'25.04'!$J$7:$J$411,$D21,'25.04'!$K$7:$K$411,W$3) -> 0 | X21: =sumifs('25.04'!$H$7:$H$411,'25.04'!$J$7:$J$411,$D21,'25.04'!$K$7:$K$411,X$3) -> 0 | Y21: =sumifs('25.04'!$H$7:$H$411,'25.04'!$J$7:$J$411,$D21,'25.04'!$K$7:$K$411,Y$3) -> 0 | Z21: =sumifs('25.04'!$H$7:$H$411,'25.04'!$J$7:$J$411,$D21,'25.04'!$K$7:$K$411,Z$3) -> 0 | AA21: =sumifs('25.04'!$H$7:$H$411,'25.04'!$J$7:$J$411,$D21,'25.04'!$K$7:$K$411,AA$3) -> 0 | AB21: =sumifs('25.04'!$H$7:$H$411,'25.04'!$J$7:$J$411,$D21,'25.04'!$K$7:$K$411,AB$3) -> 0 | AC21: =sum(T21:AB21) -> 0
C22: 45049 | D22: Spirituality | E22: =sumifs('25.04'!$H$7:$H$411,'25.04'!$G$7:$G$411,$D22,'25.04'!$F$7:$F$411,E$3) -> 0 | F22: =sumifs('25.04'!$H$7:$H$411,'25.04'!$G$7:$G$411,$D22,'25.04'!$F$7:$F$411,F$3) -> 0 | G22: =sumifs('25.04'!$H$7:$H$411,'25.04'!$G$7:$G$411,$D22,'25.04'!$F$7:$F$411,G$3) -> 0 | H22: =sumifs('25.04'!$H$7:$H$411,'25.04'!$G$7:$G$411,$D22,'25.04'!$F$7:$F$411,H$3) -> 0 | I22: =sumifs('25.04'!$H$7:$H$411,'25.04'!$G$7:$G$411,$D22,'25.04'!$F$7:$F$411,I$3) -> 0 | J22: =sumifs('25.04'!$H$7:$H$411,'25.04'!$G$7:$G$411,$D22,'25.04'!$F$7:$F$411,J$3) -> 0 | K22: =sumifs('25.04'!$H$7:$H$411,'25.04'!$G$7:$G$411,$D22,'25.04'!$F$7:$F$411,K$3) -> 0 | L22: =sumifs('25.04'!$H$7:$H$411,'25.04'!$G$7:$G$411,$D22,'25.04'!$F$7:$F$411,L$3) -> 0 | M22: =sumifs('25.04'!$H$7:$H$411,'25.04'!$G$7:$G$411,$D22,'25.04'!$F$7:$F$411,M$3) -> 0 | N22: =sum(E22:M22) -> 0 | P22: =N22/sum(N$17:N$22) -> #DIV/0! | T22: =sumifs('25.04'!$H$7:$H$411,'25.04'!$J$7:$J$411,$D22,'25.04'!$K$7:$K$411,T$3) -> 0 | U22: =sumifs('25.04'!$H$7:$H$411,'25.04'!$J$7:$J$411,$D22,'25.04'!$K$7:$K$411,U$3) -> 0 | V22: =sumifs('25.04'!$H$7:$H$411,'25.04'!$J$7:$J$411,$D22,'25.04'!$K$7:$K$411,V$3) -> 0 | W22: =sumifs('25.04'!$H$7:$H$411,'25.04'!$J$7:$J$411,$D22,'25.04'!$K$7:$K$411,W$3) -> 0 | X22: =sumifs('25.04'!$H$7:$H$411,'25.04'!$J$7:$J$411,$D22,'25.04'!$K$7:$K$411,X$3) -> 0 | Y22: =sumifs('25.04'!$H$7:$H$411,'25.04'!$J$7:$J$411,$D22,'25.04'!$K$7:$K$411,Y$3) -> 0 | Z22: =sumifs('25.04'!$H$7:$H$411,'25.04'!$J$7:$J$411,$D22,'25.04'!$K$7:$K$411,Z$3) -> 0 | AA22: =sumifs('25.04'!$H$7:$H$411,'25.04'!$J$7:$J$411,$D22,'25.04'!$K$7:$K$411,AA$3) -> 0 | AB22: =sumifs('25.04'!$H$7:$H$411,'25.04'!$J$7:$J$411,$D22,'25.04'!$K$7:$K$411,AB$3) -> 0 | AC22: =sum(T22:AB22) -> 0
C23: 4 | D23: Health | E23: =sumifs('25.04'!$H$7:$H$411,'25.04'!$G$7:$G$411,$D23,'25.04'!$F$7:$F$411,E$3) -> 0 | F23: =sumifs('25.04'!$H$7:$H$411,'25.04'!$G$7:$G$411,$D23,'25.04'!$F$7:$F$411,F$3) -> 0 | G23: =sumifs('25.04'!$H$7:$H$411,'25.04'!$G$7:$G$411,$D23,'25.04'!$F$7:$F$411,G$3) -> 0 | H23: =sumifs('25.04'!$H$7:$H$411,'25.04'!$G$7:$G$411,$D23,'25.04'!$F$7:$F$411,H$3) -> 0 | I23: =sumifs('25.04'!$H$7:$H$411,'25.04'!$G$7:$G$411,$D23,'25.04'!$F$7:$F$411,I$3) -> 0 | J23: =sumifs('25.04'!$H$7:$H$411,'25.04'!$G$7:$G$411,$D23,'25.04'!$F$7:$F$411,J$3) -> 0 | K23: =sumifs('25.04'!$H$7:$H$411,'25.04'!$G$7:$G$411,$D23,'25.04'!$F$7:$F$411,K$3) -> 0 | L23: =sumifs('25.04'!$H$7:$H$411,'25.04'!$G$7:$G$411,$D23,'25.04'!$F$7:$F$411,L$3) -> 0 | M23: =sumifs('25.04'!$H$7:$H$411,'25.04'!$G$7:$G$411,$D23,'25.04'!$F$7:$F$411,M$3) -> 0 | N23: =sum(E23:M23) -> 0 | P23: =N23/sum(N$23:N$28) -> #DIV/0! | R23: =sum(N23:N28) -> 0 | S23: =R22/sum($R$4:$R$49) -> 0 | T23: =sumifs('25.04'!$H$7:$H$411,'25.04'!$J$7:$J$411,$D23,'25.04'!$K$7:$K$411,T$3) -> 0 | U23: =sumifs('25.04'!$H$7:$H$411,'25.04'!$J$7:$J$411,$D23,'25.04'!$K$7:$K$411,U$3) -> 0 | V23: =sumifs('25.04'!$H$7:$H$411,'25.04'!$J$7:$J$411,$D23,'25.04'!$K$7:$K$411,V$3) -> 0 | W23: =sumifs('25.04'!$H$7:$H$411,'25.04'!$J$7:$J$411,$D23,'25.04'!$K$7:$K$411,W$3) -> 0 | X23: =sumifs('25.04'!$H$7:$H$411,'25.04'!$J$7:$J$411,$D23,'25.04'!$K$7:$K$411,X$3) -> 0 | Y23: =sumifs('25.04'!$H$7:$H$411,'25.04'!$J$7:$J$411,$D23,'25.04'!$K$7:$K$411,Y$3) -> 0 | Z23: =sumifs('25.04'!$H$7:$H$411,'25.04'!$J$7:$J$411,$D23,'25.04'!$K$7:$K$411,Z$3) -> 0 | AA23: =sumifs('25.04'!$H$7:$H$411,'25.04'!$J$7:$J$411,$D23,'25.04'!$K$7:$K$411,AA$3) -> 0 | AB23: =sumifs('25.04'!$H$7:$H$411,'25.04'!$J$7:$J$411,$D23,'25.04'!$K$7:$K$411,AB$3) -> 0 | AC23: =sum(T23:AB23) -> 0
A24: 4 | B24: Health | C24: 44930 | D24: Medical exam | E24: =sumifs('25.04'!$H$7:$H$411,'25.04'!$G$7:$G$411,$D24,'25.04'!$F$7:$F$411,E$3) -> 0 | F24: =sumifs('25.04'!$H$7:$H$411,'25.04'!$G$7:$G$411,$D24,'25.04'!$F$7:$F$411,F$3) -> 0 | G24: =sumifs('25.04'!$H$7:$H$411,'25.04'!$G$7:$G$411,$D24,'25.04'!$F$7:$F$411,G$3) -> 0 | H24: =sumifs('25.04'!$H$7:$H$411,'25.04'!$G$7:$G$411,$D24,'25.04'!$F$7:$F$411,H$3) -> 0 | I24: =sumifs('25.04'!$H$7:$H$411,'25.04'!$G$7:$G$411,$D24,'25.04'!$F$7:$F$411,I$3) -> 0 | J24: =sumifs('25.04'!$H$7:$H$411,'25.04'!$G$7:$G$411,$D24,'25.04'!$F$7:$F$411,J$3) -> 0 | K24: =sumifs('25.04'!$H$7:$H$411,'25.04'!$G$7:$G$411,$D24,'25.04'!$F$7:$F$411,K$3) -> 0 | L24: =sumifs('25.04'!$H$7:$H$411,'25.04'!$G$7:$G$411,$D24,'25.04'!$F$7:$F$411,L$3) -> 0 | M24: =sumifs('25.04'!$H$7:$H$411,'25.04'!$G$7:$G$411,$D24,'25.04'!$F$7:$F$411,M$3) -> 0 | N24: =sum(E24:M24) -> 0 | P24: =N24/sum(N$23:N$28) -> #DIV/0! | T24: =sumifs('25.04'!$H$7:$H$411,'25.04'!$J$7:$J$411,$D24,'25.04'!$K$7:$K$411,T$3) -> 0 | U24: =sumifs('25.04'!$H$7:$H$411,'25.04'!$J$7:$J$411,$D24,'25.04'!$K$7:$K$411,U$3) -> 0 | V24: =sumifs('25.04'!$H$7:$H$411,'25.04'!$J$7:$J$411,$D24,'25.04'!$K$7:$K$411,V$3) -> 0 | W24: =sumifs('25.04'!$H$7:$H$411,'25.04'!$J$7:$J$411,$D24,'25.04'!$K$7:$K$411,W$3) -> 0 | X24: =sumifs('25.04'!$H$7:$H$411,'25.04'!$J$7:$J$411,$D24,'25.04'!$K$7:$K$411,X$3) -> 0 | Y24: =sumifs('25.04'!$H$7:$H$411,'25.04'!$J$7:$J$411,$D24,'25.04'!$K$7:$K$411,Y$3) -> 0 | Z24: =sumifs('25.04'!$H$7:$H$411,'25.04'!$J$7:$J$411,$D24,'25.04'!$K$7:$K$411,Z$3) -> 0 | AA24: =sumifs('25.04'!$H$7:$H$411,'25.04'!$J$7:$J$411,$D24,'25.04'!$K$7:$K$411,AA$3) -> 0 | AB24: =sumifs('25.04'!$H$7:$H$411,'25.04'!$J$7:$J$411,$D24,'25.04'!$K$7:$K$411,AB$3) -> 0 | AC24: =sum(T24:AB24) -> 0
D25: Tablets | E25: =sumifs('25.04'!$H$7:$H$411,'25.04'!$G$7:$G$411,$D25,'25.04'!$F$7:$F$411,E$3) -> 0 | F25: =sumifs('25.04'!$H$7:$H$411,'25.04'!$G$7:$G$411,$D25,'25.04'!$F$7:$F$411,F$3) -> 0 | G25: =sumifs('25.04'!$H$7:$H$411,'25.04'!$G$7:$G$411,$D25,'25.04'!$F$7:$F$411,G$3) -> 0 | H25: =sumifs('25.04'!$H$7:$H$411,'25.04'!$G$7:$G$411,$D25,'25.04'!$F$7:$F$411,H$3) -> 0 | I25: =sumifs('25.04'!$H$7:$H$411,'25.04'!$G$7:$G$411,$D25,'25.04'!$F$7:$F$411,I$3) -> 0 | J25: =sumifs('25.04'!$H$7:$H$411,'25.04'!$G$7:$G$411,$D25,'25.04'!$F$7:$F$411,J$3) -> 0 | K25: =sumifs('25.04'!$H$7:$H$411,'25.04'!$G$7:$G$411,$D25,'25.04'!$F$7:$F$411,K$3) -> 0 | L25: =sumifs('25.04'!$H$7:$H$411,'25.04'!$G$7:$G$411,$D25,'25.04'!$F$7:$F$411,L$3) -> 0 | M25: =sumifs('25.04'!$H$7:$H$411,'25.04'!$G$7:$G$411,$D25,'25.04'!$F$7:$F$411,M$3) -> 0 | N25: =sum(E25:M25) -> 0
C26: 44961 | D26: Body care | E26: =sumifs('25.04'!$H$7:$H$411,'25.04'!$G$7:$G$411,$D26,'25.04'!$F$7:$F$411,E$3) -> 0 | F26: =sumifs('25.04'!$H$7:$H$411,'25.04'!$G$7:$G$411,$D26,'25.04'!$F$7:$F$411,F$3) -> 0 | G26: =sumifs('25.04'!$H$7:$H$411,'25.04'!$G$7:$G$411,$D26,'25.04'!$F$7:$F$411,G$3) -> 0 | H26: =sumifs('25.04'!$H$7:$H$411,'25.04'!$G$7:$G$411,$D26,'25.04'!$F$7:$F$411,H$3) -> 0 | I26: =sumifs('25.04'!$H$7:$H$411,'25.04'!$G$7:$G$411,$D26,'25.04'!$F$7:$F$411,I$3) -> 0 | J26: =sumifs('25.04'!$H$7:$H$411,'25.04'!$G$7:$G$411,$D26,'25.04'!$F$7:$F$411,J$3) -> 0 | K26: =sumifs('25.04'!$H$7:$H$411,'25.04'!$G$7:$G$411,$D26,'25.04'!$F$7:$F$411,K$3) -> 0 | L26: =sumifs('25.04'!$H$7:$H$411,'25.04'!$G$7:$G$411,$D26,'25.04'!$F$7:$F$411,L$3) -> 0 | M26: =sumifs('25.04'!$H$7:$H$411,'25.04'!$G$7:$G$411,$D26,'25.04'!$F$7:$F$411,M$3) -> 0 | N26: =sum(E26:M26) -> 0 | P26: =N26/sum(N$23:N$28) -> #DIV/0! | T26: =sumifs('25.04'!$H$7:$H$411,'25.04'!$J$7:$J$411,$D26,'25.04'!$K$7:$K$411,T$3) -> 0 | U26: =sumifs('25.04'!$H$7:$H$411,'25.04'!$J$7:$J$411,$D26,'25.04'!$K$7:$K$411,U$3) -> 0 | V26: =sumifs('25.04'!$H$7:$H$411,'25.04'!$J$7:$J$411,$D26,'25.04'!$K$7:$K$411,V$3) -> 0 | W26: =sumifs('25.04'!$H$7:$H$411,'25.04'!$J$7:$J$411,$D26,'25.04'!$K$7:$K$411,W$3) -> 0 | X26: =sumifs('25.04'!$H$7:$H$411,'25.04'!$J$7:$J$411,$D26,'25.04'!$K$7:$K$411,X$3) -> 0 | Y26: =sumifs('25.04'!$H$7:$H$411,'25.04'!$J$7:$J$411,$D26,'25.04'!$K$7:$K$411,Y$3) -> 0 | Z26: =sumifs('25.04'!$H$7:$H$411,'25.04'!$J$7:$J$411,$D26,'25.04'!$K$7:$K$411,Z$3) -> 0 | AA26: =sumifs('25.04'!$H$7:$H$411,'25.04'!$J$7:$J$411,$D26,'25.04'!$K$7:$K$411,AA$3) -> 0 | AB26: =sumifs('25.04'!$H$7:$H$411,'25.04'!$J$7:$J$411,$D26,'25.04'!$K$7:$K$411,AB$3) -> 0 | AC26: =sum(T26:AB26) -> 0
C27: 44989 | D27: Cosmetic | E27: =sumifs('25.04'!$H$7:$H$411,'25.04'!$G$7:$G$411,$D27,'25.04'!$F$7:$F$411,E$3) -> 0 | G27: =sumifs('25.04'!$H$7:$H$411,'25.04'!$G$7:$G$411,$D27,'25.04'!$F$7:$F$411,G$3) -> 0 | H27: =sumifs('25.04'!$H$7:$H$411,'25.04'!$G$7:$G$411,$D27,'25.04'!$F$7:$F$411,H$3) -> 0 | I27: =sumifs('25.04'!$H$7:$H$411,'25.04'!$G$7:$G$411,$D27,'25.04'!$F$7:$F$411,I$3) -> 0 | J27: =sumifs('25.04'!$H$7:$H$411,'25.04'!$G$7:$G$411,$D27,'25.04'!$F$7:$F$411,J$3) -> 0 | K27: =sumifs('25.04'!$H$7:$H$411,'25.04'!$G$7:$G$411,$D27,'25.04'!$F$7:$F$411,K$3) -> 0 | L27: =sumifs('25.04'!$H$7:$H$411,'25.04'!$G$7:$G$411,$D27,'25.04'!$F$7:$F$411,L$3) -> 0 | M27: =sumifs('25.04'!$H$7:$H$411,'25.04'!$G$7:$G$411,$D27,'25.04'!$F$7:$F$411,M$3) -> 0 | N27: =sum(E27:M27) -> 0 | P27: =N27/sum(N$23:N$28) -> #DIV/0! | T27: =sumifs('25.04'!$H$7:$H$411,'25.04'!$J$7:$J$411,$D27,'25.04'!$K$7:$K$411,T$3) -> 0 | U27: =sumifs('25.04'!$H$7:$H$411,'25.04'!$J$7:$J$411,$D27,'25.04'!$K$7:$K$411,U$3) -> 0 | V27: =sumifs('25.04'!$H$7:$H$411,'25.04'!$J$7:$J$411,$D27,'25.04'!$K$7:$K$411,V$3) -> 0 | W27: =sumifs('25.04'!$H$7:$H$411,'25.04'!$J$7:$J$411,$D27,'25.04'!$K$7:$K$411,W$3) -> 0 | X27: =sumifs('25.04'!$H$7:$H$411,'25.04'!$J$7:$J$411,$D27,'25.04'!$K$7:$K$411,X$3) -> 0 | Y27: =sumifs('25.04'!$H$7:$H$411,'25.04'!$J$7:$J$411,$D27,'25.04'!$K$7:$K$411,Y$3) -> 0 | Z27: =sumifs('25.04'!$H$7:$H$411,'25.04'!$J$7:$J$411,$D27,'25.04'!$K$7:$K$411,Z$3) -> 0 | AA27: =sumifs('25.04'!$H$7:$H$411,'25.04'!$J$7:$J$411,$D27,'25.04'!$K$7:$K$411,AA$3) -> 0 | AB27: =sumifs('25.04'!$H$7:$H$411,'25.04'!$J$7:$J$411,$D27,'25.04'!$K$7:$K$411,AB$3) -> 0 | AC27: =sum(T27:AB27) -> 0
C28: 45020 | D28: Medical Insurrance | E28: =sumifs('25.04'!$H$7:$H$411,'25.04'!$G$7:$G$411,$D28,'25.04'!$F$7:$F$411,E$3) -> 0 | F28: =sumifs('25.04'!$H$7:$H$411,'25.04'!$G$7:$G$411,$D28,'25.04'!$F$7:$F$411,F$3) -> 0 | G28: =sumifs('25.04'!$H$7:$H$411,'25.04'!$G$7:$G$411,$D28,'25.04'!$F$7:$F$411,G$3) -> 0 | H28: =sumifs('25.04'!$H$7:$H$411,'25.04'!$G$7:$G$411,$D28,'25.04'!$F$7:$F$411,H$3) -> 0 | I28: =sumifs('25.04'!$H$7:$H$411,'25.04'!$G$7:$G$411,$D28,'25.04'!$F$7:$F$411,I$3) -> 0 | J28: =sumifs('25.04'!$H$7:$H$411,'25.04'!$G$7:$G$411,$D28,'25.04'!$F$7:$F$411,J$3) -> 0 | K28: =sumifs('25.04'!$H$7:$H$411,'25.04'!$G$7:$G$411,$D28,'25.04'!$F$7:$F$411,K$3) -> 0 | L28: =sumifs('25.04'!$H$7:$H$411,'25.04'!$G$7:$G$411,$D28,'25.04'!$F$7:$F$411,L$3) -> 0 | M28: =sumifs('25.04'!$H$7:$H$411,'25.04'!$G$7:$G$411,$D28,'25.04'!$F$7:$F$411,M$3) -> 0 | N28: =sum(E28:M28) -> 0 | P28: =N28/sum(N$23:N$28) -> #DIV/0! | T28: =sumifs('25.04'!$H$7:$H$411,'25.04'!$J$7:$J$411,$D28,'25.04'!$K$7:$K$411,T$3) -> 0 | U28: =sumifs('25.04'!$H$7:$H$411,'25.04'!$J$7:$J$411,$D28,'25.04'!$K$7:$K$411,U$3) -> 0 | V28: =sumifs('25.04'!$H$7:$H$411,'25.04'!$J$7:$J$411,$D28,'25.04'!$K$7:$K$411,V$3) -> 0 | W28: =sumifs('25.04'!$H$7:$H$411,'25.04'!$J$7:$J$411,$D28,'25.04'!$K$7:$K$411,W$3) -> 0 | X28: =sumifs('25.04'!$H$7:$H$411,'25.04'!$J$7:$J$411,$D28,'25.04'!$K$7:$K$411,X$3) -> 0 | Y28: =sumifs('25.04'!$H$7:$H$411,'25.04'!$J$7:$J$411,$D28,'25.04'!$K$7:$K$411,Y$3) -> 0 | Z28: =sumifs('25.04'!$H$7:$H$411,'25.04'!$J$7:$J$411,$D28,'25.04'!$K$7:$K$411,Z$3) -> 0 | AA28: =sumifs('25.04'!$H$7:$H$411,'25.04'!$J$7:$J$411,$D28,'25.04'!$K$7:$K$411,AA$3) -> 0 | AB28: =sumifs('25.04'!$H$7:$H$411,'25.04'!$J$7:$J$411,$D28,'25.04'!$K$7:$K$411,AB$3) -> 0 | AC28: =sum(T28:AB28) -> 0
A29: 5 | B29: Living | C29: a | D29: Go Market | E29: =sumifs('25.04'!$H$7:$H$411,'25.04'!$G$7:$G$411,$D29,'25.04'!$F$7:$F$411,E$3) -> 0 | F29: =sumifs('25.04'!$H$7:$H$411,'25.04'!$G$7:$G$411,$D29,'25.04'!$F$7:$F$411,F$3) -> 0 | G29: =sumifs('25.04'!$H$7:$H$411,'25.04'!$G$7:$G$411,$D29,'25.04'!$F$7:$F$411,G$3) -> 3403644 | H29: =sumifs('25.04'!$H$7:$H$411,'25.04'!$G$7:$G$411,$D29,'25.04'!$F$7:$F$411,H$3) -> 0 | I29: =sumifs('25.04'!$H$7:$H$411,'25.04'!$G$7:$G$411,$D29,'25.04'!$F$7:$F$411,I$3) -> 0 | J29: =sumifs('25.04'!$H$7:$H$411,'25.04'!$G$7:$G$411,$D29,'25.04'!$F$7:$F$411,J$3) -> 0 | K29: =sumifs('25.04'!$H$7:$H$411,'25.04'!$G$7:$G$411,$D29,'25.04'!$F$7:$F$411,K$3) -> 0 | L29: =sumifs('25.04'!$H$7:$H$411,'25.04'!$G$7:$G$411,$D29,'25.04'!$F$7:$F$411,L$3) -> 0 | M29: =sumifs('25.04'!$H$7:$H$411,'25.04'!$G$7:$G$411,$D29,'25.04'!$F$7:$F$411,M$3) -> 0 | N29: =sum(E29:M29) -> 3403644 | P29: =N29/sum(N$29:N$47) -> 0.95070031 | Q29: =N29/sum(N$29:N$31) -> 0.95070031 | T29: =sumifs('25.04'!$H$7:$H$411,'25.04'!$J$7:$J$411,$D29,'25.04'!$K$7:$K$411,T$3) -> 0 | U29: =sumifs('25.04'!$H$7:$H$411,'25.04'!$J$7:$J$411,$D29,'25.04'!$K$7:$K$411,U$3) -> 0 | V29: =sumifs('25.04'!$H$7:$H$411,'25.04'!$J$7:$J$411,$D29,'25.04'!$K$7:$K$411,V$3) -> 0 | W29: =sumifs('25.04'!$H$7:$H$411,'25.04'!$J$7:$J$411,$D29,'25.04'!$K$7:$K$411,W$3) -> 0 | X29: =sumifs('25.04'!$H$7:$H$411,'25.04'!$J$7:$J$411,$D29,'25.04'!$K$7:$K$411,X$3) -> 0 | Y29: =sumifs('25.04'!$H$7:$H$411,'25.04'!$J$7:$J$411,$D29,'25.04'!$K$7:$K$411,Y$3) -> 0 | Z29: =sumifs('25.04'!$H$7:$H$411,'25.04'!$J$7:$J$411,$D29,'25.04'!$K$7:$K$411,Z$3) -> 0 | AA29: =sumifs('25.04'!$H$7:$H$411,'25.04'!$J$7:$J$411,$D29,'25.04'!$K$7:$K$411,AA$3) -> 0 | AB29: =sumifs('25.04'!$H$7:$H$411,'25.04'!$J$7:$J$411,$D29,'25.04'!$K$7:$K$411,AB$3) -> 0 | AC29: =sum(T29:AB29) -> 0
C30: b | D30: Breakfast | E30: =sumifs('25.04'!$H$7:$H$411,'25.04'!$G$7:$G$411,$D30,'25.04'!$F$7:$F$411,E$3) -> 0 | F30: =sumifs('25.04'!$H$7:$H$411,'25.04'!$G$7:$G$411,$D30,'25.04'!$F$7:$F$411,F$3) -> 0 | G30: =sumifs('25.04'!$H$7:$H$411,'25.04'!$G$7:$G$411,$D30,'25.04'!$F$7:$F$411,G$3) -> 0 | H30: =sumifs('25.04'!$H$7:$H$411,'25.04'!$G$7:$G$411,$D30,'25.04'!$F$7:$F$411,H$3) -> 0 | I30: =sumifs('25.04'!$H$7:$H$411,'25.04'!$G$7:$G$411,$D30,'25.04'!$F$7:$F$411,I$3) -> 0 | J30: =sumifs('25.04'!$H$7:$H$411,'25.04'!$G$7:$G$411,$D30,'25.04'!$F$7:$F$411,J$3) -> 0 | K30: =sumifs('25.04'!$H$7:$H$411,'25.04'!$G$7:$G$411,$D30,'25.04'!$F$7:$F$411,K$3) -> 0 | L30: =sumifs('25.04'!$H$7:$H$411,'25.04'!$G$7:$G$411,$D30,'25.04'!$F$7:$F$411,L$3) -> 0 | M30: =sumifs('25.04'!$H$7:$H$411,'25.04'!$G$7:$G$411,$D30,'25.04'!$F$7:$F$411,M$3) -> 0 | N30: =sum(E30:M30) -> 0 | P30: =N30/sum(N$29:N$47) -> 0 | Q30: =N30/sum(N$29:N$31) -> 0 | T30: =sumifs('25.04'!$H$7:$H$411,'25.04'!$J$7:$J$411,$D30,'25.04'!$K$7:$K$411,T$3) -> 0 | U30: =sumifs('25.04'!$H$7:$H$411,'25.04'!$J$7:$J$411,$D30,'25.04'!$K$7:$K$411,U$3) -> 0 | V30: =sumifs('25.04'!$H$7:$H$411,'25.04'!$J$7:$J$411,$D30,'25.04'!$K$7:$K$411,V$3) -> 0 | W30: =sumifs('25.04'!$H$7:$H$411,'25.04'!$J$7:$J$411,$D30,'25.04'!$K$7:$K$411,W$3) -> 0 | X30: =sumifs('25.04'!$H$7:$H$411,'25.04'!$J$7:$J$411,$D30,'25.04'!$K$7:$K$411,X$3) -> 0 | Y30: =sumifs('25.04'!$H$7:$H$411,'25.04'!$J$7:$J$411,$D30,'25.04'!$K$7:$K$411,Y$3) -> 0 | Z30: =sumifs('25.04'!$H$7:$H$411,'25.04'!$J$7:$J$411,$D30,'25.04'!$K$7:$K$411,Z$3) -> 0 | AA30: =sumifs('25.04'!$H$7:$H$411,'25.04'!$J$7:$J$411,$D30,'25.04'!$K$7:$K$411,AA$3) -> 0 | AB30: =sumifs('25.04'!$H$7:$H$411,'25.04'!$J$7:$J$411,$D30,'25.04'!$K$7:$K$411,AB$3) -> 0 | AC30: =sum(T30:AB30) -> 0
C31: c | D31: Extra meal | E31: =sumifs('25.04'!$H$7:$H$411,'25.04'!$G$7:$G$411,$D31,'25.04'!$F$7:$F$411,E$3) -> 0 | F31: =sumifs('25.04'!$H$7:$H$411,'25.04'!$G$7:$G$411,$D31,'25.04'!$F$7:$F$411,F$3) -> 0 | G31: =sumifs('25.04'!$H$7:$H$411,'25.04'!$G$7:$G$411,$D31,'25.04'!$F$7:$F$411,G$3) -> 176500 | H31: =sumifs('25.04'!$H$7:$H$411,'25.04'!$G$7:$G$411,$D31,'25.04'!$F$7:$F$411,H$3) -> 0 | I31: =sumifs('25.04'!$H$7:$H$411,'25.04'!$G$7:$G$411,$D31,'25.04'!$F$7:$F$411,I$3) -> 0 | J31: =sumifs('25.04'!$H$7:$H$411,'25.04'!$G$7:$G$411,$D31,'25.04'!$F$7:$F$411,J$3) -> 0 | K31: =sumifs('25.04'!$H$7:$H$411,'25.04'!$G$7:$G$411,$D31,'25.04'!$F$7:$F$411,K$3) -> 0 | L31: =sumifs('25.04'!$H$7:$H$411,'25.04'!$G$7:$G$411,$D31,'25.04'!$F$7:$F$411,L$3) -> 0 | M31: =sumifs('25.04'!$H$7:$H$411,'25.04'!$G$7:$G$411,$D31,'25.04'!$F$7:$F$411,M$3) -> 0 | N31: =sum(E31:M31) -> 176500 | P31: =N31/sum(N$29:N$47) -> 0.049299693 | Q31: =N31/sum(N$29:N$31) -> 0.049299693 | T31: =sumifs('25.04'!$H$7:$H$411,'25.04'!$J$7:$J$411,$D31,'25.04'!$K$7:$K$411,T$3) -> 0 | U31: =sumifs('25.04'!$H$7:$H$411,'25.04'!$J$7:$J$411,$D31,'25.04'!$K$7:$K$411,U$3) -> 0 | V31: =sumifs('25.04'!$H$7:$H$411,'25.04'!$J$7:$J$411,$D31,'25.04'!$K$7:$K$411,V$3) -> 0 | W31: =sumifs('25.04'!$H$7:$H$411,'25.04'!$J$7:$J$411,$D31,'25.04'!$K$7:$K$411,W$3) -> 0 | X31: =sumifs('25.04'!$H$7:$H$411,'25.04'!$J$7:$J$411,$D31,'25.04'!$K$7:$K$411,X$3) -> 0 | Y31: =sumifs('25.04'!$H$7:$H$411,'25.04'!$J$7:$J$411,$D31,'25.04'!$K$7:$K$411,Y$3) -> 0 | Z31: =sumifs('25.04'!$H$7:$H$411,'25.04'!$J$7:$J$411,$D31,'25.04'!$K$7:$K$411,Z$3) -> 0 | AA31: =sumifs('25.04'!$H$7:$H$411,'25.04'!$J$7:$J$411,$D31,'25.04'!$K$7:$K$411,AA$3) -> 0 | AB31: =sumifs('25.04'!$H$7:$H$411,'25.04'!$J$7:$J$411,$D31,'25.04'!$K$7:$K$411,AB$3) -> 0 | AC31: =sum(T31:AB31) -> 0
C32: d | D32: Nghĩa | E32: =sumifs('25.04'!$H$7:$H$411,'25.04'!$G$7:$G$411,$D32,'25.04'!$F$7:$F$411,E$3) -> 0 | F32: =sumifs('25.04'!$H$7:$H$411,'25.04'!$G$7:$G$411,$D32,'25.04'!$F$7:$F$411,F$3) -> 0 | G32: =sumifs('25.04'!$H$7:$H$411,'25.04'!$G$7:$G$411,$D32,'25.04'!$F$7:$F$411,G$3) -> 0 | H32: =sumifs('25.04'!$H$7:$H$411,'25.04'!$G$7:$G$411,$D32,'25.04'!$F$7:$F$411,H$3) -> 0 | I32: =sumifs('25.04'!$H$7:$H$411,'25.04'!$G$7:$G$411,$D32,'25.04'!$F$7:$F$411,I$3) -> 0 | J32: =sumifs('25.04'!$H$7:$H$411,'25.04'!$G$7:$G$411,$D32,'25.04'!$F$7:$F$411,J$3) -> 0 | K32: =sumifs('25.04'!$H$7:$H$411,'25.04'!$G$7:$G$411,$D32,'25.04'!$F$7:$F$411,K$3) -> 0 | L32: =sumifs('25.04'!$H$7:$H$411,'25.04'!$G$7:$G$411,$D32,'25.04'!$F$7:$F$411,L$3) -> 0 | M32: =sumifs('25.04'!$H$7:$H$411,'25.04'!$G$7:$G$411,$D32,'25.04'!$F$7:$F$411,M$3) -> 0 | N32: =sum(E32:M32) -> 0 | P32: =N32/sum(N$29:N$47) -> 0 | Q32: =N32/sum(N$32:N$35) -> #DIV/0! | T32: =sumifs('25.04'!$H$7:$H$411,'25.04'!$J$7:$J$411,$D32,'25.04'!$K$7:$K$411,T$3) -> 0 | U32: =sumifs('25.04'!$H$7:$H$411,'25.04'!$J$7:$J$411,$D32,'25.04'!$K$7:$K$411,U$3) -> 0 | V32: =sumifs('25.04'!$H$7:$H$411,'25.04'!$J$7:$J$411,$D32,'25.04'!$K$7:$K$411,V$3) -> 0 | W32: =sumifs('25.04'!$H$7:$H$411,'25.04'!$J$7:$J$411,$D32,'25.04'!$K$7:$K$411,W$3) -> 0 | X32: =sumifs('25.04'!$H$7:$H$411,'25.04'!$J$7:$J$411,$D32,'25.04'!$K$7:$K$411,X$3) -> 0 | Y32: =sumifs('25.04'!$H$7:$H$411,'25.04'!$J$7:$J$411,$D32,'25.04'!$K$7:$K$411,Y$3) -> 0 | Z32: =sumifs('25.04'!$H$7:$H$411,'25.04'!$J$7:$J$411,$D32,'25.04'!$K$7:$K$411,Z$3) -> 0 | AA32: =sumifs('25.04'!$H$7:$H$411,'25.04'!$J$7:$J$411,$D32,'25.04'!$K$7:$K$411,AA$3) -> 0 | AB32: =sumifs('25.04'!$H$7:$H$411,'25.04'!$J$7:$J$411,$D32,'25.04'!$K$7:$K$411,AB$3) -> 0 | AC32: =sum(T32:AB32) -> 0
C33: e | D33: Mai | E33: =sumifs('25.04'!$H$7:$H$411,'25.04'!$G$7:$G$411,$D33,'25.04'!$F$7:$F$411,E$3) -> 0 | F33: =sumifs('25.04'!$H$7:$H$411,'25.04'!$G$7:$G$411,$D33,'25.04'!$F$7:$F$411,F$3) -> 0 | G33: =sumifs('25.04'!$H$7:$H$411,'25.04'!$G$7:$G$411,$D33,'25.04'!$F$7:$F$411,G$3) -> 0 | H33: =sumifs('25.04'!$H$7:$H$411,'25.04'!$G$7:$G$411,$D33,'25.04'!$F$7:$F$411,H$3) -> 0 | I33: =sumifs('25.04'!$H$7:$H$411,'25.04'!$G$7:$G$411,$D33,'25.04'!$F$7:$F$411,I$3) -> 0 | J33: =sumifs('25.04'!$H$7:$H$411,'25.04'!$G$7:$G$411,$D33,'25.04'!$F$7:$F$411,J$3) -> 0 | K33: =sumifs('25.04'!$H$7:$H$411,'25.04'!$G$7:$G$411,$D33,'25.04'!$F$7:$F$411,K$3) -> 0 | L33: =sumifs('25.04'!$H$7:$H$411,'25.04'!$G$7:$G$411,$D33,'25.04'!$F$7:$F$411,L$3) -> 0 | M33: =sumifs('25.04'!$H$7:$H$411,'25.04'!$G$7:$G$411,$D33,'25.04'!$F$7:$F$411,M$3) -> 0 | N33: =sum(E33:M33) -> 0 | P33: =N33/sum(N$29:N$47) -> 0 | Q33: =N33/sum(N$32:N$35) -> #DIV/0! | T33: =sumifs('25.04'!$H$7:$H$411,'25.04'!$J$7:$J$411,$D33,'25.04'!$K$7:$K$411,T$3) -> 0 | U33: =sumifs('25.04'!$H$7:$H$411,'25.04'!$J$7:$J$411,$D33,'25.04'!$K$7:$K$411,U$3) -> 0 | V33: =sumifs('25.04'!$H$7:$H$411,'25.04'!$J$7:$J$411,$D33,'25.04'!$K$7:$K$411,V$3) -> 0 | W33: =sumifs('25.04'!$H$7:$H$411,'25.04'!$J$7:$J$411,$D33,'25.04'!$K$7:$K$411,W$3) -> 0 | X33: =sumifs('25.04'!$H$7:$H$411,'25.04'!$J$7:$J$411,$D33,'25.04'!$K$7:$K$411,X$3) -> 0 | Y33: =sumifs('25.04'!$H$7:$H$411,'25.04'!$J$7:$J$411,$D33,'25.04'!$K$7:$K$411,Y$3) -> 0 | Z33: =sumifs('25.04'!$H$7:$H$411,'25.04'!$J$7:$J$411,$D33,'25.04'!$K$7:$K$411,Z$3) -> 0 | AA33: =sumifs('25.04'!$H$7:$H$411,'25.04'!$J$7:$J$411,$D33,'25.04'!$K$7:$K$411,AA$3) -> 0 | AB33: =sumifs('25.04'!$H$7:$H$411,'25.04'!$J$7:$J$411,$D33,'25.04'!$K$7:$K$411,AB$3) -> 0 | AC33: =sum(T33:AB33) -> 0
C34: g | D34: Totto | E34: =sumifs('25.04'!$H$7:$H$411,'25.04'!$G$7:$G$411,$D34,'25.04'!$F$7:$F$411,E$3) -> 0 | F34: =sumifs('25.04'!$H$7:$H$411,'25.04'!$G$7:$G$411,$D34,'25.04'!$F$7:$F$411,F$3) -> 0 | G34: =sumifs('25.04'!$H$7:$H$411,'25.04'!$G$7:$G$411,$D34,'25.04'!$F$7:$F$411,G$3) -> 0 | H34: =sumifs('25.04'!$H$7:$H$411,'25.04'!$G$7:$G$411,$D34,'25.04'!$F$7:$F$411,H$3) -> 0 | I34: =sumifs('25.04'!$H$7:$H$411,'25.04'!$G$7:$G$411,$D34,'25.04'!$F$7:$F$411,I$3) -> 0 | J34: =sumifs('25.04'!$H$7:$H$411,'25.04'!$G$7:$G$411,$D34,'25.04'!$F$7:$F$411,J$3) -> 0 | K34: =sumifs('25.04'!$H$7:$H$411,'25.04'!$G$7:$G$411,$D34,'25.04'!$F$7:$F$411,K$3) -> 0 | L34: =sumifs('25.04'!$H$7:$H$411,'25.04'!$G$7:$G$411,$D34,'25.04'!$F$7:$F$411,L$3) -> 0 | M34: =sumifs('25.04'!$H$7:$H$411,'25.04'!$G$7:$G$411,$D34,'25.04'!$F$7:$F$411,M$3) -> 0 | N34: =sum(E34:M34) -> 0 | P34: =N34/sum(N$29:N$47) -> 0 | Q34: =N34/sum(N$32:N$35) -> #DIV/0! | T34: =sumifs('25.04'!$H$7:$H$411,'25.04'!$J$7:$J$411,$D34,'25.04'!$K$7:$K$411,T$3) -> 0 | U34: =sumifs('25.04'!$H$7:$H$411,'25.04'!$J$7:$J$411,$D34,'25.04'!$K$7:$K$411,U$3) -> 0 | V34: =sumifs('25.04'!$H$7:$H$411,'25.04'!$J$7:$J$411,$D34,'25.04'!$K$7:$K$411,V$3) -> 0 | W34: =sumifs('25.04'!$H$7:$H$411,'25.04'!$J$7:$J$411,$D34,'25.04'!$K$7:$K$411,W$3) -> 0 | X34: =sumifs('25.04'!$H$7:$H$411,'25.04'!$J$7:$J$411,$D34,'25.04'!$K$7:$K$411,X$3) -> 0 | Y34: =sumifs('25.04'!$H$7:$H$411,'25.04'!$J$7:$J$411,$D34,'25.04'!$K$7:$K$411,Y$3) -> 0 | Z34: =sumifs('25.04'!$H$7:$H$411,'25.04'!$J$7:$J$411,$D34,'25.04'!$K$7:$K$411,Z$3) -> 0 | AA34: =sumifs('25.04'!$H$7:$H$411,'25.04'!$J$7:$J$411,$D34,'25.04'!$K$7:$K$411,AA$3) -> 0 | AB34: =sumifs('25.04'!$H$7:$H$411,'25.04'!$J$7:$J$411,$D34,'25.04'!$K$7:$K$411,AB$3) -> 0 | AC34: =sum(T34:AB34) -> 0
C35: h | D35: Lego | E35: =sumifs('25.04'!$H$7:$H$411,'25.04'!$G$7:$G$411,$D35,'25.04'!$F$7:$F$411,E$3) -> 0 | F35: =sumifs('25.04'!$H$7:$H$411,'25.04'!$G$7:$G$411,$D35,'25.04'!$F$7:$F$411,F$3) -> 0 | G35: =sumifs('25.04'!$H$7:$H$411,'25.04'!$G$7:$G$411,$D35,'25.04'!$F$7:$F$411,G$3) -> 0 | H35: =sumifs('25.04'!$H$7:$H$411,'25.04'!$G$7:$G$411,$D35,'25.04'!$F$7:$F$411,H$3) -> 0 | I35: =sumifs('25.04'!$H$7:$H$411,'25.04'!$G$7:$G$411,$D35,'25.04'!$F$7:$F$411,I$3) -> 0 | J35: =sumifs('25.04'!$H$7:$H$411,'25.04'!$G$7:$G$411,$D35,'25.04'!$F$7:$F$411,J$3) -> 0 | K35: =sumifs('25.04'!$H$7:$H$411,'25.04'!$G$7:$G$411,$D35,'25.04'!$F$7:$F$411,K$3) -> 0 | L35: =sumifs('25.04'!$H$7:$H$411,'25.04'!$G$7:$G$411,$D35,'25.04'!$F$7:$F$411,L$3) -> 0 | M35: =sumifs('25.04'!$H$7:$H$411,'25.04'!$G$7:$G$411,$D35,'25.04'!$F$7:$F$411,M$3) -> 0 | N35: =sum(E35:M35) -> 0 | P35: =N35/sum(N$29:N$47) -> 0 | Q35: =N35/sum(N$32:N$35) -> #DIV/0! | T35: =sumifs('25.04'!$H$7:$H$411,'25.04'!$J$7:$J$411,$D35,'25.04'!$K$7:$K$411,T$3) -> 0 | U35: =sumifs('25.04'!$H$7:$H$411,'25.04'!$J$7:$J$411,$D35,'25.04'!$K$7:$K$411,U$3) -> 0 | V35: =sumifs('25.04'!$H$7:$H$411,'25.04'!$J$7:$J$411,$D35,'25.04'!$K$7:$K$411,V$3) -> 0 | W35: =sumifs('25.04'!$H$7:$H$411,'25.04'!$J$7:$J$411,$D35,'25.04'!$K$7:$K$411,W$3) -> 0 | X35: =sumifs('25.04'!$H$7:$H$411,'25.04'!$J$7:$J$411,$D35,'25.04'!$K$7:$K$411,X$3) -> 0 | Y35: =sumifs('25.04'!$H$7:$H$411,'25.04'!$J$7:$J$411,$D35,'25.04'!$K$7:$K$411,Y$3) -> 0 | Z35: =sumifs('25.04'!$H$7:$H$411,'25.04'!$J$7:$J$411,$D35,'25.04'!$K$7:$K$411,Z$3) -> 0 | AA35: =sumifs('25.04'!$H$7:$H$411,'25.04'!$J$7:$J$411,$D35,'25.04'!$K$7:$K$411,AA$3) -> 0 | AB35: =sumifs('25.04'!$H$7:$H$411,'25.04'!$J$7:$J$411,$D35,'25.04'!$K$7:$K$411,AB$3) -> 0 | AC35: =sum(T35:AB35) -> 0
C36: i | D36: Phone | E36: =sumifs('25.04'!$H$7:$H$411,'25.04'!$G$7:$G$411,$D36,'25.04'!$F$7:$F$411,E$3) -> 0 | F36: =sumifs('25.04'!$H$7:$H$411,'25.04'!$G$7:$G$411,$D36,'25.04'!$F$7:$F$411,F$3) -> 0 | G36: =sumifs('25.04'!$H$7:$H$411,'25.04'!$G$7:$G$411,$D36,'25.04'!$F$7:$F$411,G$3) -> 0 | H36: =sumifs('25.04'!$H$7:$H$411,'25.04'!$G$7:$G$411,$D36,'25.04'!$F$7:$F$411,H$3) -> 0 | I36: =sumifs('25.04'!$H$7:$H$411,'25.04'!$G$7:$G$411,$D36,'25.04'!$F$7:$F$411,I$3) -> 0 | J36: =sumifs('25.04'!$H$7:$H$411,'25.04'!$G$7:$G$411,$D36,'25.04'!$F$7:$F$411,J$3) -> 0 | K36: =sumifs('25.04'!$H$7:$H$411,'25.04'!$G$7:$G$411,$D36,'25.04'!$F$7:$F$411,K$3) -> 0 | L36: =sumifs('25.04'!$H$7:$H$411,'25.04'!$G$7:$G$411,$D36,'25.04'!$F$7:$F$411,L$3) -> 0 | M36: =sumifs('25.04'!$H$7:$H$411,'25.04'!$G$7:$G$411,$D36,'25.04'!$F$7:$F$411,M$3) -> 0 | N36: =sum(E36:M36) -> 0 | P36: =N36/sum(N$29:N$47) -> 0 | Q36: =N36/sum(N$36:N$40) -> #DIV/0! | T36: =sumifs('25.04'!$H$7:$H$411,'25.04'!$J$7:$J$411,$D36,'25.04'!$K$7:$K$411,T$3) -> 0 | U36: =sumifs('25.04'!$H$7:$H$411,'25.04'!$J$7:$J$411,$D36,'25.04'!$K$7:$K$411,U$3) -> 0 | V36: =sumifs('25.04'!$H$7:$H$411,'25.04'!$J$7:$J$411,$D36,'25.04'!$K$7:$K$411,V$3) -> 0 | W36: =sumifs('25.04'!$H$7:$H$411,'25.04'!$J$7:$J$411,$D36,'25.04'!$K$7:$K$411,W$3) -> 0 | X36: =sumifs('25.04'!$H$7:$H$411,'25.04'!$J$7:$J$411,$D36,'25.04'!$K$7:$K$411,X$3) -> 0 | Y36: =sumifs('25.04'!$H$7:$H$411,'25.04'!$J$7:$J$411,$D36,'25.04'!$K$7:$K$411,Y$3) -> 0 | Z36: =sumifs('25.04'!$H$7:$H$411,'25.04'!$J$7:$J$411,$D36,'25.04'!$K$7:$K$411,Z$3) -> 0 | AA36: =sumifs('25.04'!$H$7:$H$411,'25.04'!$J$7:$J$411,$D36,'25.04'!$K$7:$K$411,AA$3) -> 0 | AB36: =sumifs('25.04'!$H$7:$H$411,'25.04'!$J$7:$J$411,$D36,'25.04'!$K$7:$K$411,AB$3) -> 0 | AC36: =sum(T36:AB36) -> 0
D37: Papers
