Workbook

Sheet 25.06
B2: this month is | E2: May | F2: 2025
B4: How much money do you have coming in? and spend out?
D5: ( + ) | F5: (-) | I5: ( + )
B6: Month | C6: Date | D6: SOURCE | E6: Name | F6: Account | G6: Fund | H6: AMOUNT | I6: Fund | J6: Account
C7: 45810 | E7: Trả commission | F7: Vietcombank | G7: Togohub management | H7: 6000000
F8: Vietcombank | G8: T. Mainternance
C9: 45822 | E9: nước | F9: Vietcombank | G9: T. Water | H9: 1033850
C10: 45811 | E10: điện | F10: Vietcombank | G10: T. Electricity | H10: 4544704
E11: trả Phương Anh cọc nhà | F11: Vietcombank | G11: Togohub management | H11: 10730000
C12: 45828 | D12: House rental money | E12: Lợi trả tiền điện nước | H12: 4157000 | I12: T. Electricity | J12: Vietcombank
C13: 45821 | D13: House rental money | E13: Lợi trả tiền nhà | H13: 36000000 | I13: Togohub management | J13: Vietcombank
C14: 45821 | D14: House rental money | E14: Nhận cọc nhà | H14: 11000000 | I14: Togohub management | J14: Vietcombank
C15: 45836 | D15: House rental money | E15: Tiền thuê nhà | H15: 33000000 | I15: Togohub management | J15: Vietcombank
C74: 45322
C75: 45322
C76: 45322
C77: 45322
C78: 45322
C79: 45322
C80: 45322
E163: TOTAL (A) | H163: =sum(H7:H162) -> 106465554
B165: How much money do you have going out? | E165: =#REF! -> #REF!
B168: How much money do you have available to you?
B169: TOTAL (A) | D169: - | E169: TOTAL (B) | F169: = | H169: TOTAL (C)
B170: =H163 -> 106465554 | E170: =#REF! -> #REF! | H170: =B170-E170 -> #REF!
B172: How much money do you want to save
B173: TOTAL (D) | E173: ='Spending 25.06'!F99+#REF! -> #REF!
B175: What for?
B181: How much should you spend?
B182: TOTAL (C) | D182: - | E182: TOTAL (D) | F182: = | H182: TOTAL (E) (PER MONTH)
B183: =H170 -> #REF! | E183: =E173 -> #REF! | H183: =H170-E173 -> #REF!
B185: TOTAL (E) | D185: / | E185: No OF WEEKS | F185: = | H185: TOTAL (PER WEEK)
B186: =H183 -> #REF! | E186: 5 | H186: =B186/E186 -> #REF!
B188: NOTES

Sheet Spending 25.06
A1: Chi tiêu thực tế
C2: (-) | S2: ( + )
C3: Cash | D3: BIDV | E3: Vietcombank | F3: Vp bank Lady | G3: Moca | H3: Momo | I3: Zalo | J3: Saving | K3: Loan | L3: Total out | N3: % | O3: % | R3: Cash | S3: BIDV | T3: Vietcombank | U3: Vp bank Lady | V3: Moca | W3: Momo | X3: Zalo | Y3: Saving | Z3: Loan | AA3: Total in
A4: 1 | B4: Education | C4: =sumifs('25.06'!$H$7:$H$162,'25.06'!$G$7:$G$162,$B4,'25.06'!$F$7:$F$162,C$3) -> 0 | D4: =sumifs('25.06'!$H$7:$H$162,'25.06'!$G$7:$G$162,$B4,'25.06'!$F$7:$F$162,D$3) -> 0 | E4: =sumifs('25.06'!$H$7:$H$162,'25.06'!$G$7:$G$162,$B4,'25.06'!$F$7:$F$162,E$3) -> 0 | F4: =sumifs('25.06'!$H$7:$H$162,'25.06'!$G$7:$G$162,$B4,'25.06'!$F$7:$F$162,F$3) -> 0 | G4: =sumifs('25.06'!$H$7:$H$162,'25.06'!$G$7:$G$162,$B4,'25.06'!$F$7:$F$162,G$3) -> 0 | H4: =sumifs('25.06'!$H$7:$H$162,'25.06'!$G$7:$G$162,$B4,'25.06'!$F$7:$F$162,H$3) -> 0 | I4: =sumifs('25.06'!$H$7:$H$162,'25.06'!$G$7:$G$162,$B4,'25.06'!$F$7:$F$162,I$3) -> 0 | J4: =sumifs('25.06'!$H$7:$H$162,'25.06'!$G$7:$G$162,$B4,'25.06'!$F$7:$F$162,J$3) -> 0 | K4: =sumifs('25.06'!$H$7:$H$162,'25.06'!$G$7:$G$162,$B4,'25.06'!$F$7:$F$162,K$3) -> 0 | L4: =sum(C4:K4) -> 0 | N4: =L4/sum(L$4:L$9) -> #DIV/0! | P4: =sum(L4:L9) -> 0 | Q4: =P4/sum($P$4:$P$57) -> #DIV/0! | R4: =sumifs('25.06'!$H$7:$H$162,'25.06'!$I$7:$I$162,$B4,'25.06'!$J$7:$J$162,R$3) -> 0 | S4: =sumifs('25.06'!$H$7:$H$162,'25.06'!$I$7:$I$162,$B4,'25.06'!$J$7:$J$162,S$3) -> 0 | T4: =sumifs('25.06'!$H$7:$H$162,'25.06'!$I$7:$I$162,$B4,'25.06'!$J$7:$J$162,T$3) -> 0 | U4: =sumifs('25.06'!$H$7:$H$162,'25.06'!$I$7:$I$162,$B4,'25.06'!$J$7:$J$162,U$3) -> 0 | V4: =sumifs('25.06'!$H$7:$H$162,'25.06'!$I$7:$I$162,$B4,'25.06'!$J$7:$J$162,V$3) -> 0 | W4: =sumifs('25.06'!$H$7:$H$162,'25.06'!$I$7:$I$162,$B4,'25.06'!$J$7:$J$162,W$3) -> 0 | X4: =sumifs('25.06'!$H$7:$H$162,'25.06'!$I$7:$I$162,$B4,'25.06'!$J$7:$J$162,X$3) -> 0 | Y4: =sumifs('25.06'!$H$7:$H$162,'25.06'!$I$7:$I$162,$B4,'25.06'!$J$7:$J$162,Y$3) -> 0 | Z4: =sumifs('25.06'!$H$7:$H$162,'25.06'!$I$7:$I$162,$B4,'25.06'!$J$7:$J$162,Z$3) -> 0 | AA4: =sum(R4:Z4) -> 0
A5: 44927 | B5: Education fee | C5: =sumifs('25.06'!$H$7:$H$162,'25.06'!$G$7:$G$162,$B5,'25.06'!$F$7:$F$162,C$3) -> 0 | D5: =sumifs('25.06'!$H$7:$H$162,'25.06'!$G$7:$G$162,$B5,'25.06'!$F$7:$F$162,D$3) -> 0 | E5: =sumifs('25.06'!$H$7:$H$162,'25.06'!$G$7:$G$162,$B5,'25.06'!$F$7:$F$162,E$3) -> 0 | F5: =sumifs('25.06'!$H$7:$H$162,'25.06'!$G$7:$G$162,$B5,'25.06'!$F$7:$F$162,F$3) -> 0 | G5: =sumifs('25.06'!$H$7:$H$162,'25.06'!$G$7:$G$162,$B5,'25.06'!$F$7:$F$162,G$3) -> 0 | H5: =sumifs('25.06'!$H$7:$H$162,'25.06'!$G$7:$G$162,$B5,'25.06'!$F$7:$F$162,H$3) -> 0 | I5: =sumifs('25.06'!$H$7:$H$162,'25.06'!$G$7:$G$162,$B5,'25.06'!$F$7:$F$162,I$3) -> 0 | J5: =sumifs('25.06'!$H$7:$H$162,'25.06'!$G$7:$G$162,$B5,'25.06'!$F$7:$F$162,J$3) -> 0 | K5: =sumifs('25.06'!$H$7:$H$162,'25.06'!$G$7:$G$162,$B5,'25.06'!$F$7:$F$162,K$3) -> 0 | L5: =sum(C5:K5) -> 0 | N5: =L5/sum(L$4:L$9) -> #DIV/0! | R5: =sumifs('25.06'!$H$7:$H$162,'25.06'!$I$7:$I$162,$B5,'25.06'!$J$7:$J$162,R$3) -> 0 | S5: =sumifs('25.06'!$H$7:$H$162,'25.06'!$I$7:$I$162,$B5,'25.06'!$J$7:$J$162,S$3) -> 0 | T5: =sumifs('25.06'!$H$7:$H$162,'25.06'!$I$7:$I$162,$B5,'25.06'!$J$7:$J$162,T$3) -> 0 | U5: =sumifs('25.06'!$H$7:$H$162,'25.06'!$I$7:$I$162,$B5,'25.06'!$J$7:$J$162,U$3) -> 0 | V5: =sumifs('25.06'!$H$7:$H$162,'25.06'!$I$7:$I$162,$B5,'25.06'!$J$7:$J$162,V$3) -> 0 | W5: =sumifs('25.06'!$H$7:$H$162,'25.06'!$I$7:$I$162,$B5,'25.06'!$J$7:$J$162,W$3) -> 0 | X5: =sumifs('25.06'!$H$7:$H$162,'25.06'!$I$7:$I$162,$B5,'25.06'!$J$7:$J$162,X$3) -> 0 | Y5: =sumifs('25.06'!$H$7:$H$162,'25.06'!$I$7:$I$162,$B5,'25.06'!$J$7:$J$162,Y$3) -> 0 | Z5: =sumifs('25.06'!$H$7:$H$162,'25.06'!$I$7:$I$162,$B5,'25.06'!$J$7:$J$162,Z$3) -> 0 | AA5: =sum(R5:Z5) -> 0
A6: 44958 | B6: Extra Education fee | C6: =sumifs('25.06'!$H$7:$H$162,'25.06'!$G$7:$G$162,$B6,'25.06'!$F$7:$F$162,C$3) -> 0 | D6: =sumifs('25.06'!$H$7:$H$162,'25.06'!$G$7:$G$162,$B6,'25.06'!$F$7:$F$162,D$3) -> 0 | E6: =sumifs('25.06'!$H$7:$H$162,'25.06'!$G$7:$G$162,$B6,'25.06'!$F$7:$F$162,E$3) -> 0 | F6: =sumifs('25.06'!$H$7:$H$162,'25.06'!$G$7:$G$162,$B6,'25.06'!$F$7:$F$162,F$3) -> 0 | G6: =sumifs('25.06'!$H$7:$H$162,'25.06'!$G$7:$G$162,$B6,'25.06'!$F$7:$F$162,G$3) -> 0 | H6: =sumifs('25.06'!$H$7:$H$162,'25.06'!$G$7:$G$162,$B6,'25.06'!$F$7:$F$162,H$3) -> 0 | I6: =sumifs('25.06'!$H$7:$H$162,'25.06'!$G$7:$G$162,$B6,'25.06'!$F$7:$F$162,I$3) -> 0 | J6: =sumifs('25.06'!$H$7:$H$162,'25.06'!$G$7:$G$162,$B6,'25.06'!$F$7:$F$162,J$3) -> 0 | K6: =sumifs('25.06'!$H$7:$H$162,'25.06'!$G$7:$G$162,$B6,'25.06'!$F$7:$F$162,K$3) -> 0 | L6: =sum(C6:K6) -> 0 | N6: =L6/sum(L$4:L$9) -> #DIV/0! | R6: =sumifs('25.06'!$H$7:$H$162,'25.06'!$I$7:$I$162,$B6,'25.06'!$J$7:$J$162,R$3) -> 0 | S6: =sumifs('25.06'!$H$7:$H$162,'25.06'!$I$7:$I$162,$B6,'25.06'!$J$7:$J$162,S$3) -> 0 | T6: =sumifs('25.06'!$H$7:$H$162,'25.06'!$I$7:$I$162,$B6,'25.06'!$J$7:$J$162,T$3) -> 0 | U6: =sumifs('25.06'!$H$7:$H$162,'25.06'!$I$7:$I$162,$B6,'25.06'!$J$7:$J$162,U$3) -> 0 | V6: =sumifs('25.06'!$H$7:$H$162,'25.06'!$I$7:$I$162,$B6,'25.06'!$J$7:$J$162,V$3) -> 0 | W6: =sumifs('25.06'!$H$7:$H$162,'25.06'!$I$7:$I$162,$B6,'25.06'!$J$7:$J$162,W$3) -> 0 | X6: =sumifs('25.06'!$H$7:$H$162,'25.06'!$I$7:$I$162,$B6,'25.06'!$J$7:$J$162,X$3) -> 0 | Y6: =sumifs('25.06'!$H$7:$H$162,'25.06'!$I$7:$I$162,$B6,'25.06'!$J$7:$J$162,Y$3) -> 0 | Z6: =sumifs('25.06'!$H$7:$H$162,'25.06'!$I$7:$I$162,$B6,'25.06'!$J$7:$J$162,Z$3) -> 0 | AA6: =sum(R6:Z6) -> 0
A7: 44986 | B7: Talent Education fee | C7: =sumifs('25.06'!$H$7:$H$162,'25.06'!$G$7:$G$162,$B7,'25.06'!$F$7:$F$162,C$3) -> 0 | D7: =sumifs('25.06'!$H$7:$H$162,'25.06'!$G$7:$G$162,$B7,'25.06'!$F$7:$F$162,D$3) -> 0 | E7: =sumifs('25.06'!$H$7:$H$162,'25.06'!$G$7:$G$162,$B7,'25.06'!$F$7:$F$162,E$3) -> 0 | F7: =sumifs('25.06'!$H$7:$H$162,'25.06'!$G$7:$G$162,$B7,'25.06'!$F$7:$F$162,F$3) -> 0 | G7: =sumifs('25.06'!$H$7:$H$162,'25.06'!$G$7:$G$162,$B7,'25.06'!$F$7:$F$162,G$3) -> 0 | H7: =sumifs('25.06'!$H$7:$H$162,'25.06'!$G$7:$G$162,$B7,'25.06'!$F$7:$F$162,H$3) -> 0 | I7: =sumifs('25.06'!$H$7:$H$162,'25.06'!$G$7:$G$162,$B7,'25.06'!$F$7:$F$162,I$3) -> 0 | J7: =sumifs('25.06'!$H$7:$H$162,'25.06'!$G$7:$G$162,$B7,'25.06'!$F$7:$F$162,J$3) -> 0 | K7: =sumifs('25.06'!$H$7:$H$162,'25.06'!$G$7:$G$162,$B7,'25.06'!$F$7:$F$162,K$3) -> 0 | L7: =sum(C7:K7) -> 0 | N7: =L7/sum(L$4:L$9) -> #DIV/0! | R7: =sumifs('25.06'!$H$7:$H$162,'25.06'!$I$7:$I$162,$B7,'25.06'!$J$7:$J$162,R$3) -> 0 | S7: =sumifs('25.06'!$H$7:$H$162,'25.06'!$I$7:$I$162,$B7,'25.06'!$J$7:$J$162,S$3) -> 0 | T7: =sumifs('25.06'!$H$7:$H$162,'25.06'!$I$7:$I$162,$B7,'25.06'!$J$7:$J$162,T$3) -> 0 | U7: =sumifs('25.06'!$H$7:$H$162,'25.06'!$I$7:$I$162,$B7,'25.06'!$J$7:$J$162,U$3) -> 0 | V7: =sumifs('25.06'!$H$7:$H$162,'25.06'!$I$7:$I$162,$B7,'25.06'!$J$7:$J$162,V$3) -> 0 | W7: =sumifs('25.06'!$H$7:$H$162,'25.06'!$I$7:$I$162,$B7,'25.06'!$J$7:$J$162,W$3) -> 0 | X7: =sumifs('25.06'!$H$7:$H$162,'25.06'!$I$7:$I$162,$B7,'25.06'!$J$7:$J$162,X$3) -> 0 | Y7: =sumifs('25.06'!$H$7:$H$162,'25.06'!$I$7:$I$162,$B7,'25.06'!$J$7:$J$162,Y$3) -> 0 | Z7: =sumifs('25.06'!$H$7:$H$162,'25.06'!$I$7:$I$162,$B7,'25.06'!$J$7:$J$162,Z$3) -> 0 | AA7: =sum(R7:Z7) -> 0
A8: 45017 | B8: Books | C8: =sumifs('25.06'!$H$7:$H$162,'25.06'!$G$7:$G$162,$B8,'25.06'!$F$7:$F$162,C$3) -> 0 | D8: =sumifs('25.06'!$H$7:$H$162,'25.06'!$G$7:$G$162,$B8,'25.06'!$F$7:$F$162,D$3) -> 0 | E8: =sumifs('25.06'!$H$7:$H$162,'25.06'!$G$7:$G$162,$B8,'25.06'!$F$7:$F$162,E$3) -> 0 | F8: =sumifs('25.06'!$H$7:$H$162,'25.06'!$G$7:$G$162,$B8,'25.06'!$F$7:$F$162,F$3) -> 0 | G8: =sumifs('25.06'!$H$7:$H$162,'25.06'!$G$7:$G$162,$B8,'25.06'!$F$7:$F$162,G$3) -> 0 | H8: =sumifs('25.06'!$H$7:$H$162,'25.06'!$G$7:$G$162,$B8,'25.06'!$F$7:$F$162,H$3) -> 0 | I8: =sumifs('25.06'!$H$7:$H$162,'25.06'!$G$7:$G$162,$B8,'25.06'!$F$7:$F$162,I$3) -> 0 | J8: =sumifs('25.06'!$H$7:$H$162,'25.06'!$G$7:$G$162,$B8,'25.06'!$F$7:$F$162,J$3) -> 0 | K8: =sumifs('25.06'!$H$7:$H$162,'25.06'!$G$7:$G$162,$B8,'25.06'!$F$7:$F$162,K$3) -> 0 | L8: =sum(C8:K8) -> 0 | N8: =L8/sum(L$4:L$9) -> #DIV/0! | R8: =sumifs('25.06'!$H$7:$H$162,'25.06'!$I$7:$I$162,$B8,'25.06'!$J$7:$J$162,R$3) -> 0 | S8: =sumifs('25.06'!$H$7:$H$162,'25.06'!$I$7:$I$162,$B8,'25.06'!$J$7:$J$162,S$3) -> 0 | T8: =sumifs('25.06'!$H$7:$H$162,'25.06'!$I$7:$I$162,$B8,'25.06'!$J$7:$J$162,T$3) -> 0 | U8: =sumifs('25.06'!$H$7:$H$162,'25.06'!$I$7:$I$162,$B8,'25.06'!$J$7:$J$162,U$3) -> 0 | V8: =sumifs('25.06'!$H$7:$H$162,'25.06'!$I$7:$I$162,$B8,'25.06'!$J$7:$J$162,V$3) -> 0 | W8: =sumifs('25.06'!$H$7:$H$162,'25.06'!$I$7:$I$162,$B8,'25.06'!$J$7:$J$162,W$3) -> 0 | X8: =sumifs('25.06'!$H$7:$H$162,'25.06'!$I$7:$I$162,$B8,'25.06'!$J$7:$J$162,X$3) -> 0 | Y8: =sumifs('25.06'!$H$7:$H$162,'25.06'!$I$7:$I$162,$B8,'25.06'!$J$7:$J$162,Y$3) -> 0 | Z8: =sumifs('25.06'!$H$7:$H$162,'25.06'!$I$7:$I$162,$B8,'25.06'!$J$7:$J$162,Z$3) -> 0 | AA8: =sum(R8:Z8) -> 0
A9: 45047 | B9: Stationery | C9: =sumifs('25.06'!$H$7:$H$162,'25.06'!$G$7:$G$162,$B9,'25.06'!$F$7:$F$162,C$3) -> 0 | D9: =sumifs('25.06'!$H$7:$H$162,'25.06'!$G$7:$G$162,$B9,'25.06'!$F$7:$F$162,D$3) -> 0 | E9: =sumifs('25.06'!$H$7:$H$162,'25.06'!$G$7:$G$162,$B9,'25.06'!$F$7:$F$162,E$3) -> 0 | F9: =sumifs('25.06'!$H$7:$H$162,'25.06'!$G$7:$G$162,$B9,'25.06'!$F$7:$F$162,F$3) -> 0 | G9: =sumifs('25.06'!$H$7:$H$162,'25.06'!$G$7:$G$162,$B9,'25.06'!$F$7:$F$162,G$3) -> 0 | H9: =sumifs('25.06'!$H$7:$H$162,'25.06'!$G$7:$G$162,$B9,'25.06'!$F$7:$F$162,H$3) -> 0 | I9: =sumifs('25.06'!$H$7:$H$162,'25.06'!$G$7:$G$162,$B9,'25.06'!$F$7:$F$162,I$3) -> 0 | J9: =sumifs('25.06'!$H$7:$H$162,'25.06'!$G$7:$G$162,$B9,'25.06'!$F$7:$F$162,J$3) -> 0 | K9: =sumifs('25.06'!$H$7:$H$162,'25.06'!$G$7:$G$162,$B9,'25.06'!$F$7:$F$162,K$3) -> 0 | L9: =sum(C9:K9) -> 0 | N9: =L9/sum(L$4:L$9) -> #DIV/0! | R9: =sumifs('25.06'!$H$7:$H$162,'25.06'!$I$7:$I$162,$B9,'25.06'!$J$7:$J$162,R$3) -> 0 | S9: =sumifs('25.06'!$H$7:$H$162,'25.06'!$I$7:$I$162,$B9,'25.06'!$J$7:$J$162,S$3) -> 0 | T9: =sumifs('25.06'!$H$7:$H$162,'25.06'!$I$7:$I$162,$B9,'25.06'!$J$7:$J$162,T$3) -> 0 | U9: =sumifs('25.06'!$H$7:$H$162,'25.06'!$I$7:$I$162,$B9,'25.06'!$J$7:$J$162,U$3) -> 0 | V9: =sumifs('25.06'!$H$7:$H$162,'25.06'!$I$7:$I$162,$B9,'25.06'!$J$7:$J$162,V$3) -> 0 | W9: =sumifs('25.06'!$H$7:$H$162,'25.06'!$I$7:$I$162,$B9,'25.06'!$J$7:$J$162,W$3) -> 0 | X9: =sumifs('25.06'!$H$7:$H$162,'25.06'!$I$7:$I$162,$B9,'25.06'!$J$7:$J$162,X$3) -> 0 | Y9: =sumifs('25.06'!$H$7:$H$162,'25.06'!$I$7:$I$162,$B9,'25.06'!$J$7:$J$162,Y$3) -> 0 | Z9: =sumifs('25.06'!$H$7:$H$162,'25.06'!$I$7:$I$162,$B9,'25.06'!$J$7:$J$162,Z$3) -> 0 | AA9: =sum(R9:Z9) -> 0
A10: 2 | B10: Enjoy | C10: =sumifs('25.06'!$H$7:$H$162,'25.06'!$G$7:$G$162,$B10,'25.06'!$F$7:$F$162,C$3) -> 0 | D10: =sumifs('25.06'!$H$7:$H$162,'25.06'!$G$7:$G$162,$B10,'25.06'!$F$7:$F$162,D$3) -> 0 | E10: =sumifs('25.06'!$H$7:$H$162,'25.06'!$G$7:$G$162,$B10,'25.06'!$F$7:$F$162,E$3) -> 0 | F10: =sumifs('25.06'!$H$7:$H$162,'25.06'!$G$7:$G$162,$B10,'25.06'!$F$7:$F$162,F$3) -> 0 | G10: =sumifs('25.06'!$H$7:$H$162,'25.06'!$G$7:$G$162,$B10,'25.06'!$F$7:$F$162,G$3) -> 0 | H10: =sumifs('25.06'!$H$7:$H$162,'25.06'!$G$7:$G$162,$B10,'25.06'!$F$7:$F$162,H$3) -> 0 | I10: =sumifs('25.06'!$H$7:$H$162,'25.06'!$G$7:$G$162,$B10,'25.06'!$F$7:$F$162,I$3) -> 0 | J10: =sumifs('25.06'!$H$7:$H$162,'25.06'!$G$7:$G$162,$B10,'25.06'!$F$7:$F$162,J$3) -> 0 | K10: =sumifs('25.06'!$H$7:$H$162,'25.06'!$G$7:$G$162,$B10,'25.06'!$F$7:$F$162,K$3) -> 0 | L10: =sum(C10:K10) -> 0 | N10: =L10/sum(L$10:L$16) -> #DIV/0! | P10: =sum(L10:L16) -> 0 | Q10: =P10/sum($P$4:$P$57) -> #DIV/0! | R10: =sumifs('25.06'!$H$7:$H$162,'25.06'!$I$7:$I$162,$B10,'25.06'!$J$7:$J$162,R$3) -> 0 | S10: =sumifs('25.06'!$H$7:$H$162,'25.06'!$I$7:$I$162,$B10,'25.06'!$J$7:$J$162,S$3) -> 0 | T10: =sumifs('25.06'!$H$7:$H$162,'25.06'!$I$7:$I$162,$B10,'25.06'!$J$7:$J$162,T$3) -> 0 | U10: =sumifs('25.06'!$H$7:$H$162,'25.06'!$I$7:$I$162,$B10,'25.06'!$J$7:$J$162,U$3) -> 0 | V10: =sumifs('25.06'!$H$7:$H$162,'25.06'!$I$7:$I$162,$B10,'25.06'!$J$7:$J$162,V$3) -> 0 | W10: =sumifs('25.06'!$H$7:$H$162,'25.06'!$I$7:$I$162,$B10,'25.06'!$J$7:$J$162,W$3) -> 0 | X10: =sumifs('25.06'!$H$7:$H$162,'25.06'!$I$7:$I$162,$B10,'25.06'!$J$7:$J$162,X$3) -> 0 | Y10: =sumifs('25.06'!$H$7:$H$162,'25.06'!$I$7:$I$162,$B10,'25.06'!$J$7:$J$162,Y$3) -> 0 | Z10: =sumifs('25.06'!$H$7:$H$162,'25.06'!$I$7:$I$162,$B10,'25.06'!$J$7:$J$162,Z$3) -> 0 | AA10: =sum(R10:Z10) -> 0
A11: 44928 | B11: Travel | C11: =sumifs('25.06'!$H$7:$H$162,'25.06'!$G$7:$G$162,$B11,'25.06'!$F$7:$F$162,C$3) -> 0 | D11: =sumifs('25.06'!$H$7:$H$162,'25.06'!$G$7:$G$162,$B11,'25.06'!$F$7:$F$162,D$3) -> 0 | E11: =sumifs('25.06'!$H$7:$H$162,'25.06'!$G$7:$G$162,$B11,'25.06'!$F$7:$F$162,E$3) -> 0 | F11: =sumifs('25.06'!$H$7:$H$162,'25.06'!$G$7:$G$162,$B11,'25.06'!$F$7:$F$162,F$3) -> 0 | G11: =sumifs('25.06'!$H$7:$H$162,'25.06'!$G$7:$G$162,$B11,'25.06'!$F$7:$F$162,G$3) -> 0 | H11: =sumifs('25.06'!$H$7:$H$162,'25.06'!$G$7:$G$162,$B11,'25.06'!$F$7:$F$162,H$3) -> 0 | I11: =sumifs('25.06'!$H$7:$H$162,'25.06'!$G$7:$G$162,$B11,'25.06'!$F$7:$F$162,I$3) -> 0 | J11: =sumifs('25.06'!$H$7:$H$162,'25.06'!$G$7:$G$162,$B11,'25.06'!$F$7:$F$162,J$3) -> 0 | K11: =sumifs('25.06'!$H$7:$H$162,'25.06'!$G$7:$G$162,$B11,'25.06'!$F$7:$F$162,K$3) -> 0 | L11: =sum(C11:K11) -> 0 | N11: =L11/sum(L$10:L$16) -> #DIV/0! | R11: =sumifs('25.06'!$H$7:$H$162,'25.06'!$I$7:$I$162,$B11,'25.06'!$J$7:$J$162,R$3) -> 0 | S11: =sumifs('25.06'!$H$7:$H$162,'25.06'!$I$7:$I$162,$B11,'25.06'!$J$7:$J$162,S$3) -> 0 | T11: =sumifs('25.06'!$H$7:$H$162,'25.06'!$I$7:$I$162,$B11,'25.06'!$J$7:$J$162,T$3) -> 0 | U11: =sumifs('25.06'!$H$7:$H$162,'25.06'!$I$7:$I$162,$B11,'25.06'!$J$7:$J$162,U$3) -> 0 | V11: =sumifs('25.06'!$H$7:$H$162,'25.06'!$I$7:$I$162,$B11,'25.06'!$J$7:$J$162,V$3) -> 0 | W11: =sumifs('25.06'!$H$7:$H$162,'25.06'!$I$7:$I$162,$B11,'25.06'!$J$7:$J$162,W$3) -> 0 | X11: =sumifs('25.06'!$H$7:$H$162,'25.06'!$I$7:$I$162,$B11,'25.06'!$J$7:$J$162,X$3) -> 0 | Y11: =sumifs('25.06'!$H$7:$H$162,'25.06'!$I$7:$I$162,$B11,'25.06'!$J$7:$J$162,Y$3) -> 0 | Z11: =sumifs('25.06'!$H$7:$H$162,'25.06'!$I$7:$I$162,$B11,'25.06'!$J$7:$J$162,Z$3) -> 0 | AA11: =sum(R11:Z11) -> 0
A12: 44959 | B12: Café | C12: =sumifs('25.06'!$H$7:$H$162,'25.06'!$G$7:$G$162,$B12,'25.06'!$F$7:$F$162,C$3) -> 0 | D12: =sumifs('25.06'!$H$7:$H$162,'25.06'!$G$7:$G$162,$B12,'25.06'!$F$7:$F$162,D$3) -> 0 | E12: =sumifs('25.06'!$H$7:$H$162,'25.06'!$G$7:$G$162,$B12,'25.06'!$F$7:$F$162,E$3) -> 0 | F12: =sumifs('25.06'!$H$7:$H$162,'25.06'!$G$7:$G$162,$B12,'25.06'!$F$7:$F$162,F$3) -> 0 | G12: =sumifs('25.06'!$H$7:$H$162,'25.06'!$G$7:$G$162,$B12,'25.06'!$F$7:$F$162,G$3) -> 0 | H12: =sumifs('25.06'!$H$7:$H$162,'25.06'!$G$7:$G$162,$B12,'25.06'!$F$7:$F$162,H$3) -> 0 | I12: =sumifs('25.06'!$H$7:$H$162,'25.06'!$G$7:$G$162,$B12,'25.06'!$F$7:$F$162,I$3) -> 0 | J12: =sumifs('25.06'!$H$7:$H$162,'25.06'!$G$7:$G$162,$B12,'25.06'!$F$7:$F$162,J$3) -> 0 | K12: =sumifs('25.06'!$H$7:$H$162,'25.06'!$G$7:$G$162,$B12,'25.06'!$F$7:$F$162,K$3) -> 0 | L12: =sum(C12:K12) -> 0 | N12: =L12/sum(L$10:L$16) -> #DIV/0! | R12: =sumifs('25.06'!$H$7:$H$162,'25.06'!$I$7:$I$162,$B12,'25.06'!$J$7:$J$162,R$3) -> 0 | S12: =sumifs('25.06'!$H$7:$H$162,'25.06'!$I$7:$I$162,$B12,'25.06'!$J$7:$J$162,S$3) -> 0 | T12: =sumifs('25.06'!$H$7:$H$162,'25.06'!$I$7:$I$162,$B12,'25.06'!$J$7:$J$162,T$3) -> 0 | U12: =sumifs('25.06'!$H$7:$H$162,'25.06'!$I$7:$I$162,$B12,'25.06'!$J$7:$J$162,U$3) -> 0 | V12: =sumifs('25.06'!$H$7:$H$162,'25.06'!$I$7:$I$162,$B12,'25.06'!$J$7:$J$162,V$3) -> 0 | W12: =sumifs('25.06'!$H$7:$H$162,'25.06'!$I$7:$I$162,$B12,'25.06'!$J$7:$J$162,W$3) -> 0 | X12: =sumifs('25.06'!$H$7:$H$162,'25.06'!$I$7:$I$162,$B12,'25.06'!$J$7:$J$162,X$3) -> 0 | Y12: =sumifs('25.06'!$H$7:$H$162,'25.06'!$I$7:$I$162,$B12,'25.06'!$J$7:$J$162,Y$3) -> 0 | Z12: =sumifs('25.06'!$H$7:$H$162,'25.06'!$I$7:$I$162,$B12,'25.06'!$J$7:$J$162,Z$3) -> 0 | AA12: =sum(R12:Z12) -> 0
A13: 44987 | B13: Restaurant | C13: =sumifs('25.06'!$H$7:$H$162,'25.06'!$G$7:$G$162,$B13,'25.06'!$F$7:$F$162,C$3) -> 0 | D13: =sumifs('25.06'!$H$7:$H$162,'25.06'!$G$7:$G$162,$B13,'25.06'!$F$7:$F$162,D$3) -> 0 | E13: =sumifs('25.06'!$H$7:$H$162,'25.06'!$G$7:$G$162,$B13,'25.06'!$F$7:$F$162,E$3) -> 0 | F13: =sumifs('25.06'!$H$7:$H$162,'25.06'!$G$7:$G$162,$B13,'25.06'!$F$7:$F$162,F$3) -> 0 | G13: =sumifs('25.06'!$H$7:$H$162,'25.06'!$G$7:$G$162,$B13,'25.06'!$F$7:$F$162,G$3) -> 0 | H13: =sumifs('25.06'!$H$7:$H$162,'25.06'!$G$7:$G$162,$B13,'25.06'!$F$7:$F$162,H$3) -> 0 | I13: =sumifs('25.06'!$H$7:$H$162,'25.06'!$G$7:$G$162,$B13,'25.06'!$F$7:$F$162,I$3) -> 0 | J13: =sumifs('25.06'!$H$7:$H$162,'25.06'!$G$7:$G$162,$B13,'25.06'!$F$7:$F$162,J$3) -> 0 | K13: =sumifs('25.06'!$H$7:$H$162,'25.06'!$G$7:$G$162,$B13,'25.06'!$F$7:$F$162,K$3) -> 0 | L13: =sum(C13:K13) -> 0 | N13: =L13/sum(L$10:L$16) -> #DIV/0! | R13: =sumifs('25.06'!$H$7:$H$162,'25.06'!$I$7:$I$162,$B13,'25.06'!$J$7:$J$162,R$3) -> 0 | S13: =sumifs('25.06'!$H$7:$H$162,'25.06'!$I$7:$I$162,$B13,'25.06'!$J$7:$J$162,S$3) -> 0 | T13: =sumifs('25.06'!$H$7:$H$162,'25.06'!$I$7:$I$162,$B13,'25.06'!$J$7:$J$162,T$3) -> 0 | U13: =sumifs('25.06'!$H$7:$H$162,'25.06'!$I$7:$I$162,$B13,'25.06'!$J$7:$J$162,U$3) -> 0 | V13: =sumifs('25.06'!$H$7:$H$162,'25.06'!$I$7:$I$162,$B13,'25.06'!$J$7:$J$162,V$3) -> 0 | W13: =sumifs('25.06'!$H$7:$H$162,'25.06'!$I$7:$I$162,$B13,'25.06'!$J$7:$J$162,W$3) -> 0 | X13: =sumifs('25.06'!$H$7:$H$162,'25.06'!$I$7:$I$162,$B13,'25.06'!$J$7:$J$162,X$3) -> 0 | Y13: =sumifs('25.06'!$H$7:$H$162,'25.06'!$I$7:$I$162,$B13,'25.06'!$J$7:$J$162,Y$3) -> 0 | Z13: =sumifs('25.06'!$H$7:$H$162,'25.06'!$I$7:$I$162,$B13,'25.06'!$J$7:$J$162,Z$3) -> 0 | AA13: =sum(R13:Z13) -> 0
A14: 45018 | B14: Sightseeing | C14: =sumifs('25.06'!$H$7:$H$162,'25.06'!$G$7:$G$162,$B14,'25.06'!$F$7:$F$162,C$3) -> 0 | D14: =sumifs('25.06'!$H$7:$H$162,'25.06'!$G$7:$G$162,$B14,'25.06'!$F$7:$F$162,D$3) -> 0 | E14: =sumifs('25.06'!$H$7:$H$162,'25.06'!$G$7:$G$162,$B14,'25.06'!$F$7:$F$162,E$3) -> 0 | F14: =sumifs('25.06'!$H$7:$H$162,'25.06'!$G$7:$G$162,$B14,'25.06'!$F$7:$F$162,F$3) -> 0 | G14: =sumifs('25.06'!$H$7:$H$162,'25.06'!$G$7:$G$162,$B14,'25.06'!$F$7:$F$162,G$3) -> 0 | H14: =sumifs('25.06'!$H$7:$H$162,'25.06'!$G$7:$G$162,$B14,'25.06'!$F$7:$F$162,H$3) -> 0 | I14: =sumifs('25.06'!$H$7:$H$162,'25.06'!$G$7:$G$162,$B14,'25.06'!$F$7:$F$162,I$3) -> 0 | J14: =sumifs('25.06'!$H$7:$H$162,'25.06'!$G$7:$G$162,$B14,'25.06'!$F$7:$F$162,J$3) -> 0 | K14: =sumifs('25.06'!$H$7:$H$162,'25.06'!$G$7:$G$162,$B14,'25.06'!$F$7:$F$162,K$3) -> 0 | L14: =sum(C14:K14) -> 0 | N14: =L14/sum(L$10:L$16) -> #DIV/0! | R14: =sumifs('25.06'!$H$7:$H$162,'25.06'!$I$7:$I$162,$B14,'25.06'!$J$7:$J$162,R$3) -> 0 | S14: =sumifs('25.06'!$H$7:$H$162,'25.06'!$I$7:$I$162,$B14,'25.06'!$J$7:$J$162,S$3) -> 0 | T14: =sumifs('25.06'!$H$7:$H$162,'25.06'!$I$7:$I$162,$B14,'25.06'!$J$7:$J$162,T$3) -> 0 | U14: =sumifs('25.06'!$H$7:$H$162,'25.06'!$I$7:$I$162,$B14,'25.06'!$J$7:$J$162,U$3) -> 0 | V14: =sumifs('25.06'!$H$7:$H$162,'25.06'!$I$7:$I$162,$B14,'25.06'!$J$7:$J$162,V$3) -> 0 | W14: =sumifs('25.06'!$H$7:$H$162,'25.06'!$I$7:$I$162,$B14,'25.06'!$J$7:$J$162,W$3) -> 0 | X14: =sumifs('25.06'!$H$7:$H$162,'25.06'!$I$7:$I$162,$B14,'25.06'!$J$7:$J$162,X$3) -> 0 | Y14: =sumifs('25.06'!$H$7:$H$162,'25.06'!$I$7:$I$162,$B14,'25.06'!$J$7:$J$162,Y$3) -> 0 | Z14: =sumifs('25.06'!$H$7:$H$162,'25.06'!$I$7:$I$162,$B14,'25.06'!$J$7:$J$162,Z$3) -> 0 | AA14: =sum(R14:Z14) -> 0
A15: 45048 | B15: Exhibition | C15: =sumifs('25.06'!$H$7:$H$162,'25.06'!$G$7:$G$162,$B15,'25.06'!$F$7:$F$162,C$3) -> 0 | D15: =sumifs('25.06'!$H$7:$H$162,'25.06'!$G$7:$G$162,$B15,'25.06'!$F$7:$F$162,D$3) -> 0 | E15: =sumifs('25.06'!$H$7:$H$162,'25.06'!$G$7:$G$162,$B15,'25.06'!$F$7:$F$162,E$3) -> 0 | F15: =sumifs('25.06'!$H$7:$H$162,'25.06'!$G$7:$G$162,$B15,'25.06'!$F$7:$F$162,F$3) -> 0 | G15: =sumifs('25.06'!$H$7:$H$162,'25.06'!$G$7:$G$162,$B15,'25.06'!$F$7:$F$162,G$3) -> 0 | H15: =sumifs('25.06'!$H$7:$H$162,'25.06'!$G$7:$G$162,$B15,'25.06'!$F$7:$F$162,H$3) -> 0 | I15: =sumifs('25.06'!$H$7:$H$162,'25.06'!$G$7:$G$162,$B15,'25.06'!$F$7:$F$162,I$3) -> 0 | J15: =sumifs('25.06'!$H$7:$H$162,'25.06'!$G$7:$G$162,$B15,'25.06'!$F$7:$F$162,J$3) -> 0 | K15: =sumifs('25.06'!$H$7:$H$162,'25.06'!$G$7:$G$162,$B15,'25.06'!$F$7:$F$162,K$3) -> 0 | L15: =sum(C15:K15) -> 0 | N15: =L15/sum(L$10:L$16) -> #DIV/0! | R15: =sumifs('25.06'!$H$7:$H$162,'25.06'!$I$7:$I$162,$B15,'25.06'!$J$7:$J$162,R$3) -> 0 | S15: =sumifs('25.06'!$H$7:$H$162,'25.06'!$I$7:$I$162,$B15,'25.06'!$J$7:$J$162,S$3) -> 0 | T15: =sumifs('25.06'!$H$7:$H$162,'25.06'!$I$7:$I$162,$B15,'25.06'!$J$7:$J$162,T$3) -> 0 | U15: =sumifs('25.06'!$H$7:$H$162,'25.06'!$I$7:$I$162,$B15,'25.06'!$J$7:$J$162,U$3) -> 0 | V15: =sumifs('25.06'!$H$7:$H$162,'25.06'!$I$7:$I$162,$B15,'25.06'!$J$7:$J$162,V$3) -> 0 | W15: =sumifs('25.06'!$H$7:$H$162,'25.06'!$I$7:$I$162,$B15,'25.06'!$J$7:$J$162,W$3) -> 0 | X15: =sumifs('25.06'!$H$7:$H$162,'25.06'!$I$7:$I$162,$B15,'25.06'!$J$7:$J$162,X$3) -> 0 | Y15: =sumifs('25.06'!$H$7:$H$162,'25.06'!$I$7:$I$162,$B15,'25.06'!$J$7:$J$162,Y$3) -> 0 | Z15: =sumifs('25.06'!$H$7:$H$162,'25.06'!$I$7:$I$162,$B15,'25.06'!$J$7:$J$162,Z$3) -> 0 | AA15: =sum(R15:Z15) -> 0
A16: 45079 | B16: Museum | C16: =sumifs('25.06'!$H$7:$H$162,'25.06'!$G$7:$G$162,$B16,'25.06'!$F$7:$F$162,C$3) -> 0 | D16: =sumifs('25.06'!$H$7:$H$162,'25.06'!$G$7:$G$162,$B16,'25.06'!$F$7:$F$162,D$3) -> 0 | E16: =sumifs('25.06'!$H$7:$H$162,'25.06'!$G$7:$G$162,$B16,'25.06'!$F$7:$F$162,E$3) -> 0 | F16: =sumifs('25.06'!$H$7:$H$162,'25.06'!$G$7:$G$162,$B16,'25.06'!$F$7:$F$162,F$3) -> 0 | G16: =sumifs('25.06'!$H$7:$H$162,'25.06'!$G$7:$G$162,$B16,'25.06'!$F$7:$F$162,G$3) -> 0 | H16: =sumifs('25.06'!$H$7:$H$162,'25.06'!$G$7:$G$162,$B16,'25.06'!$F$7:$F$162,H$3) -> 0 | I16: =sumifs('25.06'!$H$7:$H$162,'25.06'!$G$7:$G$162,$B16,'25.06'!$F$7:$F$162,I$3) -> 0 | J16: =sumifs('25.06'!$H$7:$H$162,'25.06'!$G$7:$G$162,$B16,'25.06'!$F$7:$F$162,J$3) -> 0 | K16: =sumifs('25.06'!$H$7:$H$162,'25.06'!$G$7:$G$162,$B16,'25.06'!$F$7:$F$162,K$3) -> 0 | L16: =sum(C16:K16) -> 0 | N16: =L16/sum(L$10:L$16) -> #DIV/0! | R16: =sumifs('25.06'!$H$7:$H$162,'25.06'!$I$7:$I$162,$B16,'25.06'!$J$7:$J$162,R$3) -> 0 | S16: =sumifs('25.06'!$H$7:$H$162,'25.06'!$I$7:$I$162,$B16,'25.06'!$J$7:$J$162,S$3) -> 0 | T16: =sumifs('25.06'!$H$7:$H$162,'25.06'!$I$7:$I$162,$B16,'25.06'!$J$7:$J$162,T$3) -> 0 | U16: =sumifs('25.06'!$H$7:$H$162,'25.06'!$I$7:$I$162,$B16,'25.06'!$J$7:$J$162,U$3) -> 0 | V16: =sumifs('25.06'!$H$7:$H$162,'25.06'!$I$7:$I$162,$B16,'25.06'!$J$7:$J$162,V$3) -> 0 | W16: =sumifs('25.06'!$H$7:$H$162,'25.06'!$I$7:$I$162,$B16,'25.06'!$J$7:$J$162,W$3) -> 0 | X16: =sumifs('25.06'!$H$7:$H$162,'25.06'!$I$7:$I$162,$B16,'25.06'!$J$7:$J$162,X$3) -> 0 | Y16: =sumifs('25.06'!$H$7:$H$162,'25.06'!$I$7:$I$162,$B16,'25.06'!$J$7:$J$162,Y$3) -> 0 | Z16: =sumifs('25.06'!$H$7:$H$162,'25.06'!$I$7:$I$162,$B16,'25.06'!$J$7:$J$162,Z$3) -> 0 | AA16: =sum(R16:Z16) -> 0
A17: 3 | B17: For give | C17: =sumifs('25.06'!$H$7:$H$162,'25.06'!$G$7:$G$162,$B17,'25.06'!$F$7:$F$162,C$3) -> 0 | D17: =sumifs('25.06'!$H$7:$H$162,'25.06'!$G$7:$G$162,$B17,'25.06'!$F$7:$F$162,D$3) -> 0 | E17: =sumifs('25.06'!$H$7:$H$162,'25.06'!$G$7:$G$162,$B17,'25.06'!$F$7:$F$162,E$3) -> 0 | F17: =sumifs('25.06'!$H$7:$H$162,'25.06'!$G$7:$G$162,$B17,'25.06'!$F$7:$F$162,F$3) -> 0 | G17: =sumifs('25.06'!$H$7:$H$162,'25.06'!$G$7:$G$162,$B17,'25.06'!$F$7:$F$162,G$3) -> 0 | H17: =sumifs('25.06'!$H$7:$H$162,'25.06'!$G$7:$G$162,$B17,'25.06'!$F$7:$F$162,H$3) -> 0 | I17: =sumifs('25.06'!$H$7:$H$162,'25.06'!$G$7:$G$162,$B17,'25.06'!$F$7:$F$162,I$3) -> 0 | J17: =sumifs('25.06'!$H$7:$H$162,'25.06'!$G$7:$G$162,$B17,'25.06'!$F$7:$F$162,J$3) -> 0 | K17: =sumifs('25.06'!$H$7:$H$162,'25.06'!$G$7:$G$162,$B17,'25.06'!$F$7:$F$162,K$3) -> 0 | L17: =sum(C17:K17) -> 0 | N17: =L17/sum(L$17:L$22) -> #DIV/0! | P17: =sum(L17:L22) -> 0 | Q17: =P17/sum($P$4:$P$57) -> #DIV/0! | R17: =sumifs('25.06'!$H$7:$H$162,'25.06'!$I$7:$I$162,$B17,'25.06'!$J$7:$J$162,R$3) -> 0 | S17: =sumifs('25.06'!$H$7:$H$162,'25.06'!$I$7:$I$162,$B17,'25.06'!$J$7:$J$162,S$3) -> 0 | T17: =sumifs('25.06'!$H$7:$H$162,'25.06'!$I$7:$I$162,$B17,'25.06'!$J$7:$J$162,T$3) -> 0 | U17: =sumifs('25.06'!$H$7:$H$162,'25.06'!$I$7:$I$162,$B17,'25.06'!$J$7:$J$162,U$3) -> 0 | V17: =sumifs('25.06'!$H$7:$H$162,'25.06'!$I$7:$I$162,$B17,'25.06'!$J$7:$J$162,V$3) -> 0 | W17: =sumifs('25.06'!$H$7:$H$162,'25.06'!$I$7:$I$162,$B17,'25.06'!$J$7:$J$162,W$3) -> 0 | X17: =sumifs('25.06'!$H$7:$H$162,'25.06'!$I$7:$I$162,$B17,'25.06'!$J$7:$J$162,X$3) -> 0 | Y17: =sumifs('25.06'!$H$7:$H$162,'25.06'!$I$7:$I$162,$B17,'25.06'!$J$7:$J$162,Y$3) -> 0 | Z17: =sumifs('25.06'!$H$7:$H$162,'25.06'!$I$7:$I$162,$B17,'25.06'!$J$7:$J$162,Z$3) -> 0 | AA17: =sum(R17:Z17) -> 0
A18: 44929 | B18: Funeral | C18: =sumifs('25.06'!$H$7:$H$162,'25.06'!$G$7:$G$162,$B18,'25.06'!$F$7:$F$162,C$3) -> 0 | D18: =sumifs('25.06'!$H$7:$H$162,'25.06'!$G$7:$G$162,$B18,'25.06'!$F$7:$F$162,D$3) -> 0 | E18: =sumifs('25.06'!$H$7:$H$162,'25.06'!$G$7:$G$162,$B18,'25.06'!$F$7:$F$162,E$3) -> 0 | F18: =sumifs('25.06'!$H$7:$H$162,'25.06'!$G$7:$G$162,$B18,'25.06'!$F$7:$F$162,F$3) -> 0 | G18: =sumifs('25.06'!$H$7:$H$162,'25.06'!$G$7:$G$162,$B18,'25.06'!$F$7:$F$162,G$3) -> 0 | H18: =sumifs('25.06'!$H$7:$H$162,'25.06'!$G$7:$G$162,$B18,'25.06'!$F$7:$F$162,H$3) -> 0 | I18: =sumifs('25.06'!$H$7:$H$162,'25.06'!$G$7:$G$162,$B18,'25.06'!$F$7:$F$162,I$3) -> 0 | J18: =sumifs('25.06'!$H$7:$H$162,'25.06'!$G$7:$G$162,$B18,'25.06'!$F$7:$F$162,J$3) -> 0 | K18: =sumifs('25.06'!$H$7:$H$162,'25.06'!$G$7:$G$162,$B18,'25.06'!$F$7:$F$162,K$3) -> 0 | L18: =sum(C18:K18) -> 0 | N18: =L18/sum(L$17:L$22) -> #DIV/0! | R18: =sumifs('25.06'!$H$7:$H$162,'25.06'!$I$7:$I$162,$B18,'25.06'!$J$7:$J$162,R$3) -> 0 | S18: =sumifs('25.06'!$H$7:$H$162,'25.06'!$I$7:$I$162,$B18,'25.06'!$J$7:$J$162,S$3) -> 0 | T18: =sumifs('25.06'!$H$7:$H$162,'25.06'!$I$7:$I$162,$B18,'25.06'!$J$7:$J$162,T$3) -> 0 | U18: =sumifs('25.06'!$H$7:$H$162,'25.06'!$I$7:$I$162,$B18,'25.06'!$J$7:$J$162,U$3) -> 0 | V18: =sumifs('25.06'!$H$7:$H$162,'25.06'!$I$7:$I$162,$B18,'25.06'!$J$7:$J$162,V$3) -> 0 | W18: =sumifs('25.06'!$H$7:$H$162,'25.06'!$I$7:$I$162,$B18,'25.06'!$J$7:$J$162,W$3) -> 0 | X18: =sumifs('25.06'!$H$7:$H$162,'25.06'!$I$7:$I$162,$B18,'25.06'!$J$7:$J$162,X$3) -> 0 | Y18: =sumifs('25.06'!$H$7:$H$162,'25.06'!$I$7:$I$162,$B18,'25.06'!$J$7:$J$162,Y$3) -> 0 | Z18: =sumifs('25.06'!$H$7:$H$162,'25.06'!$I$7:$I$162,$B18,'25.06'!$J$7:$J$162,Z$3) -> 0 | AA18: =sum(R18:Z18) -> 0
A19: 44960 | B19: Wedding | C19: =sumifs('25.06'!$H$7:$H$162,'25.06'!$G$7:$G$162,$B19,'25.06'!$F$7:$F$162,C$3) -> 0 | D19: =sumifs('25.06'!$H$7:$H$162,'25.06'!$G$7:$G$162,$B19,'25.06'!$F$7:$F$162,D$3) -> 0 | E19: =sumifs('25.06'!$H$7:$H$162,'25.06'!$G$7:$G$162,$B19,'25.06'!$F$7:$F$162,E$3) -> 0 | F19: =sumifs('25.06'!$H$7:$H$162,'25.06'!$G$7:$G$162,$B19,'25.06'!$F$7:$F$162,F$3) -> 0 | G19: =sumifs('25.06'!$H$7:$H$162,'25.06'!$G$7:$G$162,$B19,'25.06'!$F$7:$F$162,G$3) -> 0 | H19: =sumifs('25.06'!$H$7:$H$162,'25.06'!$G$7:$G$162,$B19,'25.06'!$F$7:$F$162,H$3) -> 0 | I19: =sumifs('25.06'!$H$7:$H$162,'25.06'!$G$7:$G$162,$B19,'25.06'!$F$7:$F$162,I$3) -> 0 | J19: =sumifs('25.06'!$H$7:$H$162,'25.06'!$G$7:$G$162,$B19,'25.06'!$F$7:$F$162,J$3) -> 0 | K19: =sumifs('25.06'!$H$7:$H$162,'25.06'!$G$7:$G$162,$B19,'25.06'!$F$7:$F$162,K$3) -> 0 | L19: =sum(C19:K19) -> 0 | N19: =L19/sum(L$17:L$22) -> #DIV/0! | R19: =sumifs('25.06'!$H$7:$H$162,'25.06'!$I$7:$I$162,$B19,'25.06'!$J$7:$J$162,R$3) -> 0 | S19: =sumifs('25.06'!$H$7:$H$162,'25.06'!$I$7:$I$162,$B19,'25.06'!$J$7:$J$162,S$3) -> 0 | T19: =sumifs('25.06'!$H$7:$H$162,'25.06'!$I$7:$I$162,$B19,'25.06'!$J$7:$J$162,T$3) -> 0 | U19: =sumifs('25.06'!$H$7:$H$162,'25.06'!$I$7:$I$162,$B19,'25.06'!$J$7:$J$162,U$3) -> 0 | V19: =sumifs('25.06'!$H$7:$H$162,'25.06'!$I$7:$I$162,$B19,'25.06'!$J$7:$J$162,V$3) -> 0 | W19: =sumifs('25.06'!$H$7:$H$162,'25.06'!$I$7:$I$162,$B19,'25.06'!$J$7:$J$162,W$3) -> 0 | X19: =sumifs('25.06'!$H$7:$H$162,'25.06'!$I$7:$I$162,$B19,'25.06'!$J$7:$J$162,X$3) -> 0 | Y19: =sumifs('25.06'!$H$7:$H$162,'25.06'!$I$7:$I$162,$B19,'25.06'!$J$7:$J$162,Y$3) -> 0 | Z19: =sumifs('25.06'!$H$7:$H$162,'25.06'!$I$7:$I$162,$B19,'25.06'!$J$7:$J$162,Z$3) -> 0 | AA19: =sum(R19:Z19) -> 0
A20: 44988 | B20: Gift | C20: =sumifs('25.06'!$H$7:$H$162,'25.06'!$G$7:$G$162,$B20,'25.06'!$F$7:$F$162,C$3) -> 0 | D20: =sumifs('25.06'!$H$7:$H$162,'25.06'!$G$7:$G$162,$B20,'25.06'!$F$7:$F$162,D$3) -> 0 | E20: =sumifs('25.06'!$H$7:$H$162,'25.06'!$G$7:$G$162,$B20,'25.06'!$F$7:$F$162,E$3) -> 0 | F20: =sumifs('25.06'!$H$7:$H$162,'25.06'!$G$7:$G$162,$B20,'25.06'!$F$7:$F$162,F$3) -> 0 | G20: =sumifs('25.06'!$H$7:$H$162,'25.06'!$G$7:$G$162,$B20,'25.06'!$F$7:$F$162,G$3) -> 0 | H20: =sumifs('25.06'!$H$7:$H$162,'25.06'!$G$7:$G$162,$B20,'25.06'!$F$7:$F$162,H$3) -> 0 | I20: =sumifs('25.06'!$H$7:$H$162,'25.06'!$G$7:$G$162,$B20,'25.06'!$F$7:$F$162,I$3) -> 0 | J20: =sumifs('25.06'!$H$7:$H$162,'25.06'!$G$7:$G$162,$B20,'25.06'!$F$7:$F$162,J$3) -> 0 | K20: =sumifs('25.06'!$H$7:$H$162,'25.06'!$G$7:$G$162,$B20,'25.06'!$F$7:$F$162,K$3) -> 0 | L20: =sum(C20:K20) -> 0 | N20: =L20/sum(L$17:L$22) -> #DIV/0! | R20: =sumifs('25.06'!$H$7:$H$162,'25.06'!$I$7:$I$162,$B20,'25.06'!$J$7:$J$162,R$3) -> 0 | S20: =sumifs('25.06'!$H$7:$H$162,'25.06'!$I$7:$I$162,$B20,'25.06'!$J$7:$J$162,S$3) -> 0 | T20: =sumifs('25.06'!$H$7:$H$162,'25.06'!$I$7:$I$162,$B20,'25.06'!$J$7:$J$162,T$3) -> 0 | U20: =sumifs('25.06'!$H$7:$H$162,'25.06'!$I$7:$I$162,$B20,'25.06'!$J$7:$J$162,U$3) -> 0 | V20: =sumifs('25.06'!$H$7:$H$162,'25.06'!$I$7:$I$162,$B20,'25.06'!$J$7:$J$162,V$3) -> 0 | W20: =sumifs('25.06'!$H$7:$H$162,'25.06'!$I$7:$I$162,$B20,'25.06'!$J$7:$J$162,W$3) -> 0 | X20: =sumifs('25.06'!$H$7:$H$162,'25.06'!$I$7:$I$162,$B20,'25.06'!$J$7:$J$162,X$3) -> 0 | Y20: =sumifs('25.06'!$H$7:$H$162,'25.06'!$I$7:$I$162,$B20,'25.06'!$J$7:$J$162,Y$3) -> 0 | Z20: =sumifs('25.06'!$H$7:$H$162,'25.06'!$I$7:$I$162,$B20,'25.06'!$J$7:$J$162,Z$3) -> 0 | AA20: =sum(R20:Z20) -> 0
A21: 45019 | B21: Charity | C21: =sumifs('25.06'!$H$7:$H$162,'25.06'!$G$7:$G$162,$B21,'25.06'!$F$7:$F$162,C$3) -> 0 | D21: =sumifs('25.06'!$H$7:$H$162,'25.06'!$G$7:$G$162,$B21,'25.06'!$F$7:$F$162,D$3) -> 0 | E21: =sumifs('25.06'!$H$7:$H$162,'25.06'!$G$7:$G$162,$B21,'25.06'!$F$7:$F$162,E$3) -> 0 | F21: =sumifs('25.06'!$H$7:$H$162,'25.06'!$G$7:$G$162,$B21,'25.06'!$F$7:$F$162,F$3) -> 0 | G21: =sumifs('25.06'!$H$7:$H$162,'25.06'!$G$7:$G$162,$B21,'25.06'!$F$7:$F$162,G$3) -> 0 | H21: =sumifs('25.06'!$H$7:$H$162,'25.06'!$G$7:$G$162,$B21,'25.06'!$F$7:$F$162,H$3) -> 0 | I21: =sumifs('25.06'!$H$7:$H$162,'25.06'!$G$7:$G$162,$B21,'25.06'!$F$7:$F$162,I$3) -> 0 | J21: =sumifs('25.06'!$H$7:$H$162,'25.06'!$G$7:$G$162,$B21,'25.06'!$F$7:$F$162,J$3) -> 0 | K21: =sumifs('25.06'!$H$7:$H$162,'25.06'!$G$7:$G$162,$B21,'25.06'!$F$7:$F$162,K$3) -> 0 | L21: =sum(C21:K21) -> 0 | N21: =L21/sum(L$17:L$22) -> #DIV/0! | R21: =sumifs('25.06'!$H$7:$H$162,'25.06'!$I$7:$I$162,$B21,'25.06'!$J$7:$J$162,R$3) -> 0 | S21: =sumifs('25.06'!$H$7:$H$162,'25.06'!$I$7:$I$162,$B21,'25.06'!$J$7:$J$162,S$3) -> 0 | T21: =sumifs('25.06'!$H$7:$H$162,'25.06'!$I$7:$I$162,$B21,'25.06'!$J$7:$J$162,T$3) -> 0 | U21: =sumifs('25.06'!$H$7:$H$162,'25.06'!$I$7:$I$162,$B21,'25.06'!$J$7:$J$162,U$3) -> 0 | V21: =sumifs('25.06'!$H$7:$H$162,'25.06'!$I$7:$I$162,$B21,'25.06'!$J$7:$J$162,V$3) -> 0 | W21: =sumifs('25.06'!$H$7:$H$162,'25.06'!$I$7:$I$162,$B21,'25.06'!$J$7:$J$162,W$3) -> 0 | X21: =sumifs('25.06'!$H$7:$H$162,'25.06'!$I$7:$I$162,$B21,'25.06'!$J$7:$J$162,X$3) -> 0 | Y21: =sumifs('25.06'!$H$7:$H$162,'25.06'!$I$7:$I$162,$B21,'25.06'!$J$7:$J$162,Y$3) -> 0 | Z21: =sumifs('25.06'!$H$7:$H$162,'25.06'!$I$7:$I$162,$B21,'25.06'!$J$7:$J$162,Z$3) -> 0 | AA21: =sum(R21:Z21) -> 0
A22: 45049 | B22: Spirituality | C22: =sumifs('25.06'!$H$7:$H$162,'25.06'!$G$7:$G$162,$B22,'25.06'!$F$7:$F$162,C$3) -> 0 | D22: =sumifs('25.06'!$H$7:$H$162,'25.06'!$G$7:$G$162,$B22,'25.06'!$F$7:$F$162,D$3) -> 0 | E22: =sumifs('25.06'!$H$7:$H$162,'25.06'!$G$7:$G$162,$B22,'25.06'!$F$7:$F$162,E$3) -> 0 | F22: =sumifs('25.06'!$H$7:$H$162,'25.06'!$G$7:$G$162,$B22,'25.06'!$F$7:$F$162,F$3) -> 0 | G22: =sumifs('25.06'!$H$7:$H$162,'25.06'!$G$7:$G$162,$B22,'25.06'!$F$7:$F$162,G$3) -> 0 | H22: =sumifs('25.06'!$H$7:$H$162,'25.06'!$G$7:$G$162,$B22,'25.06'!$F$7:$F$162,H$3) -> 0 | I22: =sumifs('25.06'!$H$7:$H$162,'25.06'!$G$7:$G$162,$B22,'25.06'!$F$7:$F$162,I$3) -> 0 | J22: =sumifs('25.06'!$H$7:$H$162,'25.06'!$G$7:$G$162,$B22,'25.06'!$F$7:$F$162,J$3) -> 0 | K22: =sumifs('25.06'!$H$7:$H$162,'25.06'!$G$7:$G$162,$B22,'25.06'!$F$7:$F$162,K$3) -> 0 | L22: =sum(C22:K22) -> 0 | N22: =L22/sum(L$17:L$22) -> #DIV/0! | R22: =sumifs('25.06'!$H$7:$H$162,'25.06'!$I$7:$I$162,$B22,'25.06'!$J$7:$J$162,R$3) -> 0 | S22: =sumifs('25.06'!$H$7:$H$162,'25.06'!$I$7:$I$162,$B22,'25.06'!$J$7:$J$162,S$3) -> 0 | T22: =sumifs('25.06'!$H$7:$H$162,'25.06'!$I$7:$I$162,$B22,'25.06'!$J$7:$J$162,T$3) -> 0 | U22: =sumifs('25.06'!$H$7:$H$162,'25.06'!$I$7:$I$162,$B22,'25.06'!$J$7:$J$162,U$3) -> 0 | V22: =sumifs('25.06'!$H$7:$H$162,'25.06'!$I$7:$I$162,$B22,'25.06'!$J$7:$J$162,V$3) -> 0 | W22: =sumifs('25.06'!$H$7:$H$162,'25.06'!$I$7:$I$162,$B22,'25.06'!$J$7:$J$162,W$3) -> 0 | X22: =sumifs('25.06'!$H$7:$H$162,'25.06'!$I$7:$I$162,$B22,'25.06'!$J$7:$J$162,X$3) -> 0 | Y22: =sumifs('25.06'!$H$7:$H$162,'25.06'!$I$7:$I$162,$B22,'25.06'!$J$7:$J$162,Y$3) -> 0 | Z22: =sumifs('25.06'!$H$7:$H$162,'25.06'!$I$7:$I$162,$B22,'25.06'!$J$7:$J$162,Z$3) -> 0 | AA22: =sum(R22:Z22) -> 0
A23: 4 | B23: Health | C23: =sumifs('25.06'!$H$7:$H$162,'25.06'!$G$7:$G$162,$B23,'25.06'!$F$7:$F$162,C$3) -> 0 | D23: =sumifs('25.06'!$H$7:$H$162,'25.06'!$G$7:$G$162,$B23,'25.06'!$F$7:$F$162,D$3) -> 0 | E23: =sumifs('25.06'!$H$7:$H$162,'25.06'!$G$7:$G$162,$B23,'25.06'!$F$7:$F$162,E$3) -> 0 | F23: =sumifs('25.06'!$H$7:$H$162,'25.06'!$G$7:$G$162,$B23,'25.06'!$F$7:$F$162,F$3) -> 0 | G23: =sumifs('25.06'!$H$7:$H$162,'25.06'!$G$7:$G$162,$B23,'25.06'!$F$7:$F$162,G$3) -> 0 | H23: =sumifs('25.06'!$H$7:$H$162,'25.06'!$G$7:$G$162,$B23,'25.06'!$F$7:$F$162,H$3) -> 0 | I23: =sumifs('25.06'!$H$7:$H$162,'25.06'!$G$7:$G$162,$B23,'25.06'!$F$7:$F$162,I$3) -> 0 | J23: =sumifs('25.06'!$H$7:$H$162,'25.06'!$G$7:$G$162,$B23,'25.06'!$F$7:$F$162,J$3) -> 0 | K23: =sumifs('25.06'!$H$7:$H$162,'25.06'!$G$7:$G$162,$B23,'25.06'!$F$7:$F$162,K$3) -> 0 | L23: =sum(C23:K23) -> 0 | N23: =L23/sum(L$23:L$28) -> #DIV/0! | P23: =sum(L23:L28) -> 0 | Q23: =P22/sum($P$4:$P$57) -> #DIV/0! | R23: =sumifs('25.06'!$H$7:$H$162,'25.06'!$I$7:$I$162,$B23,'25.06'!$J$7:$J$162,R$3) -> 0 | S23: =sumifs('25.06'!$H$7:$H$162,'25.06'!$I$7:$I$162,$B23,'25.06'!$J$7:$J$162,S$3) -> 0 | T23: =sumifs('25.06'!$H$7:$H$162,'25.06'!$I$7:$I$162,$B23,'25.06'!$J$7:$J$162,T$3) -> 0 | U23: =sumifs('25.06'!$H$7:$H$162,'25.06'!$I$7:$I$162,$B23,'25.06'!$J$7:$J$162,U$3) -> 0 | V23: =sumifs('25.06'!$H$7:$H$162,'25.06'!$I$7:$I$162,$B23,'25.06'!$J$7:$J$162,V$3) -> 0 | W23: =sumifs('25.06'!$H$7:$H$162,'25.06'!$I$7:$I$162,$B23,'25.06'!$J$7:$J$162,W$3) -> 0 | X23: =sumifs('25.06'!$H$7:$H$162,'25.06'!$I$7:$I$162,$B23,'25.06'!$J$7:$J$162,X$3) -> 0 | Y23: =sumifs('25.06'!$H$7:$H$162,'25.06'!$I$7:$I$162,$B23,'25.06'!$J$7:$J$162,Y$3) -> 0 | Z23: =sumifs('25.06'!$H$7:$H$162,'25.06'!$I$7:$I$162,$B23,'25.06'!$J$7:$J$162,Z$3) -> 0 | AA23: =sum(R23:Z23) -> 0
A24: 44930 | B24: Medical exam | C24: =sumifs('25.06'!$H$7:$H$162,'25.06'!$G$7:$G$162,$B24,'25.06'!$F$7:$F$162,C$3) -> 0 | D24: =sumifs('25.06'!$H$7:$H$162,'25.06'!$G$7:$G$162,$B24,'25.06'!$F$7:$F$162,D$3) -> 0 | E24: =sumifs('25.06'!$H$7:$H$162,'25.06'!$G$7:$G$162,$B24,'25.06'!$F$7:$F$162,E$3) -> 0 | F24: =sumifs('25.06'!$H$7:$H$162,'25.06'!$G$7:$G$162,$B24,'25.06'!$F$7:$F$162,F$3) -> 0 | G24: =sumifs('25.06'!$H$7:$H$162,'25.06'!$G$7:$G$162,$B24,'25.06'!$F$7:$F$162,G$3) -> 0 | H24: =sumifs('25.06'!$H$7:$H$162,'25.06'!$G$7:$G$162,$B24,'25.06'!$F$7:$F$162,H$3) -> 0 | I24: =sumifs('25.06'!$H$7:$H$162,'25.06'!$G$7:$G$162,$B24,'25.06'!$F$7:$F$162,I$3) -> 0 | J24: =sumifs('25.06'!$H$7:$H$162,'25.06'!$G$7:$G$162,$B24,'25.06'!$F$7:$F$162,J$3) -> 0 | K24: =sumifs('25.06'!$H$7:$H$162,'25.06'!$G$7:$G$162,$B24,'25.06'!$F$7:$F$162,K$3) -> 0 | L24: =sum(C24:K24) -> 0 | N24: =L24/sum(L$23:L$28) -> #DIV/0! | R24: =sumifs('25.06'!$H$7:$H$162,'25.06'!$I$7:$I$162,$B24,'25.06'!$J$7:$J$162,R$3) -> 0 | S24: =sumifs('25.06'!$H$7:$H$162,'25.06'!$I$7:$I$162,$B24,'25.06'!$J$7:$J$162,S$3) -> 0 | T24: =sumifs('25.06'!$H$7:$H$162,'25.06'!$I$7:$I$162,$B24,'25.06'!$J$7:$J$162,T$3) -> 0 | U24: =sumifs('25.06'!$H$7:$H$162,'25.06'!$I$7:$I$162,$B24,'25.06'!$J$7:$J$162,U$3) -> 0 | V24: =sumifs('25.06'!$H$7:$H$162,'25.06'!$I$7:$I$162,$B24,'25.06'!$J$7:$J$162,V$3) -> 0 | W24: =sumifs('25.06'!$H$7:$H$162,'25.06'!$I$7:$I$162,$B24,'25.06'!$J$7:$J$162,W$3) -> 0 | X24: =sumifs('25.06'!$H$7:$H$162,'25.06'!$I$7:$I$162,$B24,'25.06'!$J$7:$J$162,X$3) -> 0 | Y24: =sumifs('25.06'!$H$7:$H$162,'25.06'!$I$7:$I$162,$B24,'25.06'!$J$7:$J$162,Y$3) -> 0 | Z24: =sumifs('25.06'!$H$7:$H$162,'25.06'!$I$7:$I$162,$B24,'25.06'!$J$7:$J$162,Z$3) -> 0 | AA24: =sum(R24:Z24) -> 0
B25: Tablets | C25: =sumifs('25.06'!$H$7:$H$162,'25.06'!$G$7:$G$162,$B25,'25.06'!$F$7:$F$162,C$3) -> 0 | D25: =sumifs('25.06'!$H$7:$H$162,'25.06'!$G$7:$G$162,$B25,'25.06'!$F$7:$F$162,D$3) -> 0 | E25: =sumifs('25.06'!$H$7:$H$162,'25.06'!$G$7:$G$162,$B25,'25.06'!$F$7:$F$162,E$3) -> 0 | F25: =sumifs('25.06'!$H$7:$H$162,'25.06'!$G$7:$G$162,$B25,'25.06'!$F$7:$F$162,F$3) -> 0 | G25: =sumifs('25.06'!$H$7:$H$162,'25.06'!$G$7:$G$162,$B25,'25.06'!$F$7:$F$162,G$3) -> 0 | H25: =sumifs('25.06'!$H$7:$H$162,'25.06'!$G$7:$G$162,$B25,'25.06'!$F$7:$F$162,H$3) -> 0 | I25: =sumifs('25.06'!$H$7:$H$162,'25.06'!$G$7:$G$162,$B25,'25.06'!$F$7:$F$162,I$3) -> 0 | J25: =sumifs('25.06'!$H$7:$H$162,'25.06'!$G$7:$G$162,$B25,'25.06'!$F$7:$F$162,J$3) -> 0 | K25: =sumifs('25.06'!$H$7:$H$162,'25.06'!$G$7:$G$162,$B25,'25.06'!$F$7:$F$162,K$3) -> 0 | L25: =sum(C25:K25) -> 0
A26: 44961 | B26: Body care | C26: =sumifs('25.06'!$H$7:$H$162,'25.06'!$G$7:$G$162,$B26,'25.06'!$F$7:$F$162,C$3) -> 0 | D26: =sumifs('25.06'!$H$7:$H$162,'25.06'!$G$7:$G$162,$B26,'25.06'!$F$7:$F$162,D$3) -> 0 | E26: =sumifs('25.06'!$H$7:$H$162,'25.06'!$G$7:$G$162,$B26,'25.06'!$F$7:$F$162,E$3) -> 0 | F26: =sumifs('25.06'!$H$7:$H$162,'25.06'!$G$7:$G$162,$B26,'25.06'!$F$7:$F$162,F$3) -> 0 | G26: =sumifs('25.06'!$H$7:$H$162,'25.06'!$G$7:$G$162,$B26,'25.06'!$F$7:$F$162,G$3) -> 0 | H26: =sumifs('25.06'!$H$7:$H$162,'25.06'!$G$7:$G$162,$B26,'25.06'!$F$7:$F$162,H$3) -> 0 | I26: =sumifs('25.06'!$H$7:$H$162,'25.06'!$G$7:$G$162,$B26,'25.06'!$F$7:$F$162,I$3) -> 0 | J26: =sumifs('25.06'!$H$7:$H$162,'25.06'!$G$7:$G$162,$B26,'25.06'!$F$7:$F$162,J$3) -> 0 | K26: =sumifs('25.06'!$H$7:$H$162,'25.06'!$G$7:$G$162,$B26,'25.06'!$F$7:$F$162,K$3) -> 0 | L26: =sum(C26:K26) -> 0 | N26: =L26/sum(L$23:L$28) -> #DIV/0! | R26: =sumifs('25.06'!$H$7:$H$162,'25.06'!$I$7:$I$162,$B26,'25.06'!$J$7:$J$162,R$3) -> 0 | S26: =sumifs('25.06'!$H$7:$H$162,'25.06'!$I$7:$I$162,$B26,'25.06'!$J$7:$J$162,S$3) -> 0 | T26: =sumifs('25.06'!$H$7:$H$162,'25.06'!$I$7:$I$162,$B26,'25.06'!$J$7:$J$162,T$3) -> 0 | U26: =sumifs('25.06'!$H$7:$H$162,'25.06'!$I$7:$I$162,$B26,'25.06'!$J$7:$J$162,U$3) -> 0 | V26: =sumifs('25.06'!$H$7:$H$162,'25.06'!$I$7:$I$162,$B26,'25.06'!$J$7:$J$162,V$3) -> 0 | W26: =sumifs('25.06'!$H$7:$H$162,'25.06'!$I$7:$I$162,$B26,'25.06'!$J$7:$J$162,W$3) -> 0 | X26: =sumifs('25.06'!$H$7:$H$162,'25.06'!$I$7:$I$162,$B26,'25.06'!$J$7:$J$162,X$3) -> 0 | Y26: =sumifs('25.06'!$H$7:$H$162,'25.06'!$I$7:$I$162,$B26,'25.06'!$J$7:$J$162,Y$3) -> 0 | Z26: =sumifs('25.06'!$H$7:$H$162,'25.06'!$I$7:$I$162,$B26,'25.06'!$J$7:$J$162,Z$3) -> 0 | AA26: =sum(R26:Z26) -> 0
A27: 44989 | B27: Cosmetic | C27: =sumifs('25.06'!$H$7:$H$162,'25.06'!$G$7:$G$162,$B27,'25.06'!$F$7:$F$162,C$3) -> 0 | E27: =sumifs('25.06'!$H$7:$H$162,'25.06'!$G$7:$G$162,$B27,'25.06'!$F$7:$F$162,E$3) -> 0 | F27: =sumifs('25.06'!$H$7:$H$162,'25.06'!$G$7:$G$162,$B27,'25.06'!$F$7:$F$162,F$3) -> 0 | G27: =sumifs('25.06'!$H$7:$H$162,'25.06'!$G$7:$G$162,$B27,'25.06'!$F$7:$F$162,G$3) -> 0 | H27: =sumifs('25.06'!$H$7:$H$162,'25.06'!$G$7:$G$162,$B27,'25.06'!$F$7:$F$162,H$3) -> 0 | I27: =sumifs('25.06'!$H$7:$H$162,'25.06'!$G$7:$G$162,$B27,'25.06'!$F$7:$F$162,I$3) -> 0 | J27: =sumifs('25.06'!$H$7:$H$162,'25.06'!$G$7:$G$162,$B27,'25.06'!$F$7:$F$162,J$3) -> 0 | K27: =sumifs('25.06'!$H$7:$H$162,'25.06'!$G$7:$G$162,$B27,'25.06'!$F$7:$F$162,K$3) -> 0 | L27: =sum(C27:K27) -> 0 | N27: =L27/sum(L$23:L$28) -> #DIV/0! | R27: =sumifs('25.06'!$H$7:$H$162,'25.06'!$I$7:$I$162,$B27,'25.06'!$J$7:$J$162,R$3) -> 0 | S27: =sumifs('25.06'!$H$7:$H$162,'25.06'!$I$7:$I$162,$B27,'25.06'!$J$7:$J$162,S$3) -> 0 | T27: =sumifs('25.06'!$H$7:$H$162,'25.06'!$I$7:$I$162,$B27,'25.06'!$J$7:$J$162,T$3) -> 0 | U27: =sumifs('25.06'!$H$7:$H$162,'25.06'!$I$7:$I$162,$B27,'25.06'!$J$7:$J$162,U$3) -> 0 | V27: =sumifs('25.06'!$H$7:$H$162,'25.06'!$I$7:$I$162,$B27,'25.06'!$J$7:$J$162,V$3) -> 0 | W27: =sumifs('25.06'!$H$7:$H$162,'25.06'!$I$7:$I$162,$B27,'25.06'!$J$7:$J$162,W$3) -> 0 | X27: =sumifs('25.06'!$H$7:$H$162,'25.06'!$I$7:$I$162,$B27,'25.06'!$J$7:$J$162,X$3) -> 0 | Y27: =sumifs('25.06'!$H$7:$H$162,'25.06'!$I$7:$I$162,$B27,'25.06'!$J$7:$J$162,Y$3) -> 0 | Z27: =sumifs('25.06'!$H$7:$H$162,'25.06'!$I$7:$I$162,$B27,'25.06'!$J$7:$J$162,Z$3) -> 0 | AA27: =sum(R27:Z27) -> 0
A28: 45020 | B28: Medical Insurrance | C28: =sumifs('25.06'!$H$7:$H$162,'25.06'!$G$7:$G$162,$B28,'25.06'!$F$7:$F$162,C$3) -> 0 | D28: =sumifs('25.06'!$H$7:$H$162,'25.06'!$G$7:$G$162,$B28,'25.06'!$F$7:$F$162,D$3) -> 0 | E28: =sumifs('25.06'!$H$7:$H$162,'25.06'!$G$7:$G$162,$B28,'25.06'!$F$7:$F$162,E$3) -> 0 | F28: =sumifs('25.06'!$H$7:$H$162,'25.06'!$G$7:$G$162,$B28,'25.06'!$F$7:$F$162,F$3) -> 0 | G28: =sumifs('25.06'!$H$7:$H$162,'25.06'!$G$7:$G$162,$B28,'25.06'!$F$7:$F$162,G$3) -> 0 | H28: =sumifs('25.06'!$H$7:$H$162,'25.06'!$G$7:$G$162,$B28,'25.06'!$F$7:$F$162,H$3) -> 0 | I28: =sumifs('25.06'!$H$7:$H$162,'25.06'!$G$7:$G$162,$B28,'25.06'!$F$7:$F$162,I$3) -> 0 | J28: =sumifs('25.06'!$H$7:$H$162,'25.06'!$G$7:$G$162,$B28,'25.06'!$F$7:$F$162,J$3) -> 0 | K28: =sumifs('25.06'!$H$7:$H$162,'25.06'!$G$7:$G$162,$B28,'25.06'!$F$7:$F$162,K$3) -> 0 | L28: =sum(C28:K28) -> 0 | N28: =L28/sum(L$23:L$28) -> #DIV/0! | R28: =sumifs('25.06'!$H$7:$H$162,'25.06'!$I$7:$I$162,$B28,'25.06'!$J$7:$J$162,R$3) -> 0 | S28: =sumifs('25.06'!$H$7:$H$162,'25.06'!$I$7:$I$162,$B28,'25.06'!$J$7:$J$162,S$3) -> 0 | T28: =sumifs('25.06'!$H$7:$H$162,'25.06'!$I$7:$I$162,$B28,'25.06'!$J$7:$J$162,T$3) -> 0 | U28: =sumifs('25.06'!$H$7:$H$162,'25.06'!$I$7:$I$162,$B28,'25.06'!$J$7:$J$162,U$3) -> 0 | V28: =sumifs('25.06'!$H$7:$H$162,'25.06'!$I$7:$I$162,$B28,'25.06'!$J$7:$J$162,V$3) -> 0 | W28: =sumifs('25.06'!$H$7:$H$162,'25.06'!$I$7:$I$162,$B28,'25.06'!$J$7:$J$162,W$3) -> 0 | X28: =sumifs('25.06'!$H$7:$H$162,'25.06'!$I$7:$I$162,$B28,'25.06'!$J$7:$J$162,X$3) -> 0 | Y28: =sumifs('25.06'!$H$7:$H$162,'25.06'!$I$7:$I$162,$B28,'25.06'!$J$7:$J$162,Y$3) -> 0 | Z28: =sumifs('25.06'!$H$7:$H$162,'25.06'!$I$7:$I$162,$B28,'25.06'!$J$7:$J$162,Z$3) -> 0 | AA28: =sum(R28:Z28) -> 0
A29: 5 | B29: Living | C29: =sumifs('25.06'!$H$7:$H$162,'25.06'!$G$7:$G$162,$B29,'25.06'!$F$7:$F$162,C$3) -> 0 | D29: =sumifs('25.06'!$H$7:$H$162,'25.06'!$G$7:$G$162,$B29,'25.06'!$F$7:$F$162,D$3) -> 0 | E29: =sumifs('25.06'!$H$7:$H$162,'25.06'!$G$7:$G$162,$B29,'25.06'!$F$7:$F$162,E$3) -> 0 | F29: =sumifs('25.06'!$H$7:$H$162,'25.06'!$G$7:$G$162,$B29,'25.06'!$F$7:$F$162,F$3) -> 0 | G29: =sumifs('25.06'!$H$7:$H$162,'25.06'!$G$7:$G$162,$B29,'25.06'!$F$7:$F$162,G$3) -> 0 | H29: =sumifs('25.06'!$H$7:$H$162,'25.06'!$G$7:$G$162,$B29,'25.06'!$F$7:$F$162,H$3) -> 0 | I29: =sumifs('25.06'!$H$7:$H$162,'25.06'!$G$7:$G$162,$B29,'25.06'!$F$7:$F$162,I$3) -> 0 | J29: =sumifs('25.06'!$H$7:$H$162,'25.06'!$G$7:$G$162,$B29,'25.06'!$F$7:$F$162,J$3) -> 0 | K29: =sumifs('25.06'!$H$7:$H$162,'25.06'!$G$7:$G$162,$B29,'25.06'!$F$7:$F$162,K$3) -> 0 | L29: =sum(C29:K29) -> 0 | N29: =L29/sum(L$29:L$54) -> #DIV/0! | P29: =sum(L29:L54) -> 0 | Q29: =P29/sum($P$4:$P$57) -> #DIV/0! | R29: =sumifs('25.06'!$H$7:$H$162,'25.06'!$I$7:$I$162,$B29,'25.06'!$J$7:$J$162,R$3) -> 0 | S29: =sumifs('25.06'!$H$7:$H$162,'25.06'!$I$7:$I$162,$B29,'25.06'!$J$7:$J$162,S$3) -> 0 | T29: =sumifs('25.06'!$H$7:$H$162,'25.06'!$I$7:$I$162,$B29,'25.06'!$J$7:$J$162,T$3) -> 0 | U29: =sumifs('25.06'!$H$7:$H$162,'25.06'!$I$7:$I$162,$B29,'25.06'!$J$7:$J$162,U$3) -> 0 | V29: =sumifs('25.06'!$H$7:$H$162,'25.06'!$I$7:$I$162,$B29,'25.06'!$J$7:$J$162,V$3) -> 0 | W29: =sumifs('25.06'!$H$7:$H$162,'25.06'!$I$7:$I$162,$B29,'25.06'!$J$7:$J$162,W$3) -> 0 | X29: =sumifs('25.06'!$H$7:$H$162,'25.06'!$I$7:$I$162,$B29,'25.06'!$J$7:$J$162,X$3) -> 0 | Y29: =sumifs('25.06'!$H$7:$H$162,'25.06'!$I$7:$I$162,$B29,'25.06'!$J$7:$J$162,Y$3) -> 0 | Z29: =sumifs('25.06'!$H$7:$H$162,'25.06'!$I$7:$I$162,$B29,'25.06'!$J$7:$J$162,Z$3) -> 0 | AA29: =sum(R29:Z29) -> 0
A30: 44931 | B30: Eating | C30: =sumifs('25.06'!$H$7:$H$162,'25.06'!$G$7:$G$162,$B30,'25.06'!$F$7:$F$162,C$3) -> 0 | D30: =sumifs('25.06'!$H$7:$H$162,'25.06'!$G$7:$G$162,$B30,'25.06'!$F$7:$F$162,D$3) -> 0 | E30: =sumifs('25.06'!$H$7:$H$162,'25.06'!$G$7:$G$162,$B30,'25.06'!$F$7:$F$162,E$3) -> 0 | F30: =sumifs('25.06'!$H$7:$H$162,'25.06'!$G$7:$G$162,$B30,'25.06'!$F$7:$F$162,F$3) -> 0 | G30: =sumifs('25.06'!$H$7:$H$162,'25.06'!$G$7:$G$162,$B30,'25.06'!$F$7:$F$162,G$3) -> 0 | H30: =sumifs('25.06'!$H$7:$H$162,'25.06'!$G$7:$G$162,$B30,'25.06'!$F$7:$F$162,H$3) -> 0 | I30: =sumifs('25.06'!$H$7:$H$162,'25.06'!$G$7:$G$162,$B30,'25.06'!$F$7:$F$162,I$3) -> 0 | J30: =sumifs('25.06'!$H$7:$H$162,'25.06'!$G$7:$G$162,$B30,'25.06'!$F$7:$F$162,J$3) -> 0 | K30: =sumifs('25.06'!$H$7:$H$162,'25.06'!$G$7:$G$162,$B30,'25.06'!$F$7:$F$162,K$3) -> 0 | L30: =sum(C30:K30) -> 0 | N30: =L30/sum(L$29:L$54) -> #DIV/0! | O30: =L30/sum(L$30:L$33) -> #DIV/0! | R30: =sumifs('25.06'!$H$7:$H$162,'25.06'!$I$7:$I$162,$B30,'25.06'!$J$7:$J$162,R$3) -> 0 | S30: =sumifs('25.06'!$H$7:$H$162,'25.06'!$I$7:$I$162,$B30,'25.06'!$J$7:$J$162,S$3) -> 0 | T30: =sumifs('25.06'!$H$7:$H$162,'25.06'!$I$7:$I$162,$B30,'25.06'!$J$7:$J$162,T$3) -> 0 | U30: =sumifs('25.06'!$H$7:$H$162,'25.06'!$I$7:$I$162,$B30,'25.06'!$J$7:$J$162,U$3) -> 0 | V30: =sumifs('25.06'!$H$7:$H$162,'25.06'!$I$7:$I$162,$B30,'25.06'!$J$7:$J$162,V$3) -> 0 | W30: =sumifs('25.06'!$H$7:$H$162,'25.06'!$I$7:$I$162,$B30,'25.06'!$J$7:$J$162,W$3) -> 0 | X30: =sumifs('25.06'!$H$7:$H$162,'25.06'!$I$7:$I$162,$B30,'25.06'!$J$7:$J$162,X$3) -> 0 | Y30: =sumifs('25.06'!$H$7:$H$162,'25.06'!$I$7:$I$162,$B30,'25.06'!$J$7:$J$162,Y$3) -> 0 | Z30: =sumifs('25.06'!$H$7:$H$162,'25.06'!$I$7:$I$162,$B30,'25.06'!$J$7:$J$162,Z$3) -> 0 | AA30: =sum(R30:Z30) -> 0
A31: a | B31: Go Market | C31: =sumifs('25.06'!$H$7:$H$162,'25.06'!$G$7:$G$162,$B31,'25.06'!$F$7:$F$162,C$3) -> 0 | D31: =sumifs('25.06'!$H$7:$H$162,'25.06'!$G$7:$G$162,$B31,'25.06'!$F$7:$F$162,D$3) -> 0 | E31: =sumifs('25.06'!$H$7:$H$162,'25.06'!$G$7:$G$162,$B31,'25.06'!$F$7:$F$162,E$3) -> 0 | F31: =sumifs('25.06'!$H$7:$H$162,'25.06'!$G$7:$G$162,$B31,'25.06'!$F$7:$F$162,F$3) -> 0 | G31: =sumifs('25.06'!$H$7:$H$162,'25.06'!$G$7:$G$162,$B31,'25.06'!$F$7:$F$162,G$3) -> 0 | H31: =sumifs('25.06'!$H$7:$H$162,'25.06'!$G$7:$G$162,$B31,'25.06'!$F$7:$F$162,H$3) -> 0 | I31: =sumifs('25.06'!$H$7:$H$162,'25.06'!$G$7:$G$162,$B31,'25.06'!$F$7:$F$162,I$3) -> 0 | J31: =sumifs('25.06'!$H$7:$H$162,'25.06'!$G$7:$G$162,$B31,'25.06'!$F$7:$F$162,J$3) -> 0 | K31: =sumifs('25.06'!$H$7:$H$162,'25.06'!$G$7:$G$162,$B31,'25.06'!$F$7:$F$162,K$3) -> 0 | L31: =sum(C31:K31) -> 0 | N31: =L31/sum(L$29:L$54) -> #DIV/0! | O31: =L31/sum(L$30:L$33) -> #DIV/0! | R31: =sumifs('25.06'!$H$7:$H$162,'25.06'!$I$7:$I$162,$B31,'25.06'!$J$7:$J$162,R$3) -> 0 | S31: =sumifs('25.06'!$H$7:$H$162,'25.06'!$I$7:$I$162,$B31,'25.06'!$J$7:$J$162,S$3) -> 0 | T31: =sumifs('25.06'!$H$7:$H$162,'25.06'!$I$7:$I$162,$B31,'25.06'!$J$7:$J$162,T$3) -> 0 | U31: =sumifs('25.06'!$H$7:$H$162,'25.06'!$I$7:$I$162,$B31,'25.06'!$J$7:$J$162,U$3) -> 0 | V31: =sumifs('25.06'!$H$7:$H$162,'25.06'!$I$7:$I$162,$B31,'25.06'!$J$7:$J$162,V$3) -> 0 | W31: =sumifs('25.06'!$H$7:$H$162,'25.06'!$I$7:$I$162,$B31,'25.06'!$J$7:$J$162,W$3) -> 0 | X31: =sumifs('25.06'!$H$7:$H$162,'25.06'!$I$7:$I$162,$B31,'25.06'!$J$7:$J$162,X$3) -> 0 | Y31: =sumifs('25.06'!$H$7:$H$162,'25.06'!$I$7:$I$162,$B31,'25.06'!$J$7:$J$162,Y$3) -> 0 | Z31: =sumifs('25.06'!$H$7:$H$162,'25.06'!$I$7:$I$162,$B31,'25.06'!$J$7:$J$162,Z$3) -> 0 | AA31: =sum(R31:Z31) -> 0
A32: b | B32: Breakfast | C32: =sumifs('25.06'!$H$7:$H$162,'25.06'!$G$7:$G$162,$B32,'25.06'!$F$7:$F$162,C$3) -> 0 | D32: =sumifs('25.06'!$H$7:$H$162,'25.06'!$G$7:$G$162,$B32,'25.06'!$F$7:$F$162,D$3) -> 0 | E32: =sumifs('25.06'!$H$7:$H$162,'25.06'!$G$7:$G$162,$B32,'25.06'!$F$7:$F$162,E$3) -> 0 | F32: =sumifs('25.06'!$H$7:$H$162,'25.06'!$G$7:$G$162,$B32,'25.06'!$F$7:$F$162,F$3) -> 0 | G32: =sumifs('25.06'!$H$7:$H$162,'25.06'!$G$7:$G$162,$B32,'25.06'!$F$7:$F$162,G$3) -> 0 | H32: =sumifs('25.06'!$H$7:$H$162,'25.06'!$G$7:$G$162,$B32,'25.06'!$F$7:$F$162,H$3) -> 0 | I32: =sumifs('25.06'!$H$7:$H$162,'25.06'!$G$7:$G$162,$B32,'25.06'!$F$7:$F$162,I$3) -> 0 | J32: =sumifs('25.06'!$H$7:$H$162,'25.06'!$G$7:$G$162,$B32,'25.06'!$F$7:$F$162,J$3) -> 0 | K32: =sumifs('25.06'!$H$7:$H$162,'25.06'!$G$7:$G$162,$B32,'25.06'!$F$7:$F$162,K$3) -> 0 | L32: =sum(C32:K32) -> 0 | N32: =L32/sum(L$29:L$54) -> #DIV/0! | O32: =L32/sum(L$30:L$33) -> #DIV/0! | R32: =sumifs('25.06'!$H$7:$H$162,'25.06'!$I$7:$I$162,$B32,'25.06'!$J$7:$J$162,R$3) -> 0 | S32: =sumifs('25.06'!$H$7:$H$162,'25.06'!$I$7:$I$162,$B32,'25.06'!$J$7:$J$162,S$3) -> 0 | T32: =sumifs('25.06'!$H$7:$H$162,'25.06'!$I$7:$I$162,$B32,'25.06'!$J$7:$J$162,T$3) -> 0 | U32: =sumifs('25.06'!$H$7:$H$162,'25.06'!$I$7:$I$162,$B32,'25.06'!$J$7:$J$162,U$3) -> 0 | V32: =sumifs('25.06'!$H$7:$H$162,'25.06'!$I$7:$I$162,$B32,'25.06'!$J$7:$J$162,V$3) -> 0 | W32: =sumifs('25.06'!$H$7:$H$162,'25.06'!$I$7:$I$162,$B32,'25.06'!$J$7:$J$162,W$3) -> 0 | X32: =sumifs('25.06'!$H$7:$H$162,'25.06'!$I$7:$I$162,$B32,'25.06'!$J$7:$J$162,X$3) -> 0 | Y32: =sumifs('25.06'!$H$7:$H$162,'25.06'!$I$7:$I$162,$B32,'25.06'!$J$7:$J$162,Y$3) -> 0 | Z32: =sumifs('25.06'!$H$7:$H$162,'25.06'!$I$7:$I$162,$B32,'25.06'!$J$7:$J$162,Z$3) -> 0 | AA32: =sum(R32:Z32) -> 0
A33: c | B33: Extra meal | C33: =sumifs('25.06'!$H$7:$H$162,'25.06'!$G$7:$G$162,$B33,'25.06'!$F$7:$F$162,C$3) -> 0 | D33: =sumifs('25.06'!$H$7:$H$162,'25.06'!$G$7:$G$162,$B33,'25.06'!$F$7:$F$162,D$3) -> 0 | E33: =sumifs('25.06'!$H$7:$H$162,'25.06'!$G$7:$G$162,$B33,'25.06'!$F$7:$F$162,E$3) -> 0 | F33: =sumifs('25.06'!$H$7:$H$162,'25.06'!$G$7:$G$162,$B33,'25.06'!$F$7:$F$162,F$3) -> 0 | G33: =sumifs('25.06'!$H$7:$H$162,'25.06'!$G$7:$G$162,$B33,'25.06'!$F$7:$F$162,G$3) -> 0 | H33: =sumifs('25.06'!$H$7:$H$162,'25.06'!$G$7:$G$162,$B33,'25.06'!$F$7:$F$162,H$3) -> 0 | I33: =sumifs('25.06'!$H$7:$H$162,'25.06'!$G$7:$G$162,$B33,'25.06'!$F$7:$F$162,I$3) -> 0 | J33: =sumifs('25.06'!$H$7:$H$162,'25.06'!$G$7:$G$162,$B33,'25.06'!$F$7:$F$162,J$3) -> 0 | K33: =sumifs('25.06'!$H$7:$H$162,'25.06'!$G$7:$G$162,$B33,'25.06'!$F$7:$F$162,K$3) -> 0 | L33: =sum(C33:K33) -> 0 | N33: =L33/sum(L$29:L$54) -> #DIV/0! | O33: =L33/sum(L$30:L$33) -> #DIV/0! | R33: =sumifs('25.06'!$H$7:$H$162,'25.06'!$I$7:$I$162,$B33,'25.06'!$J$7:$J$162,R$3) -> 0 | S33: =sumifs('25.06'!$H$7:$H$162,'25.06'!$I$7:$I$162,$B33,'25.06'!$J$7:$J$162,S$3) -> 0 | T33: =sumifs('25.06'!$H$7:$H$162,'25.06'!$I$7:$I$162,$B33,'25.06'!$J$7:$J$162,T$3) -> 0 | U33: =sumifs('25.06'!$H$7:$H$162,'25.06'!$I$7:$I$162,$B33,'25.06'!$J$7:$J$162,U$3) -> 0 | V33: =sumifs('25.06'!$H$7:$H$162,'25.06'!$I$7:$I$162,$B33,'25.06'!$J$7:$J$162,V$3) -> 0 | W33: =sumifs('25.06'!$H$7:$H$162,'25.06'!$I$7:$I$162,$B33,'25.06'!$J$7:$J$162,W$3) -> 0 | X33: =sumifs('25.06'!$H$7:$H$162,'25.06'!$I$7:$I$162,$B33,'25.06'!$J$7:$J$162,X$3) -> 0 | Y33: =sumifs('25.06'!$H$7:$H$162,'25.06'!$I$7:$I$162,$B33,'25.06'!$J$7:$J$162,Y$3) -> 0 | Z33: =sumifs('25.06'!$H$7:$H$162,'25.06'!$I$7:$I$162,$B33,'25.06'!$J$7:$J$162,Z$3) -> 0 | AA33: =sum(R33:Z33) -> 0
A34: 44962 | B34: Wearing | C34: =sumifs('25.06'!$H$7:$H$162,'25.06'!$G$7:$G$162,$B34,'25.06'!$F$7:$F$162,C$3) -> 0 | D34: =sumifs('25.06'!$H$7:$H$162,'25.06'!$G$7:$G$162,$B34,'25.06'!$F$7:$F$162,D$3) -> 0 | E34: =sumifs('25.06'!$H$7:$H$162,'25.06'!$G$7:$G$162,$B34,'25.06'!$F$7:$F$162,E$3) -> 0 | F34: =sumifs('25.06'!$H$7:$H$162,'25.06'!$G$7:$G$162,$B34,'25.06'!$F$7:$F$162,F$3) -> 0 | G34: =sumifs('25.06'!$H$7:$H$162,'25.06'!$G$7:$G$162,$B34,'25.06'!$F$7:$F$162,G$3) -> 0 | H34: =sumifs('25.06'!$H$7:$H$162,'25.06'!$G$7:$G$162,$B34,'25.06'!$F$7:$F$162,H$3) -> 0 | I34: =sumifs('25.06'!$H$7:$H$162,'25.06'!$G$7:$G$162,$B34,'25.06'!$F$7:$F$162,I$3) -> 0 | J34: =sumifs('25.06'!$H$7:$H$162,'25.06'!$G$7:$G$162,$B34,'25.06'!$F$7:$F$162,J$3) -> 0 | K34: =sumifs('25.06'!$H$7:$H$162,'25.06'!$G$7:$G$162,$B34,'25.06'!$F$7:$F$162,K$3) -> 0 | L34: =sum(C34:K34) -> 0 | N34: =L34/sum(L$29:L$54) -> #DIV/0! | O34: =L34/sum(L$34:L$38) -> #DIV/0! | R34: =sumifs('25.06'!$H$7:$H$162,'25.06'!$I$7:$I$162,$B34,'25.06'!$J$7:$J$162,R$3) -> 0 | S34: =sumifs('25.06'!$H$7:$H$162,'25.06'!$I$7:$I$162,$B34,'25.06'!$J$7:$J$162,S$3) -> 0 | T34: =sumifs('25.06'!$H$7:$H$162,'25.06'!$I$7:$I$162,$B34,'25.06'!$J$7:$J$162,T$3) -> 0 | U34: =sumifs('25.06'!$H$7:$H$162,'25.06'!$I$7:$I$162,$B34,'25.06'!$J$7:$J$162,U$3) -> 0 | V34: =sumifs('25.06'!$H$7:$H$162,'25.06'!$I$7:$I$162,$B34,'25.06'!$J$7:$J$162,V$3) -> 0 | W34: =sumifs('25.06'!$H$7:$H$162,'25.06'!$I$7:$I$162,$B34,'25.06'!$J$7:$J$162,W$3) -> 0 | X34: =sumifs('25.06'!$H$7:$H$162,'25.06'!$I$7:$I$162,$B34,'25.06'!$J$7:$J$162,X$3) -> 0 | Y34: =sumifs('25.06'!$H$7:$H$162,'25.06'!$I$7:$I$162,$B34,'25.06'!$J$7:$J$162,Y$3) -> 0 | Z34: =sumifs('25.06'!$H$7:$H$162,'25.06'!$I$7:$I$162,$B34,'25.06'!$J$7:$J$162,Z$3) -> 0 | AA34: =sum(R34:Z34) -> 0
A35: d | B35: Nghĩa | C35: =sumifs('25.06'!$H$7:$H$162,'25.06'!$G$7:$G$162,$B35,'25.06'!$F$7:$F$162,C$3) -> 0 | D35: =sumifs('25.06'!$H$7:$H$162,'25.06'!$G$7:$G$162,$B35,'25.06'!$F$7:$F$162,D$3) -> 0 | E35: =sumifs('25.06'!$H$7:$H$162,'25.06'!$G$7:$G$162,$B35,'25.06'!$F$7:$F$162,E$3) -> 0 | F35: =sumifs('25.06'!$H$7:$H$162,'25.06'!$G$7:$G$162,$B35,'25.06'!$F$7:$F$162,F$3) -> 0 | G35: =sumifs('25.06'!$H$7:$H$162,'25.06'!$G$7:$G$162,$B35,'25.06'!$F$7:$F$162,G$3) -> 0 | H35: =sumifs('25.06'!$H$7:$H$162,'25.06'!$G$7:$G$162,$B35,'25.06'!$F$7:$F$162,H$3) -> 0 | I35: =sumifs('25.06'!$H$7:$H$162,'25.06'!$G$7:$G$162,$B35,'25.06'!$F$7:$F$162,I$3) -> 0 | J35: =sumifs('25.06'!$H$7:$H$162,'25.06'!$G$7:$G$162,$B35,'25.06'!$F$7:$F$162,J$3) -> 0 | K35: =sumifs('25.06'!$H$7:$H$162,'25.06'!$G$7:$G$162,$B35,'25.06'!$F$7:$F$162,K$3) -> 0 | L35: =sum(C35:K35) -> 0 | N35: =L35/sum(L$29:L$54) -> #DIV/0! | O35: =L35/sum(L$34:L$38) -> #DIV/0! | R35: =sumifs('25.06'!$H$7:$H$162,'25.06'!$I$7:$I$162,$B35,'25.06'!$J$7:$J$162,R$3) -> 0 | S35: =sumifs('25.06'!$H$7:$H$162,'25.06'!$I$7:$I$162,$B35,'25.06'!$J$7:$J$162,S$3) -> 0 | T35: =sumifs('25.06'!$H$7:$H$162,'25.06'!$I$7:$I$162,$B35,'25.06'!$J$7:$J$162,T$3) -> 0 | U35: =sumifs('25.06'!$H$7:$H$162,'25.06'!$I$7:$I$162,$B35,'25.06'!$J$7:$J$162,U$3) -> 0 | V35: =sumifs('25.06'!$H$7:$H$162,'25.06'!$I$7:$I$162,$B35,'25.06'!$J$7:$J$162,V$3) -> 0 | W35: =sumifs('25.06'!$H$7:$H$162,'25.06'!$I$7:$I$162,$B35,'25.06'!$J$7:$J$162,W$3) -> 0 | X35: =sumifs('25.06'!$H$7:$H$162,'25.06'!$I$7:$I$162,$B35,'25.06'!$J$7:$J$162,X$3) -> 0 | Y35: =sumifs('25.06'!$H$7:$H$162,'25.06'!$I$7:$I$162,$B35,'25.06'!$J$7:$J$162,Y$3) -> 0 | Z35: =sumifs('25.06'!$H$7:$H$162,'25.06'!$I$7:$I$162,$B35,'25.06'!$J$7:$J$162,Z$3) -> 0 | AA35: =sum(R35:Z35) -> 0
A36: e | B36: Mai | C36: =sumifs('25.06'!$H$7:$H$162,'25.06'!$G$7:$G$162,$B36,'25.06'!$F$7:$F$162,C$3) -> 0 | D36: =sumifs('25.06'!$H$7:$H$162,'25.06'!$G$7:$G$162,$B36,'25.06'!$F$7:$F$162,D$3) -> 0 | E36: =sumifs('25.06'!$H$7:$H$162,'25.06'!$G$7:$G$162,$B36,'25.06'!$F$7:$F$162,E$3) -> 0 | F36: =sumifs('25.06'!$H$7:$H$162,'25.06'!$G$7:$G$162,$B36,'25.06'!$F$7:$F$162,F$3) -> 0 | G36: =sumifs('25.06'!$H$7:$H$162,'25.06'!$G$7:$G$162,$B36,'25.06'!$F$7:$F$162,G$3) -> 0 | H36: =sumifs('25.06'!$H$7:$H$162,'25.06'!$G$7:$G$162,$B36,'25.06'!$F$7:$F$162,H$3) -> 0 | I36: =sumifs('25.06'!$H$7:$H$162,'25.06'!$G$7:$G$162,$B36,'25.06'!$F$7:$F$162,I$3) -> 0 | J36: =sumifs('25.06'!$H$7:$H$162,'25.06'!$G$7:$G$162,$B36,'25.06'!$F$7:$F$162,J$3) -> 0 | K36: =sumifs('25.06'!$H$7:$H$162,'25.06'!$G$7:$G$162,$B36,'25.06'!$F$7:$F$162,K$3) -> 0 | L36: =sum(C36:K36) -> 0 | N36: =L36/sum(L$29:L$54) -> #DIV/0! | O36: =L36/sum(L$34:L$38) -> #DIV/0! | R36: =sumifs('25.06'!$H$7:$H$162,'25.06'!$I$7:$I$162,$B36,'25.06'!$J$7:$J$162,R$3) -> 0 | S36: =sumifs('25.06'!$H$7:$H$162,'25.06'!$I$7:$I$162,$B36,'25.06'!$J$7:$J$162,S$3) -> 0 | T36: =sumifs('25.06'!$H$7:$H$162,'25.06'!$I$7:$I$162,$B36,'25.06'!$J$7:$J$162,T$3) -> 0 | U36: =sumifs('25.06'!$H$7:$H$162,'25.06'!$I$7:$I$162,$B36,'25.06'!$J$7:$J$162,U$3) -> 0 | V36: =sumifs('25.06'!$H$7:$H$162,'25.06'!$I$7:$I$162,$B36,'25.06'!$J$7:$J$162,V$3) -> 0 | W36: =sumifs('25.06'!$H$7:$H$162,'25.06'!$I$7:$I$162,$B36,'25.06'!$J$7:$J$162,W$3) -> 0 | X36: =sumifs('25.06'!$H$7:$H$162,'25.06'!$I$7:$I$162,$B36,'25.06'!$J$7:$J$162,X$3) -> 0 | Y36: =sumifs('25.06'!$H$7:$H$162,'25.06'!$I$7:$I$162,$B36,'25.06'!$J$7:$J$162,Y$3) -> 0 | Z36: =sumifs('25.06'!$H$7:$H$162,'25.06'!$I$7:$I$162,$B36,'25.06'!$J$7:$J$162,Z$3) -> 0 | AA36: =sum(R36:Z36) -> 0
